Workbook
Name Type: #REF!
Name Type: #REF!

Sheet Overall Case Study
C2: Context
C3: A toy company is facing troubles with planning and data visualization
C5: Problems:
C6: 1. Need to visualize master data
C7: 2. Need to balance demand & create master production scheduling (MPS) with inhouse capacity constraints
C8: 3. Need to create material requirement planning (MRP) then determine reorder point based on leadtime (LT)
B13: No | C13: Question | D13: Requirement
B14: 1 | C14: Visualize demand of 6 SKUs | D14: By Regions, Category, Total Value
B15: 2 | C15: Create master production scheduling (MPS) | D15: Generate a master production planning for whole year
B16: 3 | C16: Balance demand | D16: Based on current fixture set and weekly capacity to balance and suggest solution if over 1. Leverage demand 2. Buy more fixture
B17: 4 | C17: Create Material requirment Planning (MRP) | D17: Generate a material requirement planning following 6 SKUs' demand and BOM usage
B18: 5 | C18: Determine supply plan | D18: Based on leadtime, current stock on hand and pending PO to find out reorder point and fill out/ layout supply plan
B19: 6 | C19: Figure out safety stock strategy | D19: Based on vendor location to define stock on hand level by week or day or hour (local and oversea)

Sheet Demand
A1: Item name | B1: Des | C1: Market | D1: Price ($) | E1: Product group | F1: Fixture | G1: Weekly Capcity | H1: Shipment Request | I1: Demand Quantity
A2: F | B2: 2025 Fantasy Spaceship Model DIY kits | C2: US | D2: 90 | E2: Arts & Crafts Toy | F2: 789EF | G2: 3000 | H2: 46143 | I2: 588
A3: A | B3: 2026 Automatic Robot ver | C3: US | D3: 105 | E3: Electronic Toy | F3: 123AB | G3: 15000 | H3: 46150 | I3: 684
A4: E | B4: 2026 Scooter ver | C4: Australia | D4: 30 | E4: Outdoor & Sports Toy | F4: 789EF | G4: 3000 | H4: 46150 | I4: 472
A5: F | B5: 2025 Fantasy Spaceship Model DIY kits | C5: US | D5: 90 | E5: Arts & Crafts Toy | F5: 789EF | G5: 3000 | H5: 46150 | I5: 4028
A6: A | B6: 2026 Automatic Robot ver | C6: US | D6: 105 | E6: Electronic Toy | F6: 123AB | G6: 15000 | H6: 46157 | I6: 20000
A7: B | B7: 2025 Barbie ver colorful | C7: US | D7: 55 | E7: Doll | F7: 123AB | G7: 15000 | H7: 46157 | I7: 2731
A8: B | B8: 2025 Barbie ver colorful | C8: US | D8: 55 | E8: Doll | F8: 123AB | G8: 15000 | H8: 46157 | I8: 2771
A9: C | B9: 2026 Castle & Farm Blocks | C9: UK | D9: 80 | E9: Building & Construction Toy | F9: 456CD | G9: 5000 | H9: 46157 | I9: 270
A10: C | B10: 2026 Castle & Farm Blocks | C10: UK | D10: 80 | E10: Building & Construction Toy | F10: 456CD | G10: 5000 | H10: 46157 | I10: 270
A11: C | B11: 2026 Castle & Farm Blocks | C11: UK | D11: 80 | E11: Building & Construction Toy | F11: 456CD | G11: 5000 | H11: 46157 | I11: 270
A12: C | B12: 2026 Castle & Farm Blocks | C12: UK | D12: 80 | E12: Building & Construction Toy | F12: 456CD | G12: 5000 | H12: 46157 | I12: 270
A13: C | B13: 2026 Castle & Farm Blocks | C13: UK | D13: 80 | E13: Building & Construction Toy | F13: 456CD | G13: 5000 | H13: 46157 | I13: 270
... A466: F | B466: 2025 Fantasy Spaceship Model DIY kits | C466: US | D466: 90 | E466: Arts & Crafts Toy | F466: 789EF | G466: 3000 | H466: 46381 | I466: 1928

Sheet Demand_
A1: Item name | B1: Des | C1: Market | D1: Price ($) | E1: Product group | F1: Fixture | G1: Weekly Capcity | H1: Shipment Request | I1: Demand Quantity | J1: week first day | K1: production day | L1: Total Demand by SKU-Week | M1: 46139
A2: A | B2: 2026 Automatic Robot ver | C2: US | D2: 105 | E2: Electronic Toy | F2: 123AB | G2: 15000 | H2: 46150 | I2: 684 | J2: =$M$1+7*INT((H2-$M$1)/7) -> 46146 | K2: =Table14[[#This Row],[week first day]]-7 -> 46139 | L2: =SUMIFS($I:$I,$A:$A,A2,J:J,J2) -> 684
A3: A | B3: 2026 Automatic Robot ver | C3: US | D3: 105 | E3: Electronic Toy | F3: 123AB | G3: 15000 | H3: 46157 | I3: 20000 | J3: =$M$1+7*INT((H3-$M$1)/7) -> 46153 | K3: =Table14[[#This Row],[week first day]]-7 -> 46146 | L3: =SUMIFS($I:$I,$A:$A,A3,J:J,J3) -> 20000
A4: A | B4: 2026 Automatic Robot ver | C4: US | D4: 105 | E4: Electronic Toy | F4: 123AB | G4: 15000 | H4: 46164 | I4: 15000 | J4: =$M$1+7*INT((H4-$M$1)/7) -> 46160 | K4: =Table14[[#This Row],[week first day]]-7 -> 46153 | L4: =SUMIFS($I:$I,$A:$A,A4,J:J,J4) -> 20000
A5: A | B5: 2026 Automatic Robot ver | C5: US | D5: 105 | E5: Electronic Toy | F5: 123AB | G5: 15000 | H5: 46164 | I5: 5000 | J5: =$M$1+7*INT((H5-$M$1)/7) -> 46160 | K5: =Table14[[#This Row],[week first day]]-7 -> 46153 | L5: =SUMIFS($I:$I,$A:$A,A5,J:J,J5) -> 20000
A6: A | B6: 2026 Automatic Robot ver | C6: US | D6: 105 | E6: Electronic Toy | F6: 123AB | G6: 15000 | H6: 46171 | I6: 11000 | J6: =$M$1+7*INT((H6-$M$1)/7) -> 46167 | K6: =Table14[[#This Row],[week first day]]-7 -> 46160 | L6: =SUMIFS($I:$I,$A:$A,A6,J:J,J6) -> 11000
A7: A | B7: 2026 Automatic Robot ver | C7: US | D7: 105 | E7: Electronic Toy | F7: 123AB | G7: 15000 | H7: 46178 | I7: 13000 | J7: =$M$1+7*INT((H7-$M$1)/7) -> 46174 | K7: =Table14[[#This Row],[week first day]]-7 -> 46167 | L7: =SUMIFS($I:$I,$A:$A,A7,J:J,J7) -> 13000
A8: A | B8: 2026 Automatic Robot ver | C8: US | D8: 105 | E8: Electronic Toy | F8: 123AB | G8: 15000 | H8: 46185 | I8: 13773 | J8: =$M$1+7*INT((H8-$M$1)/7) -> 46181 | K8: =Table14[[#This Row],[week first day]]-7 -> 46174 | L8: =SUMIFS($I:$I,$A:$A,A8,J:J,J8) -> 13773
A9: A | B9: 2026 Automatic Robot ver | C9: US | D9: 105 | E9: Electronic Toy | F9: 123AB | G9: 15000 | H9: 46192 | I9: 7058 | J9: =$M$1+7*INT((H9-$M$1)/7) -> 46188 | K9: =Table14[[#This Row],[week first day]]-7 -> 46181 | L9: =SUMIFS($I:$I,$A:$A,A9,J:J,J9) -> 7058
A10: A | B10: 2026 Automatic Robot ver | C10: US | D10: 105 | E10: Electronic Toy | F10: 123AB | G10: 15000 | H10: 46199 | I10: 2040 | J10: =$M$1+7*INT((H10-$M$1)/7) -> 46195 | K10: =Table14[[#This Row],[week first day]]-7 -> 46188 | L10: =SUMIFS($I:$I,$A:$A,A10,J:J,J10) -> 2040
A11: A | B11: 2026 Automatic Robot ver | C11: US | D11: 105 | E11: Electronic Toy | F11: 123AB | G11: 15000 | H11: 46206 | I11: 1500 | J11: =$M$1+7*INT((H11-$M$1)/7) -> 46202 | K11: =Table14[[#This Row],[week first day]]-7 -> 46195 | L11: =SUMIFS($I:$I,$A:$A,A11,J:J,J11) -> 3541
A12: A | B12: 2026 Automatic Robot ver | C12: US | D12: 105 | E12: Electronic Toy | F12: 123AB | G12: 15000 | H12: 46206 | I12: 2041 | J12: =$M$1+7*INT((H12-$M$1)/7) -> 46202 | K12: =Table14[[#This Row],[week first day]]-7 -> 46195 | L12: =SUMIFS($I:$I,$A:$A,A12,J:J,J12) -> 3541
A13: A | B13: 2026 Automatic Robot ver | C13: US | D13: 105 | E13: Electronic Toy | F13: 123AB | G13: 15000 | H13: 46213 | I13: 2041 | J13: =$M$1+7*INT((H13-$M$1)/7) -> 46209 | K13: =Table14[[#This Row],[week first day]]-7 -> 46202 | L13: =SUMIFS($I:$I,$A:$A,A13,J:J,J13) -> 12041
... A466: F | B466: 2025 Fantasy Spaceship Model DIY kits | C466: US | D466: 90 | E466: Arts & Crafts Toy | F466: 789EF | G466: 3000 | H466: 46381 | I466: 1928 | J466: =$M$1+7*INT((H466-$M$1)/7) -> 46377 | K466: =Table14[[#This Row],[week first day]]-7 -> 46370 | L466: =SUMIFS($I:$I,$A:$A,A466,J:J,J466) -> 1928

Sheet weekly_demand
A1: Item name | B1: market | C1: week first day | D1: Total Demand by SKU-Week | E1: carton | F1: volume
A2: {=_xlfn.UNIQUE(_xlfn.CHOOSECOLS(Demand_!A2:L466,1,3,11,12))} -> A | B2: US | C2: 46139 | D2: 684 | E2: =ROUNDUP(D2/_xlfn.XLOOKUP(A2,$J$3:$J$8,$L$3:$L$8),0) -> 171 | F2: =E2/100*_xlfn.XLOOKUP(A2,$J$3:$J$8,$M$3:$M$8) -> 1.71 | J2: Item name | K2: Des | L2: Packing size (pcs/ carton) | M2: CBM (100 cartons)
A3: A | B3: US | C3: 46146 | D3: 20000 | E3: =ROUNDUP(D3/_xlfn.XLOOKUP(A3,$J$3:$J$8,$L$3:$L$8),0) -> 5000 | F3: =E3/100*_xlfn.XLOOKUP(A3,$J$3:$J$8,$M$3:$M$8) -> 50 | J3: A | K3: 2026 Automatic Robot ver | L3: 4 | M3: 1
A4: A | B4: US | C4: 46153 | D4: 20000 | E4: =ROUNDUP(D4/_xlfn.XLOOKUP(A4,$J$3:$J$8,$L$3:$L$8),0) -> 5000 | F4: =E4/100*_xlfn.XLOOKUP(A4,$J$3:$J$8,$M$3:$M$8) -> 50 | J4: B | K4: 2025 Barbie ver colorful | L4: 4 | M4: 0.625
A5: A | B5: US | C5: 46160 | D5: 11000 | E5: =ROUNDUP(D5/_xlfn.XLOOKUP(A5,$J$3:$J$8,$L$3:$L$8),0) -> 2750 | F5: =E5/100*_xlfn.XLOOKUP(A5,$J$3:$J$8,$M$3:$M$8) -> 27.5 | J5: C | K5: 2026 Castle & Farm Blocks | L5: 2 | M5: 1
A6: A | B6: US | C6: 46167 | D6: 13000 | E6: =ROUNDUP(D6/_xlfn.XLOOKUP(A6,$J$3:$J$8,$L$3:$L$8),0) -> 3250 | F6: =E6/100*_xlfn.XLOOKUP(A6,$J$3:$J$8,$M$3:$M$8) -> 32.5 | J6: D | K6: 2026 Animal Animation Book | L6: 4 | M6: 0.625
A7: A | B7: US | C7: 46174 | D7: 13773 | E7: =ROUNDUP(D7/_xlfn.XLOOKUP(A7,$J$3:$J$8,$L$3:$L$8),0) -> 3444 | F7: =E7/100*_xlfn.XLOOKUP(A7,$J$3:$J$8,$M$3:$M$8) -> 34.44 | J7: E | K7: 2026 Scooter ver | L7: 2 | M7: 0.625
A8: A | B8: US | C8: 46181 | D8: 7058 | E8: =ROUNDUP(D8/_xlfn.XLOOKUP(A8,$J$3:$J$8,$L$3:$L$8),0) -> 1765 | F8: =E8/100*_xlfn.XLOOKUP(A8,$J$3:$J$8,$M$3:$M$8) -> 17.65 | J8: F | K8: 2025 Fantasy Spaceship Model DIY kits | L8: 8 | M8: 0.78125
A9: A | B9: US | C9: 46188 | D9: 2040 | E9: =ROUNDUP(D9/_xlfn.XLOOKUP(A9,$J$3:$J$8,$L$3:$L$8),0) -> 510 | F9: =E9/100*_xlfn.XLOOKUP(A9,$J$3:$J$8,$M$3:$M$8) -> 5.1
A10: A | B10: US | C10: 46195 | D10: 3541 | E10: =ROUNDUP(D10/_xlfn.XLOOKUP(A10,$J$3:$J$8,$L$3:$L$8),0) -> 886 | F10: =E10/100*_xlfn.XLOOKUP(A10,$J$3:$J$8,$M$3:$M$8) -> 8.86
A11: A | B11: US | C11: 46202 | D11: 12041 | E11: =ROUNDUP(D11/_xlfn.XLOOKUP(A11,$J$3:$J$8,$L$3:$L$8),0) -> 3011 | F11: =E11/100*_xlfn.XLOOKUP(A11,$J$3:$J$8,$M$3:$M$8) -> 30.11
A12: A | B12: US | C12: 46209 | D12: 12040 | E12: =ROUNDUP(D12/_xlfn.XLOOKUP(A12,$J$3:$J$8,$L$3:$L$8),0) -> 3010 | F12: =E12/100*_xlfn.XLOOKUP(A12,$J$3:$J$8,$M$3:$M$8) -> 30.1
A13: A | B13: US | C13: 46230 | D13: 27760 | E13: =ROUNDUP(D13/_xlfn.XLOOKUP(A13,$J$3:$J$8,$L$3:$L$8),0) -> 6940 | F13: =E13/100*_xlfn.XLOOKUP(A13,$J$3:$J$8,$M$3:$M$8) -> 69.4
A14: A | B14: US | C14: 46237 | D14: 26486 | E14: =ROUNDUP(D14/_xlfn.XLOOKUP(A14,$J$3:$J$8,$L$3:$L$8),0) -> 6622 | F14: =E14/100*_xlfn.XLOOKUP(A14,$J$3:$J$8,$M$3:$M$8) -> 66.22
A15: A | B15: US | C15: 46244 | D15: 4248 | E15: =ROUNDUP(D15/_xlfn.XLOOKUP(A15,$J$3:$J$8,$L$3:$L$8),0) -> 1062 | F15: =E15/100*_xlfn.XLOOKUP(A15,$J$3:$J$8,$M$3:$M$8) -> 10.62
A16: A | B16: US | C16: 46251 | D16: 4248 | E16: =ROUNDUP(D16/_xlfn.XLOOKUP(A16,$J$3:$J$8,$L$3:$L$8),0) -> 1062 | F16: =E16/100*_xlfn.XLOOKUP(A16,$J$3:$J$8,$M$3:$M$8) -> 10.62
A17: A | B17: US | C17: 46258 | D17: 4249 | E17: =ROUNDUP(D17/_xlfn.XLOOKUP(A17,$J$3:$J$8,$L$3:$L$8),0) -> 1063 | F17: =E17/100*_xlfn.XLOOKUP(A17,$J$3:$J$8,$M$3:$M$8) -> 10.63
A18: A | B18: US | C18: 46265 | D18: 4248 | E18: =ROUNDUP(D18/_xlfn.XLOOKUP(A18,$J$3:$J$8,$L$3:$L$8),0) -> 1062 | F18: =E18/100*_xlfn.XLOOKUP(A18,$J$3:$J$8,$M$3:$M$8) -> 10.62
A19: A | B19: US | C19: 46272 | D19: 2391 | E19: =ROUNDUP(D19/_xlfn.XLOOKUP(A19,$J$3:$J$8,$L$3:$L$8),0) -> 598 | F19: =E19/100*_xlfn.XLOOKUP(A19,$J$3:$J$8,$M$3:$M$8) -> 5.98
A20: A | B20: US | C20: 46279 | D20: 2392 | E20: =ROUNDUP(D20/_xlfn.XLOOKUP(A20,$J$3:$J$8,$L$3:$L$8),0) -> 598 | F20: =E20/100*_xlfn.XLOOKUP(A20,$J$3:$J$8,$M$3:$M$8) -> 5.98
... A172: F | B172: US | C172: 46370 | D172: 1928 | E172: =ROUNDUP(D172/_xlfn.XLOOKUP(A172,$J$3:$J$8,$L$3:$L$8),0) -> 241 | F172: =E172/100*_xlfn.XLOOKUP(A172,$J$3:$J$8,$M$3:$M$8) -> 1.8828125

Sheet demand_matrix
A1: Week | B1: A | C1: B | D1: C | E1: D | F1: E | G1: F
A2: 46132 | B2: =IF($A2="","",SUMIFS(weekly_demand!$D:$D,weekly_demand!$A:$A,B$1,weekly_demand!$C:$C,$A2)) -> 0 | C2: =IF($A2="","",SUMIFS(weekly_demand!$D:$D,weekly_demand!$A:$A,C$1,weekly_demand!$C:$C,$A2)) -> 0 | D2: =IF($A2="","",SUMIFS(weekly_demand!$D:$D,weekly_demand!$A:$A,D$1,weekly_demand!$C:$C,$A2)) -> 0 | E2: =IF($A2="","",SUMIFS(weekly_demand!$D:$D,weekly_demand!$A:$A,E$1,weekly_demand!$C:$C,$A2)) -> 0 | F2: =IF($A2="","",SUMIFS(weekly_demand!$D:$D,weekly_demand!$A:$A,F$1,weekly_demand!$C:$C,$A2)) -> 0 | G2: =IF($A2="","",SUMIFS(weekly_demand!$D:$D,weekly_demand!$A:$A,G$1,weekly_demand!$C:$C,$A2)) -> 588
A3: 46139 | B3: =IF($A3="","",SUMIFS(weekly_demand!$D:$D,weekly_demand!$A:$A,B$1,weekly_demand!$C:$C,$A3)) -> 684 | C3: =IF($A3="","",SUMIFS(weekly_demand!$D:$D,weekly_demand!$A:$A,C$1,weekly_demand!$C:$C,$A3)) -> 0 | D3: =IF($A3="","",SUMIFS(weekly_demand!$D:$D,weekly_demand!$A:$A,D$1,weekly_demand!$C:$C,$A3)) -> 0 | E3: =IF($A3="","",SUMIFS(weekly_demand!$D:$D,weekly_demand!$A:$A,E$1,weekly_demand!$C:$C,$A3)) -> 0 | F3: =IF($A3="","",SUMIFS(weekly_demand!$D:$D,weekly_demand!$A:$A,F$1,weekly_demand!$C:$C,$A3)) -> 472 | G3: =IF($A3="","",SUMIFS(weekly_demand!$D:$D,weekly_demand!$A:$A,G$1,weekly_demand!$C:$C,$A3)) -> 4028
A4: 46146 | B4: =IF($A4="","",SUMIFS(weekly_demand!$D:$D,weekly_demand!$A:$A,B$1,weekly_demand!$C:$C,$A4)) -> 20000 | C4: =IF($A4="","",SUMIFS(weekly_demand!$D:$D,weekly_demand!$A:$A,C$1,weekly_demand!$C:$C,$A4)) -> 5502 | D4: =IF($A4="","",SUMIFS(weekly_demand!$D:$D,weekly_demand!$A:$A,D$1,weekly_demand!$C:$C,$A4)) -> 4320 | E4: =IF($A4="","",SUMIFS(weekly_demand!$D:$D,weekly_demand!$A:$A,E$1,weekly_demand!$C:$C,$A4)) -> 2430 | F4: =IF($A4="","",SUMIFS(weekly_demand!$D:$D,weekly_demand!$A:$A,F$1,weekly_demand!$C:$C,$A4)) -> 300 | G4: =IF($A4="","",SUMIFS(weekly_demand!$D:$D,weekly_demand!$A:$A,G$1,weekly_demand!$C:$C,$A4)) -> 4200
A5: 46153 | B5: =IF($A5="","",SUMIFS(weekly_demand!$D:$D,weekly_demand!$A:$A,B$1,weekly_demand!$C:$C,$A5)) -> 20000 | C5: =IF($A5="","",SUMIFS(weekly_demand!$D:$D,weekly_demand!$A:$A,C$1,weekly_demand!$C:$C,$A5)) -> 15658 | D5: =IF($A5="","",SUMIFS(weekly_demand!$D:$D,weekly_demand!$A:$A,D$1,weekly_demand!$C:$C,$A5)) -> 8370 | E5: =IF($A5="","",SUMIFS(weekly_demand!$D:$D,weekly_demand!$A:$A,E$1,weekly_demand!$C:$C,$A5)) -> 9990 | F5: =IF($A5="","",SUMIFS(weekly_demand!$D:$D,weekly_demand!$A:$A,F$1,weekly_demand!$C:$C,$A5)) -> 698 | G5: =IF($A5="","",SUMIFS(weekly_demand!$D:$D,weekly_demand!$A:$A,G$1,weekly_demand!$C:$C,$A5)) -> 3802
A6: 46160 | B6: =IF($A6="","",SUMIFS(weekly_demand!$D:$D,weekly_demand!$A:$A,B$1,weekly_demand!$C:$C,$A6)) -> 11000 | C6: =IF($A6="","",SUMIFS(weekly_demand!$D:$D,weekly_demand!$A:$A,C$1,weekly_demand!$C:$C,$A6)) -> 8865 | D6: =IF($A6="","",SUMIFS(weekly_demand!$D:$D,weekly_demand!$A:$A,D$1,weekly_demand!$C:$C,$A6)) -> 11782 | E6: =IF($A6="","",SUMIFS(weekly_demand!$D:$D,weekly_demand!$A:$A,E$1,weekly_demand!$C:$C,$A6)) -> 5840 | F6: =IF($A6="","",SUMIFS(weekly_demand!$D:$D,weekly_demand!$A:$A,F$1,weekly_demand!$C:$C,$A6)) -> 0 | G6: =IF($A6="","",SUMIFS(weekly_demand!$D:$D,weekly_demand!$A:$A,G$1,weekly_demand!$C:$C,$A6)) -> 4500
A7: 46167 | B7: =IF($A7="","",SUMIFS(weekly_demand!$D:$D,weekly_demand!$A:$A,B$1,weekly_demand!$C:$C,$A7)) -> 13000 | C7: =IF($A7="","",SUMIFS(weekly_demand!$D:$D,weekly_demand!$A:$A,C$1,weekly_demand!$C:$C,$A7)) -> 2146 | D7: =IF($A7="","",SUMIFS(weekly_demand!$D:$D,weekly_demand!$A:$A,D$1,weekly_demand!$C:$C,$A7)) -> 10524 | E7: =IF($A7="","",SUMIFS(weekly_demand!$D:$D,weekly_demand!$A:$A,E$1,weekly_demand!$C:$C,$A7)) -> 8100 | F7: =IF($A7="","",SUMIFS(weekly_demand!$D:$D,weekly_demand!$A:$A,F$1,weekly_demand!$C:$C,$A7)) -> 300 | G7: =IF($A7="","",SUMIFS(weekly_demand!$D:$D,weekly_demand!$A:$A,G$1,weekly_demand!$C:$C,$A7)) -> 4200
A8: 46174 | B8: =IF($A8="","",SUMIFS(weekly_demand!$D:$D,weekly_demand!$A:$A,B$1,weekly_demand!$C:$C,$A8)) -> 13773 | C8: =IF($A8="","",SUMIFS(weekly_demand!$D:$D,weekly_demand!$A:$A,C$1,weekly_demand!$C:$C,$A8)) -> 7123 | D8: =IF($A8="","",SUMIFS(weekly_demand!$D:$D,weekly_demand!$A:$A,D$1,weekly_demand!$C:$C,$A8)) -> 3240 | E8: =IF($A8="","",SUMIFS(weekly_demand!$D:$D,weekly_demand!$A:$A,E$1,weekly_demand!$C:$C,$A8)) -> 1001 | F8: =IF($A8="","",SUMIFS(weekly_demand!$D:$D,weekly_demand!$A:$A,F$1,weekly_demand!$C:$C,$A8)) -> 0 | G8: =IF($A8="","",SUMIFS(weekly_demand!$D:$D,weekly_demand!$A:$A,G$1,weekly_demand!$C:$C,$A8)) -> 4500
A9: 46181 | B9: =IF($A9="","",SUMIFS(weekly_demand!$D:$D,weekly_demand!$A:$A,B$1,weekly_demand!$C:$C,$A9)) -> 7058 | C9: =IF($A9="","",SUMIFS(weekly_demand!$D:$D,weekly_demand!$A:$A,C$1,weekly_demand!$C:$C,$A9)) -> 5309 | D9: =IF($A9="","",SUMIFS(weekly_demand!$D:$D,weekly_demand!$A:$A,D$1,weekly_demand!$C:$C,$A9)) -> 6442 | E9: =IF($A9="","",SUMIFS(weekly_demand!$D:$D,weekly_demand!$A:$A,E$1,weekly_demand!$C:$C,$A9)) -> 2471 | F9: =IF($A9="","",SUMIFS(weekly_demand!$D:$D,weekly_demand!$A:$A,F$1,weekly_demand!$C:$C,$A9)) -> 0 | G9: =IF($A9="","",SUMIFS(weekly_demand!$D:$D,weekly_demand!$A:$A,G$1,weekly_demand!$C:$C,$A9)) -> 4500
A10: 46188 | B10: =IF($A10="","",SUMIFS(weekly_demand!$D:$D,weekly_demand!$A:$A,B$1,weekly_demand!$C:$C,$A10)) -> 2040 | C10: =IF($A10="","",SUMIFS(weekly_demand!$D:$D,weekly_demand!$A:$A,C$1,weekly_demand!$C:$C,$A10)) -> 5309 | D10: =IF($A10="","",SUMIFS(weekly_demand!$D:$D,weekly_demand!$A:$A,D$1,weekly_demand!$C:$C,$A10)) -> 8802 | E10: =IF($A10="","",SUMIFS(weekly_demand!$D:$D,weekly_demand!$A:$A,E$1,weekly_demand!$C:$C,$A10)) -> 3458 | F10: =IF($A10="","",SUMIFS(weekly_demand!$D:$D,weekly_demand!$A:$A,F$1,weekly_demand!$C:$C,$A10)) -> 300 | G10: =IF($A10="","",SUMIFS(weekly_demand!$D:$D,weekly_demand!$A:$A,G$1,weekly_demand!$C:$C,$A10)) -> 2200
A11: 46195 | B11: =IF($A11="","",SUMIFS(weekly_demand!$D:$D,weekly_demand!$A:$A,B$1,weekly_demand!$C:$C,$A11)) -> 3541 | C11: =IF($A11="","",SUMIFS(weekly_demand!$D:$D,weekly_demand!$A:$A,C$1,weekly_demand!$C:$C,$A11)) -> 3000 | D11: =IF($A11="","",SUMIFS(weekly_demand!$D:$D,weekly_demand!$A:$A,D$1,weekly_demand!$C:$C,$A11)) -> 7695 | E11: =IF($A11="","",SUMIFS(weekly_demand!$D:$D,weekly_demand!$A:$A,E$1,weekly_demand!$C:$C,$A11)) -> 500 | F11: =IF($A11="","",SUMIFS(weekly_demand!$D:$D,weekly_demand!$A:$A,F$1,weekly_demand!$C:$C,$A11)) -> 0 | G11: =IF($A11="","",SUMIFS(weekly_demand!$D:$D,weekly_demand!$A:$A,G$1,weekly_demand!$C:$C,$A11)) -> 5000
A12: 46202 | B12: =IF($A12="","",SUMIFS(weekly_demand!$D:$D,weekly_demand!$A:$A,B$1,weekly_demand!$C:$C,$A12)) -> 12041 | C12: =IF($A12="","",SUMIFS(weekly_demand!$D:$D,weekly_demand!$A:$A,C$1,weekly_demand!$C:$C,$A12)) -> 3000 | D12: =IF($A12="","",SUMIFS(weekly_demand!$D:$D,weekly_demand!$A:$A,D$1,weekly_demand!$C:$C,$A12)) -> 2500 | E12: =IF($A12="","",SUMIFS(weekly_demand!$D:$D,weekly_demand!$A:$A,E$1,weekly_demand!$C:$C,$A12)) -> 500 | F12: =IF($A12="","",SUMIFS(weekly_demand!$D:$D,weekly_demand!$A:$A,F$1,weekly_demand!$C:$C,$A12)) -> 700 | G12: =IF($A12="","",SUMIFS(weekly_demand!$D:$D,weekly_demand!$A:$A,G$1,weekly_demand!$C:$C,$A12)) -> 4300
A13: 46209 | B13: =IF($A13="","",SUMIFS(weekly_demand!$D:$D,weekly_demand!$A:$A,B$1,weekly_demand!$C:$C,$A13)) -> 12040 | C13: =IF($A13="","",SUMIFS(weekly_demand!$D:$D,weekly_demand!$A:$A,C$1,weekly_demand!$C:$C,$A13)) -> 3000 | D13: =IF($A13="","",SUMIFS(weekly_demand!$D:$D,weekly_demand!$A:$A,D$1,weekly_demand!$C:$C,$A13)) -> 2500 | E13: =IF($A13="","",SUMIFS(weekly_demand!$D:$D,weekly_demand!$A:$A,E$1,weekly_demand!$C:$C,$A13)) -> 500 | F13: =IF($A13="","",SUMIFS(weekly_demand!$D:$D,weekly_demand!$A:$A,F$1,weekly_demand!$C:$C,$A13)) -> 300 | G13: =IF($A13="","",SUMIFS(weekly_demand!$D:$D,weekly_demand!$A:$A,G$1,weekly_demand!$C:$C,$A13)) -> 4700
... A36: 46370 | B36: =IF($A36="","",SUMIFS(weekly_demand!$D:$D,weekly_demand!$A:$A,B$1,weekly_demand!$C:$C,$A36)) -> 8325 | C36: =IF($A36="","",SUMIFS(weekly_demand!$D:$D,weekly_demand!$A:$A,C$1,weekly_demand!$C:$C,$A36)) -> 6250 | D36: =IF($A36="","",SUMIFS(weekly_demand!$D:$D,weekly_demand!$A:$A,D$1,weekly_demand!$C:$C,$A36)) -> 3000 | E36: =IF($A36="","",SUMIFS(weekly_demand!$D:$D,weekly_demand!$A:$A,E$1,weekly_demand!$C:$C,$A36)) -> 1250 | F36: =IF($A36="","",SUMIFS(weekly_demand!$D:$D,weekly_demand!$A:$A,F$1,weekly_demand!$C:$C,$A36)) -> 0 | G36: =IF($A36="","",SUMIFS(weekly_demand!$D:$D,weekly_demand!$A:$A,G$1,weekly_demand!$C:$C,$A36)) -> 1928
B37: =IF($A37="","",SUMIFS([1]weekly_demand!$D:$D,[1]weekly_demand!$A:$A,B$1,[1]weekly_demand!$C:$C,$A37)) | C37: =IF($A37="","",SUMIFS([1]weekly_demand!$D:$D,[1]weekly_demand!$A:$A,C$1,[1]weekly_demand!$C:$C,$A37)) | D37: =IF($A37="","",SUMIFS([1]weekly_demand!$D:$D,[1]weekly_demand!$A:$A,D$1,[1]weekly_demand!$C:$C,$A37)) | E37: =IF($A37="","",SUMIFS([1]weekly_demand!$D:$D,[1]weekly_demand!$A:$A,E$1,[1]weekly_demand!$C:$C,$A37)) | F37: =IF($A37="","",SUMIFS([1]weekly_demand!$D:$D,[1]weekly_demand!$A:$A,F$1,[1]weekly_demand!$C:$C,$A37)) | G37: =IF($A37="","",SUMIFS([1]weekly_demand!$D:$D,[1]weekly_demand!$A:$A,G$1,[1]weekly_demand!$C:$C,$A37))
B38: =IF($A38="","",SUMIFS([1]weekly_demand!$D:$D,[1]weekly_demand!$A:$A,B$1,[1]weekly_demand!$C:$C,$A38)) | C38: =IF($A38="","",SUMIFS([1]weekly_demand!$D:$D,[1]weekly_demand!$A:$A,C$1,[1]weekly_demand!$C:$C,$A38)) | D38: =IF($A38="","",SUMIFS([1]weekly_demand!$D:$D,[1]weekly_demand!$A:$A,D$1,[1]weekly_demand!$C:$C,$A38)) | E38: =IF($A38="","",SUMIFS([1]weekly_demand!$D:$D,[1]weekly_demand!$A:$A,E$1,[1]weekly_demand!$C:$C,$A38)) | F38: =IF($A38="","",SUMIFS([1]weekly_demand!$D:$D,[1]weekly_demand!$A:$A,F$1,[1]weekly_demand!$C:$C,$A38)) | G38: =IF($A38="","",SUMIFS([1]weekly_demand!$D:$D,[1]weekly_demand!$A:$A,G$1,[1]weekly_demand!$C:$C,$A38))
B39: =IF($A39="","",SUMIFS([1]weekly_demand!$D:$D,[1]weekly_demand!$A:$A,B$1,[1]weekly_demand!$C:$C,$A39)) | C39: =IF($A39="","",SUMIFS([1]weekly_demand!$D:$D,[1]weekly_demand!$A:$A,C$1,[1]weekly_demand!$C:$C,$A39)) | D39: =IF($A39="","",SUMIFS([1]weekly_demand!$D:$D,[1]weekly_demand!$A:$A,D$1,[1]weekly_demand!$C:$C,$A39)) | E39: =IF($A39="","",SUMIFS([1]weekly_demand!$D:$D,[1]weekly_demand!$A:$A,E$1,[1]weekly_demand!$C:$C,$A39)) | F39: =IF($A39="","",SUMIFS([1]weekly_demand!$D:$D,[1]weekly_demand!$A:$A,F$1,[1]weekly_demand!$C:$C,$A39)) | G39: =IF($A39="","",SUMIFS([1]weekly_demand!$D:$D,[1]weekly_demand!$A:$A,G$1,[1]weekly_demand!$C:$C,$A39))
B40: =IF($A40="","",SUMIFS([1]weekly_demand!$D:$D,[1]weekly_demand!$A:$A,B$1,[1]weekly_demand!$C:$C,$A40)) | C40: =IF($A40="","",SUMIFS([1]weekly_demand!$D:$D,[1]weekly_demand!$A:$A,C$1,[1]weekly_demand!$C:$C,$A40)) | D40: =IF($A40="","",SUMIFS([1]weekly_demand!$D:$D,[1]weekly_demand!$A:$A,D$1,[1]weekly_demand!$C:$C,$A40)) | E40: =IF($A40="","",SUMIFS([1]weekly_demand!$D:$D,[1]weekly_demand!$A:$A,E$1,[1]weekly_demand!$C:$C,$A40)) | F40: =IF($A40="","",SUMIFS([1]weekly_demand!$D:$D,[1]weekly_demand!$A:$A,F$1,[1]weekly_demand!$C:$C,$A40)) | G40: =IF($A40="","",SUMIFS([1]weekly_demand!$D:$D,[1]weekly_demand!$A:$A,G$1,[1]weekly_demand!$C:$C,$A40))
B41: =IF($A41="","",SUMIFS([1]weekly_demand!$D:$D,[1]weekly_demand!$A:$A,B$1,[1]weekly_demand!$C:$C,$A41)) | C41: =IF($A41="","",SUMIFS([1]weekly_demand!$D:$D,[1]weekly_demand!$A:$A,C$1,[1]weekly_demand!$C:$C,$A41)) | D41: =IF($A41="","",SUMIFS([1]weekly_demand!$D:$D,[1]weekly_demand!$A:$A,D$1,[1]weekly_demand!$C:$C,$A41)) | E41: =IF($A41="","",SUMIFS([1]weekly_demand!$D:$D,[1]weekly_demand!$A:$A,E$1,[1]weekly_demand!$C:$C,$A41)) | F41: =IF($A41="","",SUMIFS([1]weekly_demand!$D:$D,[1]weekly_demand!$A:$A,F$1,[1]weekly_demand!$C:$C,$A41)) | G41: =IF($A41="","",SUMIFS([1]weekly_demand!$D:$D,[1]weekly_demand!$A:$A,G$1,[1]weekly_demand!$C:$C,$A41))
B42: =IF($A42="","",SUMIFS([1]weekly_demand!$D:$D,[1]weekly_demand!$A:$A,B$1,[1]weekly_demand!$C:$C,$A42)) | C42: =IF($A42="","",SUMIFS([1]weekly_demand!$D:$D,[1]weekly_demand!$A:$A,C$1,[1]weekly_demand!$C:$C,$A42)) | D42: =IF($A42="","",SUMIFS([1]weekly_demand!$D:$D,[1]weekly_demand!$A:$A,D$1,[1]weekly_demand!$C:$C,$A42)) | E42: =IF($A42="","",SUMIFS([1]weekly_demand!$D:$D,[1]weekly_demand!$A:$A,E$1,[1]weekly_demand!$C:$C,$A42)) | F42: =IF($A42="","",SUMIFS([1]weekly_demand!$D:$D,[1]weekly_demand!$A:$A,F$1,[1]weekly_demand!$C:$C,$A42)) | G42: =IF($A42="","",SUMIFS([1]weekly_demand!$D:$D,[1]weekly_demand!$A:$A,G$1,[1]weekly_demand!$C:$C,$A42))
B43: =IF($A43="","",SUMIFS([1]weekly_demand!$D:$D,[1]weekly_demand!$A:$A,B$1,[1]weekly_demand!$C:$C,$A43)) | C43: =IF($A43="","",SUMIFS([1]weekly_demand!$D:$D,[1]weekly_demand!$A:$A,C$1,[1]weekly_demand!$C:$C,$A43)) | D43: =IF($A43="","",SUMIFS([1]weekly_demand!$D:$D,[1]weekly_demand!$A:$A,D$1,[1]weekly_demand!$C:$C,$A43)) | E43: =IF($A43="","",SUMIFS([1]weekly_demand!$D:$D,[1]weekly_demand!$A:$A,E$1,[1]weekly_demand!$C:$C,$A43)) | F43: =IF($A43="","",SUMIFS([1]weekly_demand!$D:$D,[1]weekly_demand!$A:$A,F$1,[1]weekly_demand!$C:$C,$A43)) | G43: =IF($A43="","",SUMIFS([1]weekly_demand!$D:$D,[1]weekly_demand!$A:$A,G$1,[1]weekly_demand!$C:$C,$A43))
B44: =IF($A44="","",SUMIFS([1]weekly_demand!$D:$D,[1]weekly_demand!$A:$A,B$1,[1]weekly_demand!$C:$C,$A44)) | C44: =IF($A44="","",SUMIFS([1]weekly_demand!$D:$D,[1]weekly_demand!$A:$A,C$1,[1]weekly_demand!$C:$C,$A44)) | D44: =IF($A44="","",SUMIFS([1]weekly_demand!$D:$D,[1]weekly_demand!$A:$A,D$1,[1]weekly_demand!$C:$C,$A44)) | E44: =IF($A44="","",SUMIFS([1]weekly_demand!$D:$D,[1]weekly_demand!$A:$A,E$1,[1]weekly_demand!$C:$C,$A44)) | F44: =IF($A44="","",SUMIFS([1]weekly_demand!$D:$D,[1]weekly_demand!$A:$A,F$1,[1]weekly_demand!$C:$C,$A44)) | G44: =IF($A44="","",SUMIFS([1]weekly_demand!$D:$D,[1]weekly_demand!$A:$A,G$1,[1]weekly_demand!$C:$C,$A44))
B45: =IF($A45="","",SUMIFS([1]weekly_demand!$D:$D,[1]weekly_demand!$A:$A,B$1,[1]weekly_demand!$C:$C,$A45)) | C45: =IF($A45="","",SUMIFS([1]weekly_demand!$D:$D,[1]weekly_demand!$A:$A,C$1,[1]weekly_demand!$C:$C,$A45)) | D45: =IF($A45="","",SUMIFS([1]weekly_demand!$D:$D,[1]weekly_demand!$A:$A,D$1,[1]weekly_demand!$C:$C,$A45)) | E45: =IF($A45="","",SUMIFS([1]weekly_demand!$D:$D,[1]weekly_demand!$A:$A,E$1,[1]weekly_demand!$C:$C,$A45)) | F45: =IF($A45="","",SUMIFS([1]weekly_demand!$D:$D,[1]weekly_demand!$A:$A,F$1,[1]weekly_demand!$C:$C,$A45)) | G45: =IF($A45="","",SUMIFS([1]weekly_demand!$D:$D,[1]weekly_demand!$A:$A,G$1,[1]weekly_demand!$C:$C,$A45))
B46: =IF($A46="","",SUMIFS([1]weekly_demand!$D:$D,[1]weekly_demand!$A:$A,B$1,[1]weekly_demand!$C:$C,$A46)) | C46: =IF($A46="","",SUMIFS([1]weekly_demand!$D:$D,[1]weekly_demand!$A:$A,C$1,[1]weekly_demand!$C:$C,$A46)) | D46: =IF($A46="","",SUMIFS([1]weekly_demand!$D:$D,[1]weekly_demand!$A:$A,D$1,[1]weekly_demand!$C:$C,$A46)) | E46: =IF($A46="","",SUMIFS([1]weekly_demand!$D:$D,[1]weekly_demand!$A:$A,E$1,[1]weekly_demand!$C:$C,$A46)) | F46: =IF($A46="","",SUMIFS([1]weekly_demand!$D:$D,[1]weekly_demand!$A:$A,F$1,[1]weekly_demand!$C:$C,$A46)) | G46: =IF($A46="","",SUMIFS([1]weekly_demand!$D:$D,[1]weekly_demand!$A:$A,G$1,[1]weekly_demand!$C:$C,$A46))
B47: =IF($A47="","",SUMIFS([1]weekly_demand!$D:$D,[1]weekly_demand!$A:$A,B$1,[1]weekly_demand!$C:$C,$A47)) | C47: =IF($A47="","",SUMIFS([1]weekly_demand!$D:$D,[1]weekly_demand!$A:$A,C$1,[1]weekly_demand!$C:$C,$A47)) | D47: =IF($A47="","",SUMIFS([1]weekly_demand!$D:$D,[1]weekly_demand!$A:$A,D$1,[1]weekly_demand!$C:$C,$A47)) | E47: =IF($A47="","",SUMIFS([1]weekly_demand!$D:$D,[1]weekly_demand!$A:$A,E$1,[1]weekly_demand!$C:$C,$A47)) | F47: =IF($A47="","",SUMIFS([1]weekly_demand!$D:$D,[1]weekly_demand!$A:$A,F$1,[1]weekly_demand!$C:$C,$A47)) | G47: =IF($A47="","",SUMIFS([1]weekly_demand!$D:$D,[1]weekly_demand!$A:$A,G$1,[1]weekly_demand!$C:$C,$A47))
B48: =IF($A48="","",SUMIFS([1]weekly_demand!$D:$D,[1]weekly_demand!$A:$A,B$1,[1]weekly_demand!$C:$C,$A48)) | C48: =IF($A48="","",SUMIFS([1]weekly_demand!$D:$D,[1]weekly_demand!$A:$A,C$1,[1]weekly_demand!$C:$C,$A48)) | D48: =IF($A48="","",SUMIFS([1]weekly_demand!$D:$D,[1]weekly_demand!$A:$A,D$1,[1]weekly_demand!$C:$C,$A48)) | E48: =IF($A48="","",SUMIFS([1]weekly_demand!$D:$D,[1]weekly_demand!$A:$A,E$1,[1]weekly_demand!$C:$C,$A48)) | F48: =IF($A48="","",SUMIFS([1]weekly_demand!$D:$D,[1]weekly_demand!$A:$A,F$1,[1]weekly_demand!$C:$C,$A48)) | G48: =IF($A48="","",SUMIFS([1]weekly_demand!$D:$D,[1]weekly_demand!$A:$A,G$1,[1]weekly_demand!$C:$C,$A48))
... B200: =IF($A200="","",SUMIFS([1]weekly_demand!$D:$D,[1]weekly_demand!$A:$A,B$1,[1]weekly_demand!$C:$C,$A200)) | C200: =IF($A200="","",SUMIFS([1]weekly_demand!$D:$D,[1]weekly_demand!$A:$A,C$1,[1]weekly_demand!$C:$C,$A200)) | D200: =IF($A200="","",SUMIFS([1]weekly_demand!$D:$D,[1]weekly_demand!$A:$A,D$1,[1]weekly_demand!$C:$C,$A200)) | E200: =IF($A200="","",SUMIFS([1]weekly_demand!$D:$D,[1]weekly_demand!$A:$A,E$1,[1]weekly_demand!$C:$C,$A200)) | F200: =IF($A200="","",SUMIFS([1]weekly_demand!$D:$D,[1]weekly_demand!$A:$A,F$1,[1]weekly_demand!$C:$C,$A200)) | G200: =IF($A200="","",SUMIFS([1]weekly_demand!$D:$D,[1]weekly_demand!$A:$A,G$1,[1]weekly_demand!$C:$C,$A200))

Sheet MPS
A1: SKU | B1: Fixture | C1: Week | D1: Weekly Capacity | E1: Total Demand | F1: Beginning FG Inv | G1: Storage Cap | H1: Carryover Needed | I1: Net Required | J1: Planned Production | K1: Ending FG Inv | L1: Shortage | M1: ATP | N1: Capacity Load % | O1: Planner Note | Q1: SKU | R1: Opening FG | S1: Storage Cap | U1: Logic
A2: {=_xlfn.UNIQUE(_xlfn.CHOOSECOLS(Demand_!A2:L466,1,6,11,7,12))} -> A | B2: 123AB | C2: 46139 | D2: 15000 | E2: 684 | F2: =IF($A2="","",IF($A2<>$A1,_xlfn.XLOOKUP($A2,$Q$2:$Q$7,$R$2:$R$7,0),K1)) -> 0 | G2: =IF($A2="","",_xlfn.XLOOKUP($A2,$Q$2:$Q$7,$S$2:$S$7,0)) -> 15000 | H2: =IF($A2="","",IF($A2<>$A3,0,MAX(0,H3+E3-D3))) -> 10000 | I2: =IF($A2="","",MAX(0,E2+H2-F2)) -> 10684 | J2: =IF($A2="","",MIN($D2,$I2,MAX(0,$E2+$G2-$F2))) -> 10684 | K2: =IF($A2="","",MIN($G2,MAX(0,$F2+$J2-$E2))) -> 10000 | L2: =IF($A2="","",MAX(0,E2-F2-J2)) -> 0 | M2: =IF($A2="","",MAX(0,F2+J2-E2)) -> 10000 | N2: =IF($A2="","",IFERROR(J2/D2,0)) -> 0.71226667 | Q2: A | R2: 0 | S2: 15000 | U2: Carryover Needed = lượng tồn phải build trước để cover tuần sau bị quá tải.
A3: A | B3: 123AB | C3: 46146 | D3: 15000 | E3: 20000 | F3: =IF($A3="","",IF($A3<>$A2,_xlfn.XLOOKUP($A3,$Q$2:$Q$7,$R$2:$R$7,0),K2)) -> 10000 | G3: =IF($A3="","",_xlfn.XLOOKUP($A3,$Q$2:$Q$7,$S$2:$S$7,0)) -> 15000 | H3: =IF($A3="","",IF($A3<>$A4,0,MAX(0,H4+E4-D4))) -> 5000 | I3: =IF($A3="","",MAX(0,E3+H3-F3)) -> 15000 | J3: =IF($A3="","",MIN($D3,$I3,MAX(0,$E3+$G3-$F3))) -> 15000 | K3: =IF($A3="","",MIN($G3,MAX(0,$F3+$J3-$E3))) -> 5000 | L3: =IF($A3="","",MAX(0,E3-F3-J3)) -> 0 | M3: =IF($A3="","",MAX(0,F3+J3-E3)) -> 5000 | N3: =IF($A3="","",IFERROR(J3/D3,0)) -> 1 | Q3: B | R3: 0 | S3: 15000 | U3: Nếu Fixture_Capacity_Input có dữ liệu cho fixture-week, MPS sẽ dùng capacity đó.
A4: A | B4: 123AB | C4: 46153 | D4: 15000 | E4: 20000 | F4: =IF($A4="","",IF($A4<>$A3,_xlfn.XLOOKUP($A4,$Q$2:$Q$7,$R$2:$R$7,0),K3)) -> 5000 | G4: =IF($A4="","",_xlfn.XLOOKUP($A4,$Q$2:$Q$7,$S$2:$S$7,0)) -> 15000 | H4: =IF($A4="","",IF($A4<>$A5,0,MAX(0,H5+E5-D5))) -> 0 | I4: =IF($A4="","",MAX(0,E4+H4-F4)) -> 15000 | J4: =IF($A4="","",MIN($D4,$I4,MAX(0,$E4+$G4-$F4))) -> 15000 | K4: =IF($A4="","",MIN($G4,MAX(0,$F4+$J4-$E4))) -> 0 | L4: =IF($A4="","",MAX(0,E4-F4-J4)) -> 0 | M4: =IF($A4="","",MAX(0,F4+J4-E4)) -> 0 | N4: =IF($A4="","",IFERROR(J4/D4,0)) -> 1 | Q4: C | R4: 0 | S4: 5000 | U4: Nếu Fixture_Capacity_Input trống, MPS dùng Weekly Capacity từ weekly_demand.
A5: A | B5: 123AB | C5: 46160 | D5: 15000 | E5: 11000 | F5: =IF($A5="","",IF($A5<>$A4,_xlfn.XLOOKUP($A5,$Q$2:$Q$7,$R$2:$R$7,0),K4)) -> 0 | G5: =IF($A5="","",_xlfn.XLOOKUP($A5,$Q$2:$Q$7,$S$2:$S$7,0)) -> 15000 | H5: =IF($A5="","",IF($A5<>$A6,0,MAX(0,H6+E6-D6))) -> 0 | I5: =IF($A5="","",MAX(0,E5+H5-F5)) -> 11000 | J5: =IF($A5="","",MIN($D5,$I5,MAX(0,$E5+$G5-$F5))) -> 11000 | K5: =IF($A5="","",MIN($G5,MAX(0,$F5+$J5-$E5))) -> 0 | L5: =IF($A5="","",MAX(0,E5-F5-J5)) -> 0 | M5: =IF($A5="","",MAX(0,F5+J5-E5)) -> 0 | N5: =IF($A5="","",IFERROR(J5/D5,0)) -> 0.73333333 | Q5: D | R5: 0 | S5: 5000
A6: A | B6: 123AB | C6: 46167 | D6: 15000 | E6: 13000 | F6: =IF($A6="","",IF($A6<>$A5,_xlfn.XLOOKUP($A6,$Q$2:$Q$7,$R$2:$R$7,0),K5)) -> 0 | G6: =IF($A6="","",_xlfn.XLOOKUP($A6,$Q$2:$Q$7,$S$2:$S$7,0)) -> 15000 | H6: =IF($A6="","",IF($A6<>$A7,0,MAX(0,H7+E7-D7))) -> 0 | I6: =IF($A6="","",MAX(0,E6+H6-F6)) -> 13000 | J6: =IF($A6="","",MIN($D6,$I6,MAX(0,$E6+$G6-$F6))) -> 13000 | K6: =IF($A6="","",MIN($G6,MAX(0,$F6+$J6-$E6))) -> 0 | L6: =IF($A6="","",MAX(0,E6-F6-J6)) -> 0 | M6: =IF($A6="","",MAX(0,F6+J6-E6)) -> 0 | N6: =IF($A6="","",IFERROR(J6/D6,0)) -> 0.86666667 | Q6: E | R6: 0 | S6: 3000
A7: A | B7: 123AB | C7: 46174 | D7: 15000 | E7: 13773 | F7: =IF($A7="","",IF($A7<>$A6,_xlfn.XLOOKUP($A7,$Q$2:$Q$7,$R$2:$R$7,0),K6)) -> 0 | G7: =IF($A7="","",_xlfn.XLOOKUP($A7,$Q$2:$Q$7,$S$2:$S$7,0)) -> 15000 | H7: =IF($A7="","",IF($A7<>$A8,0,MAX(0,H8+E8-D8))) -> 0 | I7: =IF($A7="","",MAX(0,E7+H7-F7)) -> 13773 | J7: =IF($A7="","",MIN($D7,$I7,MAX(0,$E7+$G7-$F7))) -> 13773 | K7: =IF($A7="","",MIN($G7,MAX(0,$F7+$J7-$E7))) -> 0 | L7: =IF($A7="","",MAX(0,E7-F7-J7)) -> 0 | M7: =IF($A7="","",MAX(0,F7+J7-E7)) -> 0 | N7: =IF($A7="","",IFERROR(J7/D7,0)) -> 0.9182 | Q7: F | R7: 0 | S7: 3000
A8: A | B8: 123AB | C8: 46181 | D8: 15000 | E8: 7058 | F8: =IF($A8="","",IF($A8<>$A7,_xlfn.XLOOKUP($A8,$Q$2:$Q$7,$R$2:$R$7,0),K7)) -> 0 | G8: =IF($A8="","",_xlfn.XLOOKUP($A8,$Q$2:$Q$7,$S$2:$S$7,0)) -> 15000 | H8: =IF($A8="","",IF($A8<>$A9,0,MAX(0,H9+E9-D9))) -> 0 | I8: =IF($A8="","",MAX(0,E8+H8-F8)) -> 7058 | J8: =IF($A8="","",MIN($D8,$I8,MAX(0,$E8+$G8-$F8))) -> 7058 | K8: =IF($A8="","",MIN($G8,MAX(0,$F8+$J8-$E8))) -> 0 | L8: =IF($A8="","",MAX(0,E8-F8-J8)) -> 0 | M8: =IF($A8="","",MAX(0,F8+J8-E8)) -> 0 | N8: =IF($A8="","",IFERROR(J8/D8,0)) -> 0.47053333
A9: A | B9: 123AB | C9: 46188 | D9: 15000 | E9: 2040 | F9: =IF($A9="","",IF($A9<>$A8,_xlfn.XLOOKUP($A9,$Q$2:$Q$7,$R$2:$R$7,0),K8)) -> 0 | G9: =IF($A9="","",_xlfn.XLOOKUP($A9,$Q$2:$Q$7,$S$2:$S$7,0)) -> 15000 | H9: =IF($A9="","",IF($A9<>$A10,0,MAX(0,H10+E10-D10))) -> 6868 | I9: =IF($A9="","",MAX(0,E9+H9-F9)) -> 8908 | J9: =IF($A9="","",MIN($D9,$I9,MAX(0,$E9+$G9-$F9))) -> 8908 | K9: =IF($A9="","",MIN($G9,MAX(0,$F9+$J9-$E9))) -> 6868 | L9: =IF($A9="","",MAX(0,E9-F9-J9)) -> 0 | M9: =IF($A9="","",MAX(0,F9+J9-E9)) -> 6868 | N9: =IF($A9="","",IFERROR(J9/D9,0)) -> 0.59386667
A10: A | B10: 123AB | C10: 46195 | D10: 15000 | E10: 3541 | F10: =IF($A10="","",IF($A10<>$A9,_xlfn.XLOOKUP($A10,$Q$2:$Q$7,$R$2:$R$7,0),K9)) -> 6868 | G10: =IF($A10="","",_xlfn.XLOOKUP($A10,$Q$2:$Q$7,$S$2:$S$7,0)) -> 15000 | H10: =IF($A10="","",IF($A10<>$A11,0,MAX(0,H11+E11-D11))) -> 18327 | I10: =IF($A10="","",MAX(0,E10+H10-F10)) -> 15000 | J10: =IF($A10="","",MIN($D10,$I10,MAX(0,$E10+$G10-$F10))) -> 11673 | K10: =IF($A10="","",MIN($G10,MAX(0,$F10+$J10-$E10))) -> 15000 | L10: =IF($A10="","",MAX(0,E10-F10-J10)) -> 0 | M10: =IF($A10="","",MAX(0,F10+J10-E10)) -> 15000 | N10: =IF($A10="","",IFERROR(J10/D10,0)) -> 0.7782
A11: A | B11: 123AB | C11: 46202 | D11: 15000 | E11: 12041 | F11: =IF($A11="","",IF($A11<>$A10,_xlfn.XLOOKUP($A11,$Q$2:$Q$7,$R$2:$R$7,0),K10)) -> 15000 | G11: =IF($A11="","",_xlfn.XLOOKUP($A11,$Q$2:$Q$7,$S$2:$S$7,0)) -> 15000 | H11: =IF($A11="","",IF($A11<>$A12,0,MAX(0,H12+E12-D12))) -> 21286 | I11: =IF($A11="","",MAX(0,E11+H11-F11)) -> 18327 | J11: =IF($A11="","",MIN($D11,$I11,MAX(0,$E11+$G11-$F11))) -> 12041 | K11: =IF($A11="","",MIN($G11,MAX(0,$F11+$J11-$E11))) -> 15000 | L11: =IF($A11="","",MAX(0,E11-F11-J11)) -> 0 | M11: =IF($A11="","",MAX(0,F11+J11-E11)) -> 15000 | N11: =IF($A11="","",IFERROR(J11/D11,0)) -> 0.80273333
A12: A | B12: 123AB | C12: 46209 | D12: 15000 | E12: 12040 | F12: =IF($A12="","",IF($A12<>$A11,_xlfn.XLOOKUP($A12,$Q$2:$Q$7,$R$2:$R$7,0),K11)) -> 15000 | G12: =IF($A12="","",_xlfn.XLOOKUP($A12,$Q$2:$Q$7,$S$2:$S$7,0)) -> 15000 | H12: =IF($A12="","",IF($A12<>$A13,0,MAX(0,H13+E13-D13))) -> 24246 | I12: =IF($A12="","",MAX(0,E12+H12-F12)) -> 21286 | J12: =IF($A12="","",MIN($D12,$I12,MAX(0,$E12+$G12-$F12))) -> 12040 | K12: =IF($A12="","",MIN($G12,MAX(0,$F12+$J12-$E12))) -> 15000 | L12: =IF($A12="","",MAX(0,E12-F12-J12)) -> 0 | M12: =IF($A12="","",MAX(0,F12+J12-E12)) -> 15000 | N12: =IF($A12="","",IFERROR(J12/D12,0)) -> 0.80266667
A13: A | B13: 123AB | C13: 46230 | D13: 15000 | E13: 27760 | F13: =IF($A13="","",IF($A13<>$A12,_xlfn.XLOOKUP($A13,$Q$2:$Q$7,$R$2:$R$7,0),K12)) -> 15000 | G13: =IF($A13="","",_xlfn.XLOOKUP($A13,$Q$2:$Q$7,$S$2:$S$7,0)) -> 15000 | H13: =IF($A13="","",IF($A13<>$A14,0,MAX(0,H14+E14-D14))) -> 11486 | I13: =IF($A13="","",MAX(0,E13+H13-F13)) -> 24246 | J13: =IF($A13="","",MIN($D13,$I13,MAX(0,$E13+$G13-$F13))) -> 15000 | K13: =IF($A13="","",MIN($G13,MAX(0,$F13+$J13-$E13))) -> 2240 | L13: =IF($A13="","",MAX(0,E13-F13-J13)) -> 0 | M13: =IF($A13="","",MAX(0,F13+J13-E13)) -> 2240 | N13: =IF($A13="","",IFERROR(J13/D13,0)) -> 1
A14: A | B14: 123AB | C14: 46237 | D14: 15000 | E14: 26486 | F14: =IF($A14="","",IF($A14<>$A13,_xlfn.XLOOKUP($A14,$Q$2:$Q$7,$R$2:$R$7,0),K13)) -> 2240 | G14: =IF($A14="","",_xlfn.XLOOKUP($A14,$Q$2:$Q$7,$S$2:$S$7,0)) -> 15000 | H14: =IF($A14="","",IF($A14<>$A15,0,MAX(0,H15+E15-D15))) -> 0 | I14: =IF($A14="","",MAX(0,E14+H14-F14)) -> 24246 | J14: =IF($A14="","",MIN($D14,$I14,MAX(0,$E14+$G14-$F14))) -> 15000 | K14: =IF($A14="","",MIN($G14,MAX(0,$F14+$J14-$E14))) -> 0 | L14: =IF($A14="","",MAX(0,E14-F14-J14)) -> 9246 | M14: =IF($A14="","",MAX(0,F14+J14-E14)) -> 0 | N14: =IF($A14="","",IFERROR(J14/D14,0)) -> 1
A15: A | B15: 123AB | C15: 46244 | D15: 15000 | E15: 4248 | F15: =IF($A15="","",IF($A15<>$A14,_xlfn.XLOOKUP($A15,$Q$2:$Q$7,$R$2:$R$7,0),K14)) -> 0 | G15: =IF($A15="","",_xlfn.XLOOKUP($A15,$Q$2:$Q$7,$S$2:$S$7,0)) -> 15000 | H15: =IF($A15="","",IF($A15<>$A16,0,MAX(0,H16+E16-D16))) -> 0 | I15: =IF($A15="","",MAX(0,E15+H15-F15)) -> 4248 | J15: =IF($A15="","",MIN($D15,$I15,MAX(0,$E15+$G15-$F15))) -> 4248 | K15: =IF($A15="","",MIN($G15,MAX(0,$F15+$J15-$E15))) -> 0 | L15: =IF($A15="","",MAX(0,E15-F15-J15)) -> 0 | M15: =IF($A15="","",MAX(0,F15+J15-E15)) -> 0 | N15: =IF($A15="","",IFERROR(J15/D15,0)) -> 0.2832
A16: A | B16: 123AB | C16: 46251 | D16: 15000 | E16: 4248 | F16: =IF($A16="","",IF($A16<>$A15,_xlfn.XLOOKUP($A16,$Q$2:$Q$7,$R$2:$R$7,0),K15)) -> 0 | G16: =IF($A16="","",_xlfn.XLOOKUP($A16,$Q$2:$Q$7,$S$2:$S$7,0)) -> 15000 | H16: =IF($A16="","",IF($A16<>$A17,0,MAX(0,H17+E17-D17))) -> 0 | I16: =IF($A16="","",MAX(0,E16+H16-F16)) -> 4248 | J16: =IF($A16="","",MIN($D16,$I16,MAX(0,$E16+$G16-$F16))) -> 4248 | K16: =IF($A16="","",MIN($G16,MAX(0,$F16+$J16-$E16))) -> 0 | L16: =IF($A16="","",MAX(0,E16-F16-J16)) -> 0 | M16: =IF($A16="","",MAX(0,F16+J16-E16)) -> 0 | N16: =IF($A16="","",IFERROR(J16/D16,0)) -> 0.2832
A17: A | B17: 123AB | C17: 46258 | D17: 15000 | E17: 4249 | F17: =IF($A17="","",IF($A17<>$A16,_xlfn.XLOOKUP($A17,$Q$2:$Q$7,$R$2:$R$7,0),K16)) -> 0 | G17: =IF($A17="","",_xlfn.XLOOKUP($A17,$Q$2:$Q$7,$S$2:$S$7,0)) -> 15000 | H17: =IF($A17="","",IF($A17<>$A18,0,MAX(0,H18+E18-D18))) -> 0 | I17: =IF($A17="","",MAX(0,E17+H17-F17)) -> 4249 | J17: =IF($A17="","",MIN($D17,$I17,MAX(0,$E17+$G17-$F17))) -> 4249 | K17: =IF($A17="","",MIN($G17,MAX(0,$F17+$J17-$E17))) -> 0 | L17: =IF($A17="","",MAX(0,E17-F17-J17)) -> 0 | M17: =IF($A17="","",MAX(0,F17+J17-E17)) -> 0 | N17: =IF($A17="","",IFERROR(J17/D17,0)) -> 0.28326667
A18: A | B18: 123AB | C18: 46265 | D18: 15000 | E18: 4248 | F18: =IF($A18="","",IF($A18<>$A17,_xlfn.XLOOKUP($A18,$Q$2:$Q$7,$R$2:$R$7,0),K17)) -> 0 | G18: =IF($A18="","",_xlfn.XLOOKUP($A18,$Q$2:$Q$7,$S$2:$S$7,0)) -> 15000 | H18: =IF($A18="","",IF($A18<>$A19,0,MAX(0,H19+E19-D19))) -> 0 | I18: =IF($A18="","",MAX(0,E18+H18-F18)) -> 4248 | J18: =IF($A18="","",MIN($D18,$I18,MAX(0,$E18+$G18-$F18))) -> 4248 | K18: =IF($A18="","",MIN($G18,MAX(0,$F18+$J18-$E18))) -> 0 | L18: =IF($A18="","",MAX(0,E18-F18-J18)) -> 0 | M18: =IF($A18="","",MAX(0,F18+J18-E18)) -> 0 | N18: =IF($A18="","",IFERROR(J18/D18,0)) -> 0.2832
A19: A | B19: 123AB | C19: 46272 | D19: 15000 | E19: 2391 | F19: =IF($A19="","",IF($A19<>$A18,_xlfn.XLOOKUP($A19,$Q$2:$Q$7,$R$2:$R$7,0),K18)) -> 0 | G19: =IF($A19="","",_xlfn.XLOOKUP($A19,$Q$2:$Q$7,$S$2:$S$7,0)) -> 15000 | H19: =IF($A19="","",IF($A19<>$A20,0,MAX(0,H20+E20-D20))) -> 0 | I19: =IF($A19="","",MAX(0,E19+H19-F19)) -> 2391 | J19: =IF($A19="","",MIN($D19,$I19,MAX(0,$E19+$G19-$F19))) -> 2391 | K19: =IF($A19="","",MIN($G19,MAX(0,$F19+$J19-$E19))) -> 0 | L19: =IF($A19="","",MAX(0,E19-F19-J19)) -> 0 | M19: =IF($A19="","",MAX(0,F19+J19-E19)) -> 0 | N19: =IF($A19="","",IFERROR(J19/D19,0)) -> 0.1594
... A172: F | B172: 789EF | C172: 46370 | D172: 3000 | E172: 1928 | F172: =IF($A172="","",IF($A172<>$A171,_xlfn.XLOOKUP($A172,$Q$2:$Q$7,$R$2:$R$7,0),K171)) -> 0 | G172: =IF($A172="","",_xlfn.XLOOKUP($A172,$Q$2:$Q$7,$S$2:$S$7,0)) -> 3000 | H172: =IF($A172="","",IF($A172<>$A173,0,MAX(0,H173+E173-D173))) -> 0 | I172: =IF($A172="","",MAX(0,E172+H172-F172)) -> 1928 | J172: =IF($A172="","",MIN($D172,$I172,MAX(0,$E172+$G172-$F172))) -> 1928 | K172: =IF($A172="","",MIN($G172,MAX(0,$F172+$J172-$E172))) -> 0 | L172: =IF($A172="","",MAX(0,E172-F172-J172)) -> 0 | M172: =IF($A172="","",MAX(0,F172+J172-E172)) -> 0 | N172: =IF($A172="","",IFERROR(J172/D172,0)) -> 0.64266667
F173: =IF($A173="","",IF($A173<>$A172,_xlfn.XLOOKUP($A173,$Q$2:$Q$7,$R$2:$R$7,0),K172)) | G173: =IF($A173="","",_xlfn.XLOOKUP($A173,$Q$2:$Q$7,$S$2:$S$7,0)) | H173: =IF($A173="","",IF($A173<>$A174,0,MAX(0,H174+E174-D174))) | I173: =IF($A173="","",MAX(0,E173+H173-F173)) | J173: =IF($A173="","",MIN($D173,$I173,MAX(0,$E173+$G173-$F173))) | K173: =IF($A173="","",MIN($G173,MAX(0,$F173+$J173-$E173))) | L173: =IF($A173="","",MAX(0,E173-F173-J173)) | M173: =IF($A173="","",MAX(0,F173+J173-E173)) | N173: =IF($A173="","",IFERROR(J173/D173,0))
F174: =IF($A174="","",IF($A174<>$A173,_xlfn.XLOOKUP($A174,$Q$2:$Q$7,$R$2:$R$7,0),K173)) | G174: =IF($A174="","",_xlfn.XLOOKUP($A174,$Q$2:$Q$7,$S$2:$S$7,0)) | H174: =IF($A174="","",IF($A174<>$A175,0,MAX(0,H175+E175-D175))) | I174: =IF($A174="","",MAX(0,E174+H174-F174)) | J174: =IF($A174="","",MIN($D174,$I174,MAX(0,$E174+$G174-$F174))) | K174: =IF($A174="","",MIN($G174,MAX(0,$F174+$J174-$E174))) | L174: =IF($A174="","",MAX(0,E174-F174-J174)) | M174: =IF($A174="","",MAX(0,F174+J174-E174)) | N174: =IF($A174="","",IFERROR(J174/D174,0))
F175: =IF($A175="","",IF($A175<>$A174,_xlfn.XLOOKUP($A175,$Q$2:$Q$7,$R$2:$R$7,0),K174)) | G175: =IF($A175="","",_xlfn.XLOOKUP($A175,$Q$2:$Q$7,$S$2:$S$7,0)) | H175: =IF($A175="","",IF($A175<>$A176,0,MAX(0,H176+E176-D176))) | I175: =IF($A175="","",MAX(0,E175+H175-F175)) | J175: =IF($A175="","",MIN($D175,$I175,MAX(0,$E175+$G175-$F175))) | K175: =IF($A175="","",MIN($G175,MAX(0,$F175+$J175-$E175))) | L175: =IF($A175="","",MAX(0,E175-F175-J175)) | M175: =IF($A175="","",MAX(0,F175+J175-E175)) | N175: =IF($A175="","",IFERROR(J175/D175,0))
F176: =IF($A176="","",IF($A176<>$A175,_xlfn.XLOOKUP($A176,$Q$2:$Q$7,$R$2:$R$7,0),K175)) | G176: =IF($A176="","",_xlfn.XLOOKUP($A176,$Q$2:$Q$7,$S$2:$S$7,0)) | H176: =IF($A176="","",IF($A176<>$A177,0,MAX(0,H177+E177-D177))) | I176: =IF($A176="","",MAX(0,E176+H176-F176)) | J176: =IF($A176="","",MIN($D176,$I176,MAX(0,$E176+$G176-$F176))) | K176: =IF($A176="","",MIN($G176,MAX(0,$F176+$J176-$E176))) | L176: =IF($A176="","",MAX(0,E176-F176-J176)) | M176: =IF($A176="","",MAX(0,F176+J176-E176)) | N176: =IF($A176="","",IFERROR(J176/D176,0))
F177: =IF($A177="","",IF($A177<>$A176,_xlfn.XLOOKUP($A177,$Q$2:$Q$7,$R$2:$R$7,0),K176)) | G177: =IF($A177="","",_xlfn.XLOOKUP($A177,$Q$2:$Q$7,$S$2:$S$7,0)) | H177: =IF($A177="","",IF($A177<>$A178,0,MAX(0,H178+E178-D178))) | I177: =IF($A177="","",MAX(0,E177+H177-F177)) | J177: =IF($A177="","",MIN($D177,$I177,MAX(0,$E177+$G177-$F177))) | K177: =IF($A177="","",MIN($G177,MAX(0,$F177+$J177-$E177))) | L177: =IF($A177="","",MAX(0,E177-F177-J177)) | M177: =IF($A177="","",MAX(0,F177+J177-E177)) | N177: =IF($A177="","",IFERROR(J177/D177,0))
F178: =IF($A178="","",IF($A178<>$A177,_xlfn.XLOOKUP($A178,$Q$2:$Q$7,$R$2:$R$7,0),K177)) | G178: =IF($A178="","",_xlfn.XLOOKUP($A178,$Q$2:$Q$7,$S$2:$S$7,0)) | H178: =IF($A178="","",IF($A178<>$A179,0,MAX(0,H179+E179-D179))) | I178: =IF($A178="","",MAX(0,E178+H178-F178)) | J178: =IF($A178="","",MIN($D178,$I178,MAX(0,$E178+$G178-$F178))) | K178: =IF($A178="","",MIN($G178,MAX(0,$F178+$J178-$E178))) | L178: =IF($A178="","",MAX(0,E178-F178-J178)) | M178: =IF($A178="","",MAX(0,F178+J178-E178)) | N178: =IF($A178="","",IFERROR(J178/D178,0))
F179: =IF($A179="","",IF($A179<>$A178,_xlfn.XLOOKUP($A179,$Q$2:$Q$7,$R$2:$R$7,0),K178)) | G179: =IF($A179="","",_xlfn.XLOOKUP($A179,$Q$2:$Q$7,$S$2:$S$7,0)) | H179: =IF($A179="","",IF($A179<>$A180,0,MAX(0,H180+E180-D180))) | I179: =IF($A179="","",MAX(0,E179+H179-F179)) | J179: =IF($A179="","",MIN($D179,$I179,MAX(0,$E179+$G179-$F179))) | K179: =IF($A179="","",MIN($G179,MAX(0,$F179+$J179-$E179))) | L179: =IF($A179="","",MAX(0,E179-F179-J179)) | M179: =IF($A179="","",MAX(0,F179+J179-E179)) | N179: =IF($A179="","",IFERROR(J179/D179,0))
F180: =IF($A180="","",IF($A180<>$A179,_xlfn.XLOOKUP($A180,$Q$2:$Q$7,$R$2:$R$7,0),K179)) | G180: =IF($A180="","",_xlfn.XLOOKUP($A180,$Q$2:$Q$7,$S$2:$S$7,0)) | H180: =IF($A180="","",IF($A180<>$A181,0,MAX(0,H181+E181-D181))) | I180: =IF($A180="","",MAX(0,E180+H180-F180)) | J180: =IF($A180="","",MIN($D180,$I180,MAX(0,$E180+$G180-$F180))) | K180: =IF($A180="","",MIN($G180,MAX(0,$F180+$J180-$E180))) | L180: =IF($A180="","",MAX(0,E180-F180-J180)) | M180: =IF($A180="","",MAX(0,F180+J180-E180)) | N180: =IF($A180="","",IFERROR(J180/D180,0))
F181: =IF($A181="","",IF($A181<>$A180,_xlfn.XLOOKUP($A181,$Q$2:$Q$7,$R$2:$R$7,0),K180)) | G181: =IF($A181="","",_xlfn.XLOOKUP($A181,$Q$2:$Q$7,$S$2:$S$7,0)) | H181: =IF($A181="","",IF($A181<>$A182,0,MAX(0,H182+E182-D182))) | I181: =IF($A181="","",MAX(0,E181+H181-F181)) | J181: =IF($A181="","",MIN($D181,$I181,MAX(0,$E181+$G181-$F181))) | K181: =IF($A181="","",MIN($G181,MAX(0,$F181+$J181-$E181))) | L181: =IF($A181="","",MAX(0,E181-F181-J181)) | M181: =IF($A181="","",MAX(0,F181+J181-E181)) | N181: =IF($A181="","",IFERROR(J181/D181,0))
F182: =IF($A182="","",IF($A182<>$A181,_xlfn.XLOOKUP($A182,$Q$2:$Q$7,$R$2:$R$7,0),K181)) | G182: =IF($A182="","",_xlfn.XLOOKUP($A182,$Q$2:$Q$7,$S$2:$S$7,0)) | H182: =IF($A182="","",IF($A182<>$A183,0,MAX(0,H183+E183-D183))) | I182: =IF($A182="","",MAX(0,E182+H182-F182)) | J182: =IF($A182="","",MIN($D182,$I182,MAX(0,$E182+$G182-$F182))) | K182: =IF($A182="","",MIN($G182,MAX(0,$F182+$J182-$E182))) | L182: =IF($A182="","",MAX(0,E182-F182-J182)) | M182: =IF($A182="","",MAX(0,F182+J182-E182)) | N182: =IF($A182="","",IFERROR(J182/D182,0))
F183: =IF($A183="","",IF($A183<>$A182,_xlfn.XLOOKUP($A183,$Q$2:$Q$7,$R$2:$R$7,0),K182)) | G183: =IF($A183="","",_xlfn.XLOOKUP($A183,$Q$2:$Q$7,$S$2:$S$7,0)) | H183: =IF($A183="","",IF($A183<>$A184,0,MAX(0,H184+E184-D184))) | I183: =IF($A183="","",MAX(0,E183+H183-F183)) | J183: =IF($A183="","",MIN($D183,$I183,MAX(0,$E183+$G183-$F183))) | K183: =IF($A183="","",MIN($G183,MAX(0,$F183+$J183-$E183))) | L183: =IF($A183="","",MAX(0,E183-F183-J183)) | M183: =IF($A183="","",MAX(0,F183+J183-E183)) | N183: =IF($A183="","",IFERROR(J183/D183,0))
F184: =IF($A184="","",IF($A184<>$A183,_xlfn.XLOOKUP($A184,$Q$2:$Q$7,$R$2:$R$7,0),K183)) | G184: =IF($A184="","",_xlfn.XLOOKUP($A184,$Q$2:$Q$7,$S$2:$S$7,0)) | H184: =IF($A184="","",IF($A184<>$A185,0,MAX(0,H185+E185-D185))) | I184: =IF($A184="","",MAX(0,E184+H184-F184)) | J184: =IF($A184="","",MIN($D184,$I184,MAX(0,$E184+$G184-$F184))) | K184: =IF($A184="","",MIN($G184,MAX(0,$F184+$J184-$E184))) | L184: =IF($A184="","",MAX(0,E184-F184-J184)) | M184: =IF($A184="","",MAX(0,F184+J184-E184)) | N184: =IF($A184="","",IFERROR(J184/D184,0))
... F255: =IF($A255="","",IF($A255<>$A254,_xlfn.XLOOKUP($A255,$Q$2:$Q$7,$R$2:$R$7,0),K254)) | G255: =IF($A255="","",_xlfn.XLOOKUP($A255,$Q$2:$Q$7,$S$2:$S$7,0)) | H255: =IF($A255="","",IF($A255<>$A256,0,MAX(0,H256+E256-D256))) | I255: =IF($A255="","",MAX(0,E255+H255-F255)) | J255: =IF($A255="","",MIN($D255,$I255,MAX(0,$E255+$G255-$F255))) | K255: =IF($A255="","",MIN($G255,MAX(0,$F255+$J255-$E255))) | L255: =IF($A255="","",MAX(0,E255-F255-J255)) | M255: =IF($A255="","",MAX(0,F255+J255-E255)) | N255: =IF($A255="","",IFERROR(J255/D255,0))
A256: =IF([2]weekly_demand!A257="","",[2]weekly_demand!A257) | B256: =IF($A256="","",[2]weekly_demand!F257) | C256: =IF($A256="","",[2]weekly_demand!H257) | D256: =IF($A256="","",IF(SUMIFS([2]Fixture_Capacity_Input!$C:$C,[2]Fixture_Capacity_Input!$A:$A,$B256,[2]Fixture_Capacity_Input!$B:$B,$C256)>0,SUMIFS([2]Fixture_Capacity_Input!$C:$C,[2]Fixture_Capacity_Input!$A:$A,$B256,[2]Fixture_Capacity_Input!$B:$B,$C256),[2]weekly_demand!G257)) | E256: =IF($A256="","",[2]weekly_demand!I257) | F256: =IF($A256="","",IF($A256<>$A255,_xlfn.XLOOKUP($A256,$Q$2:$Q$7,$R$2:$R$7,0),K255)) | G256: =IF($A256="","",_xlfn.XLOOKUP($A256,$Q$2:$Q$7,$S$2:$S$7,0)) | H256: =IF($A256="","",IF($A256<>$A257,0,MAX(0,H257+E257-D257))) | I256: =IF($A256="","",MAX(0,E256+H256-F256)) | J256: =IF($A256="","",MIN($D256,$I256,MAX(0,$E256+$G256-$F256))) | K256: =IF($A256="","",MIN($G256,MAX(0,$F256+$J256-$E256))) | L256: =IF($A256="","",MAX(0,E256-F256-J256)) | M256: =IF($A256="","",MAX(0,F256+J256-E256)) | N256: =IF($A256="","",IFERROR(J256/D256,0))
A257: =IF([2]weekly_demand!A258="","",[2]weekly_demand!A258) | B257: =IF($A257="","",[2]weekly_demand!F258) | C257: =IF($A257="","",[2]weekly_demand!H258) | D257: =IF($A257="","",IF(SUMIFS([2]Fixture_Capacity_Input!$C:$C,[2]Fixture_Capacity_Input!$A:$A,$B257,[2]Fixture_Capacity_Input!$B:$B,$C257)>0,SUMIFS([2]Fixture_Capacity_Input!$C:$C,[2]Fixture_Capacity_Input!$A:$A,$B257,[2]Fixture_Capacity_Input!$B:$B,$C257),[2]weekly_demand!G258)) | E257: =IF($A257="","",[2]weekly_demand!I258) | F257: =IF($A257="","",IF($A257<>$A256,_xlfn.XLOOKUP($A257,$Q$2:$Q$7,$R$2:$R$7,0),K256)) | G257: =IF($A257="","",_xlfn.XLOOKUP($A257,$Q$2:$Q$7,$S$2:$S$7,0)) | H257: =IF($A257="","",IF($A257<>$A258,0,MAX(0,H258+E258-D258))) | I257: =IF($A257="","",MAX(0,E257+H257-F257)) | J257: =IF($A257="","",MIN($D257,$I257,MAX(0,$E257+$G257-$F257))) | K257: =IF($A257="","",MIN($G257,MAX(0,$F257+$J257-$E257))) | L257: =IF($A257="","",MAX(0,E257-F257-J257)) | M257: =IF($A257="","",MAX(0,F257+J257-E257)) | N257: =IF($A257="","",IFERROR(J257/D257,0))
A258: =IF([2]weekly_demand!A259="","",[2]weekly_demand!A259) | B258: =IF($A258="","",[2]weekly_demand!F259) | C258: =IF($A258="","",[2]weekly_demand!H259) | D258: =IF($A258="","",IF(SUMIFS([2]Fixture_Capacity_Input!$C:$C,[2]Fixture_Capacity_Input!$A:$A,$B258,[2]Fixture_Capacity_Input!$B:$B,$C258)>0,SUMIFS([2]Fixture_Capacity_Input!$C:$C,[2]Fixture_Capacity_Input!$A:$A,$B258,[2]Fixture_Capacity_Input!$B:$B,$C258),[2]weekly_demand!G259)) | E258: =IF($A258="","",[2]weekly_demand!I259) | F258: =IF($A258="","",IF($A258<>$A257,_xlfn.XLOOKUP($A258,$Q$2:$Q$7,$R$2:$R$7,0),K257)) | G258: =IF($A258="","",_xlfn.XLOOKUP($A258,$Q$2:$Q$7,$S$2:$S$7,0)) | H258: =IF($A258="","",IF($A258<>$A259,0,MAX(0,H259+E259-D259))) | I258: =IF($A258="","",MAX(0,E258+H258-F258)) | J258: =IF($A258="","",MIN($D258,$I258,MAX(0,$E258+$G258-$F258))) | K258: =IF($A258="","",MIN($G258,MAX(0,$F258+$J258-$E258))) | L258: =IF($A258="","",MAX(0,E258-F258-J258)) | M258: =IF($A258="","",MAX(0,F258+J258-E258)) | N258: =IF($A258="","",IFERROR(J258/D258,0))
A259: =IF([2]weekly_demand!A260="","",[2]weekly_demand!A260) | B259: =IF($A259="","",[2]weekly_demand!F260) | C259: =IF($A259="","",[2]weekly_demand!H260) | D259: =IF($A259="","",IF(SUMIFS([2]Fixture_Capacity_Input!$C:$C,[2]Fixture_Capacity_Input!$A:$A,$B259,[2]Fixture_Capacity_Input!$B:$B,$C259)>0,SUMIFS([2]Fixture_Capacity_Input!$C:$C,[2]Fixture_Capacity_Input!$A:$A,$B259,[2]Fixture_Capacity_Input!$B:$B,$C259),[2]weekly_demand!G260)) | E259: =IF($A259="","",[2]weekly_demand!I260) | F259: =IF($A259="","",IF($A259<>$A258,_xlfn.XLOOKUP($A259,$Q$2:$Q$7,$R$2:$R$7,0),K258)) | G259: =IF($A259="","",_xlfn.XLOOKUP($A259,$Q$2:$Q$7,$S$2:$S$7,0)) | H259: =IF($A259="","",IF($A259<>$A260,0,MAX(0,H260+E260-D260))) | I259: =IF($A259="","",MAX(0,E259+H259-F259)) | J259: =IF($A259="","",MIN($D259,$I259,MAX(0,$E259+$G259-$F259))) | K259: =IF($A259="","",MIN($G259,MAX(0,$F259+$J259-$E259))) | L259: =IF($A259="","",MAX(0,E259-F259-J259)) | M259: =IF($A259="","",MAX(0,F259+J259-E259)) | N259: =IF($A259="","",IFERROR(J259/D259,0))
A260: =IF([2]weekly_demand!A261="","",[2]weekly_demand!A261) | B260: =IF($A260="","",[2]weekly_demand!F261) | C260: =IF($A260="","",[2]weekly_demand!H261) | D260: =IF($A260="","",IF(SUMIFS([2]Fixture_Capacity_Input!$C:$C,[2]Fixture_Capacity_Input!$A:$A,$B260,[2]Fixture_Capacity_Input!$B:$B,$C260)>0,SUMIFS([2]Fixture_Capacity_Input!$C:$C,[2]Fixture_Capacity_Input!$A:$A,$B260,[2]Fixture_Capacity_Input!$B:$B,$C260),[2]weekly_demand!G261)) | E260: =IF($A260="","",[2]weekly_demand!I261) | F260: =IF($A260="","",IF($A260<>$A259,_xlfn.XLOOKUP($A260,$Q$2:$Q$7,$R$2:$R$7,0),K259)) | G260: =IF($A260="","",_xlfn.XLOOKUP($A260,$Q$2:$Q$7,$S$2:$S$7,0)) | H260: =IF($A260="","",IF($A260<>$A261,0,MAX(0,H261+E261-D261))) | I260: =IF($A260="","",MAX(0,E260+H260-F260)) | J260: =IF($A260="","",MIN($D260,$I260,MAX(0,$E260+$G260-$F260))) | K260: =IF($A260="","",MIN($G260,MAX(0,$F260+$J260-$E260))) | L260: =IF($A260="","",MAX(0,E260-F260-J260)) | M260: =IF($A260="","",MAX(0,F260+J260-E260)) | N260: =IF($A260="","",IFERROR(J260/D260,0))
A261: =IF([2]weekly_demand!A262="","",[2]weekly_demand!A262) | B261: =IF($A261="","",[2]weekly_demand!F262) | C261: =IF($A261="","",[2]weekly_demand!H262) | D261: =IF($A261="","",IF(SUMIFS([2]Fixture_Capacity_Input!$C:$C,[2]Fixture_Capacity_Input!$A:$A,$B261,[2]Fixture_Capacity_Input!$B:$B,$C261)>0,SUMIFS([2]Fixture_Capacity_Input!$C:$C,[2]Fixture_Capacity_Input!$A:$A,$B261,[2]Fixture_Capacity_Input!$B:$B,$C261),[2]weekly_demand!G262)) | E261: =IF($A261="","",[2]weekly_demand!I262) | F261: =IF($A261="","",IF($A261<>$A260,_xlfn.XLOOKUP($A261,$Q$2:$Q$7,$R$2:$R$7,0),K260)) | G261: =IF($A261="","",_xlfn.XLOOKUP($A261,$Q$2:$Q$7,$S$2:$S$7,0)) | H261: =IF($A261="","",IF($A261<>$A262,0,MAX(0,H262+E262-D262))) | I261: =IF($A261="","",MAX(0,E261+H261-F261)) | J261: =IF($A261="","",MIN($D261,$I261,MAX(0,$E261+$G261-$F261))) | K261: =IF($A261="","",MIN($G261,MAX(0,$F261+$J261-$E261))) | L261: =IF($A261="","",MAX(0,E261-F261-J261)) | M261: =IF($A261="","",MAX(0,F261+J261-E261)) | N261: =IF($A261="","",IFERROR(J261/D261,0))
A262: =IF([2]weekly_demand!A263="","",[2]weekly_demand!A263) | B262: =IF($A262="","",[2]weekly_demand!F263) | C262: =IF($A262="","",[2]weekly_demand!H263) | D262: =IF($A262="","",IF(SUMIFS([2]Fixture_Capacity_Input!$C:$C,[2]Fixture_Capacity_Input!$A:$A,$B262,[2]Fixture_Capacity_Input!$B:$B,$C262)>0,SUMIFS([2]Fixture_Capacity_Input!$C:$C,[2]Fixture_Capacity_Input!$A:$A,$B262,[2]Fixture_Capacity_Input!$B:$B,$C262),[2]weekly_demand!G263)) | E262: =IF($A262="","",[2]weekly_demand!I263) | F262: =IF($A262="","",IF($A262<>$A261,_xlfn.XLOOKUP($A262,$Q$2:$Q$7,$R$2:$R$7,0),K261)) | G262: =IF($A262="","",_xlfn.XLOOKUP($A262,$Q$2:$Q$7,$S$2:$S$7,0)) | H262: =IF($A262="","",IF($A262<>$A263,0,MAX(0,H263+E263-D263))) | I262: =IF($A262="","",MAX(0,E262+H262-F262)) | J262: =IF($A262="","",MIN($D262,$I262,MAX(0,$E262+$G262-$F262))) | K262: =IF($A262="","",MIN($G262,MAX(0,$F262+$J262-$E262))) | L262: =IF($A262="","",MAX(0,E262-F262-J262)) | M262: =IF($A262="","",MAX(0,F262+J262-E262)) | N262: =IF($A262="","",IFERROR(J262/D262,0))
...

Sheet BOM_demand
A1: Week | B1: A | C1: B | D1: C | E1: D | F1: E | G1: F | H1: RM01 | I1: RM02 | J1: RM03 | K1: RM04 | L1: RM05 | M1: RM06 | N1: RM07 | O1: RM08 | P1: RM09 | Q1: RM10 | R1: RM11 | S1: RM12 | T1: RM13 | U1: RM14 | V1: RM15 | X1: BOM usage helper | Y1: A | Z1: B | AA1: C | AB1: D | AC1: E | AD1: F
A2: 46132 | B2: =IF($A2="","",SUMIFS(MPS!$J:$J,MPS!$A:$A,B$1,MPS!$C:$C,$A2)) -> 0 | C2: =IF($A2="","",SUMIFS(MPS!$J:$J,MPS!$A:$A,C$1,MPS!$C:$C,$A2)) -> 0 | D2: =IF($A2="","",SUMIFS(MPS!$J:$J,MPS!$A:$A,D$1,MPS!$C:$C,$A2)) -> 0 | E2: =IF($A2="","",SUMIFS(MPS!$J:$J,MPS!$A:$A,E$1,MPS!$C:$C,$A2)) -> 0 | F2: =IF($A2="","",SUMIFS(MPS!$J:$J,MPS!$A:$A,F$1,MPS!$C:$C,$A2)) -> 0 | G2: =IF($A2="","",SUMIFS(MPS!$J:$J,MPS!$A:$A,G$1,MPS!$C:$C,$A2)) -> 3000 | H2: =IF($A2="","",SUMPRODUCT($B2:$G2,INDEX($Y$2:$AD$16,MATCH(H$1,$X$2:$X$16,0),0))) -> 3000 | I2: =IF($A2="","",SUMPRODUCT($B2:$G2,INDEX($Y$2:$AD$16,MATCH(I$1,$X$2:$X$16,0),0))) -> 375 | J2: =IF($A2="","",SUMPRODUCT($B2:$G2,INDEX($Y$2:$AD$16,MATCH(J$1,$X$2:$X$16,0),0))) -> 3000 | K2: =IF($A2="","",SUMPRODUCT($B2:$G2,INDEX($Y$2:$AD$16,MATCH(K$1,$X$2:$X$16,0),0))) -> 0 | L2: =IF($A2="","",SUMPRODUCT($B2:$G2,INDEX($Y$2:$AD$16,MATCH(L$1,$X$2:$X$16,0),0))) -> 0 | M2: =IF($A2="","",SUMPRODUCT($B2:$G2,INDEX($Y$2:$AD$16,MATCH(M$1,$X$2:$X$16,0),0))) -> 0 | N2: =IF($A2="","",SUMPRODUCT($B2:$G2,INDEX($Y$2:$AD$16,MATCH(N$1,$X$2:$X$16,0),0))) -> 0 | O2: =IF($A2="","",SUMPRODUCT($B2:$G2,INDEX($Y$2:$AD$16,MATCH(O$1,$X$2:$X$16,0),0))) -> 0 | ... V2: =IF($A2="","",SUMPRODUCT($B2:$G2,INDEX($Y$2:$AD$16,MATCH(V$1,$X$2:$X$16,0),0))) -> 6000 | X2: RM01 | Y2: 1 | Z2: 1 | AA2: 1 | AB2: 1 | AC2: 1 | AD2: 1
A3: 46139 | B3: =IF($A3="","",SUMIFS(MPS!$J:$J,MPS!$A:$A,B$1,MPS!$C:$C,$A3)) -> 10684 | C3: =IF($A3="","",SUMIFS(MPS!$J:$J,MPS!$A:$A,C$1,MPS!$C:$C,$A3)) -> 0 | D3: =IF($A3="","",SUMIFS(MPS!$J:$J,MPS!$A:$A,D$1,MPS!$C:$C,$A3)) -> 0 | E3: =IF($A3="","",SUMIFS(MPS!$J:$J,MPS!$A:$A,E$1,MPS!$C:$C,$A3)) -> 0 | F3: =IF($A3="","",SUMIFS(MPS!$J:$J,MPS!$A:$A,F$1,MPS!$C:$C,$A3)) -> 472 | G3: =IF($A3="","",SUMIFS(MPS!$J:$J,MPS!$A:$A,G$1,MPS!$C:$C,$A3)) -> 3000 | H3: =IF($A3="","",SUMPRODUCT($B3:$G3,INDEX($Y$2:$AD$16,MATCH(H$1,$X$2:$X$16,0),0))) -> 14156 | I3: =IF($A3="","",SUMPRODUCT($B3:$G3,INDEX($Y$2:$AD$16,MATCH(I$1,$X$2:$X$16,0),0))) -> 3282 | J3: =IF($A3="","",SUMPRODUCT($B3:$G3,INDEX($Y$2:$AD$16,MATCH(J$1,$X$2:$X$16,0),0))) -> 14156 | K3: =IF($A3="","",SUMPRODUCT($B3:$G3,INDEX($Y$2:$AD$16,MATCH(K$1,$X$2:$X$16,0),0))) -> 21368 | L3: =IF($A3="","",SUMPRODUCT($B3:$G3,INDEX($Y$2:$AD$16,MATCH(L$1,$X$2:$X$16,0),0))) -> 10684 | M3: =IF($A3="","",SUMPRODUCT($B3:$G3,INDEX($Y$2:$AD$16,MATCH(M$1,$X$2:$X$16,0),0))) -> 0 | N3: =IF($A3="","",SUMPRODUCT($B3:$G3,INDEX($Y$2:$AD$16,MATCH(N$1,$X$2:$X$16,0),0))) -> 0 | O3: =IF($A3="","",SUMPRODUCT($B3:$G3,INDEX($Y$2:$AD$16,MATCH(O$1,$X$2:$X$16,0),0))) -> 0 | ... V3: =IF($A3="","",SUMPRODUCT($B3:$G3,INDEX($Y$2:$AD$16,MATCH(V$1,$X$2:$X$16,0),0))) -> 6000 | X3: RM02 | Y3: 0.25 | Z3: 0.25 | AA3: 0.5 | AB3: 0.25 | AC3: 0.5 | AD3: 0.125
A4: 46146 | B4: =IF($A4="","",SUMIFS(MPS!$J:$J,MPS!$A:$A,B$1,MPS!$C:$C,$A4)) -> 15000 | C4: =IF($A4="","",SUMIFS(MPS!$J:$J,MPS!$A:$A,C$1,MPS!$C:$C,$A4)) -> 6160 | D4: =IF($A4="","",SUMIFS(MPS!$J:$J,MPS!$A:$A,D$1,MPS!$C:$C,$A4)) -> 5000 | E4: =IF($A4="","",SUMIFS(MPS!$J:$J,MPS!$A:$A,E$1,MPS!$C:$C,$A4)) -> 5000 | F4: =IF($A4="","",SUMIFS(MPS!$J:$J,MPS!$A:$A,F$1,MPS!$C:$C,$A4)) -> 300 | G4: =IF($A4="","",SUMIFS(MPS!$J:$J,MPS!$A:$A,G$1,MPS!$C:$C,$A4)) -> 3000 | H4: =IF($A4="","",SUMPRODUCT($B4:$G4,INDEX($Y$2:$AD$16,MATCH(H$1,$X$2:$X$16,0),0))) -> 34460 | I4: =IF($A4="","",SUMPRODUCT($B4:$G4,INDEX($Y$2:$AD$16,MATCH(I$1,$X$2:$X$16,0),0))) -> 9565 | J4: =IF($A4="","",SUMPRODUCT($B4:$G4,INDEX($Y$2:$AD$16,MATCH(J$1,$X$2:$X$16,0),0))) -> 34460 | K4: =IF($A4="","",SUMPRODUCT($B4:$G4,INDEX($Y$2:$AD$16,MATCH(K$1,$X$2:$X$16,0),0))) -> 30000 | L4: =IF($A4="","",SUMPRODUCT($B4:$G4,INDEX($Y$2:$AD$16,MATCH(L$1,$X$2:$X$16,0),0))) -> 15000 | M4: =IF($A4="","",SUMPRODUCT($B4:$G4,INDEX($Y$2:$AD$16,MATCH(M$1,$X$2:$X$16,0),0))) -> 15400 | N4: =IF($A4="","",SUMPRODUCT($B4:$G4,INDEX($Y$2:$AD$16,MATCH(N$1,$X$2:$X$16,0),0))) -> 9240 | O4: =IF($A4="","",SUMPRODUCT($B4:$G4,INDEX($Y$2:$AD$16,MATCH(O$1,$X$2:$X$16,0),0))) -> 15000 | ... V4: =IF($A4="","",SUMPRODUCT($B4:$G4,INDEX($Y$2:$AD$16,MATCH(V$1,$X$2:$X$16,0),0))) -> 6000 | X4: RM03 | Y4: 1 | Z4: 1 | AA4: 1 | AB4: 1 | AC4: 1 | AD4: 1
