Workbook

Sheet Overall Case Study
C2: Context
C3: A toy company is facing troubles with planning and data visualization
C5: Problems:
C6: 1. Need to visualize master data
C7: 2. Need to balance demand & create master production scheduling (MPS) with inhouse capacity constraints
C8: 3. Need to create material requirement planning (MRP) then determine reorder point based on leadtime (LT)
B13: No | C13: Question | D13: Requirement
B14: 1 | C14: Visualize demand of 6 SKUs | D14: By Regions, Category, Total Value
B15: 2 | C15: Create master production scheduling (MPS) | D15: Generate a master production planning for whole year
B16: 3 | C16: Balance demand | D16: Based on current fixture set and weekly capacity to balance and suggest solution if over 1. Leverage demand 2. Buy more fixture
B17: 4 | C17: Create Material requirment Planning (MRP) | D17: Generate a material requirement planning following 6 SKUs' demand and BOM usage
B18: 5 | C18: Determine supply plan | D18: Based on leadtime, current stock on hand and pending PO to find out reorder point and fill out/ layout supply plan
B19: 6 | C19: Figure out safety stock strategy | D19: Based on vendor location to define stock on hand level by week or day or hour (local and oversea)

Sheet Demand
A1: Item name | B1: Des | C1: Market | D1: Price ($) | E1: Product group | F1: Fixture | G1: Weekly Capcity | H1: Shipment Request | I1: Demand Quantity
A2: F | B2: 2025 Fantasy Spaceship Model DIY kits | C2: US | D2: 90 | E2: Arts & Crafts Toy | F2: 789EF | G2: 3000 | H2: 46143 | I2: 588
A3: A | B3: 2026 Automatic Robot ver | C3: US | D3: 105 | E3: Electronic Toy | F3: 123AB | G3: 15000 | H3: 46150 | I3: 684
A4: E | B4: 2026 Scooter ver | C4: Australia | D4: 30 | E4: Outdoor & Sports Toy | F4: 789EF | G4: 3000 | H4: 46150 | I4: 472
A5: F | B5: 2025 Fantasy Spaceship Model DIY kits | C5: US | D5: 90 | E5: Arts & Crafts Toy | F5: 789EF | G5: 3000 | H5: 46150 | I5: 4028
A6: A | B6: 2026 Automatic Robot ver | C6: US | D6: 105 | E6: Electronic Toy | F6: 123AB | G6: 15000 | H6: 46157 | I6: 20000
A7: B | B7: 2025 Barbie ver colorful | C7: US | D7: 55 | E7: Doll | F7: 123AB | G7: 15000 | H7: 46157 | I7: 2731
A8: B | B8: 2025 Barbie ver colorful | C8: US | D8: 55 | E8: Doll | F8: 123AB | G8: 15000 | H8: 46157 | I8: 2771
A9: C | B9: 2026 Castle & Farm Blocks | C9: UK | D9: 80 | E9: Building & Construction Toy | F9: 456CD | G9: 5000 | H9: 46157 | I9: 270
A10: C | B10: 2026 Castle & Farm Blocks | C10: UK | D10: 80 | E10: Building & Construction Toy | F10: 456CD | G10: 5000 | H10: 46157 | I10: 270
A11: C | B11: 2026 Castle & Farm Blocks | C11: UK | D11: 80 | E11: Building & Construction Toy | F11: 456CD | G11: 5000 | H11: 46157 | I11: 270
A12: C | B12: 2026 Castle & Farm Blocks | C12: UK | D12: 80 | E12: Building & Construction Toy | F12: 456CD | G12: 5000 | H12: 46157 | I12: 270
A13: C | B13: 2026 Castle & Farm Blocks | C13: UK | D13: 80 | E13: Building & Construction Toy | F13: 456CD | G13: 5000 | H13: 46157 | I13: 270
... A466: F | B466: 2025 Fantasy Spaceship Model DIY kits | C466: US | D466: 90 | E466: Arts & Crafts Toy | F466: 789EF | G466: 3000 | H466: 46381 | I466: 1928

Sheet Demand_
A1: Item name | B1: Des | C1: Market | D1: Price ($) | E1: Product group | F1: Fixture | G1: Weekly Capcity | H1: Shipment Request | I1: Demand Quantity | J1: week first day | K1: production day | L1: Total Demand by SKU-Week | M1: 46139
A2: A | B2: 2026 Automatic Robot ver | C2: US | D2: 105 | E2: Electronic Toy | F2: 123AB | G2: 15000 | H2: 46150 | I2: 684 | J2: =$M$1+7*INT((H2-$M$1)/7) -> 46146 | K2: =Table14[[#This Row],[week first day]]-7 -> 46139 | L2: =SUMIFS($I:$I,$A:$A,A2,J:J,J2) -> 684
A3: A | B3: 2026 Automatic Robot ver | C3: US | D3: 105 | E3: Electronic Toy | F3: 123AB | G3: 15000 | H3: 46157 | I3: 20000 | J3: =$M$1+7*INT((H3-$M$1)/7) -> 46153 | K3: =Table14[[#This Row],[week first day]]-7 -> 46146 | L3: =SUMIFS($I:$I,$A:$A,A3,J:J,J3) -> 20000
A4: A | B4: 2026 Automatic Robot ver | C4: US | D4: 105 | E4: Electronic Toy | F4: 123AB | G4: 15000 | H4: 46164 | I4: 15000 | J4: =$M$1+7*INT((H4-$M$1)/7) -> 46160 | K4: =Table14[[#This Row],[week first day]]-7 -> 46153 | L4: =SUMIFS($I:$I,$A:$A,A4,J:J,J4) -> 20000
A5: A | B5: 2026 Automatic Robot ver | C5: US | D5: 105 | E5: Electronic Toy | F5: 123AB | G5: 15000 | H5: 46164 | I5: 5000 | J5: =$M$1+7*INT((H5-$M$1)/7) -> 46160 | K5: =Table14[[#This Row],[week first day]]-7 -> 46153 | L5: =SUMIFS($I:$I,$A:$A,A5,J:J,J5) -> 20000
A6: A | B6: 2026 Automatic Robot ver | C6: US | D6: 105 | E6: Electronic Toy | F6: 123AB | G6: 15000 | H6: 46171 | I6: 11000 | J6: =$M$1+7*INT((H6-$M$1)/7) -> 46167 | K6: =Table14[[#This Row],[week first day]]-7 -> 46160 | L6: =SUMIFS($I:$I,$A:$A,A6,J:J,J6) -> 11000
A7: A | B7: 2026 Automatic Robot ver | C7: US | D7: 105 | E7: Electronic Toy | F7: 123AB | G7: 15000 | H7: 46178 | I7: 13000 | J7: =$M$1+7*INT((H7-$M$1)/7) -> 46174 | K7: =Table14[[#This Row],[week first day]]-7 -> 46167 | L7: =SUMIFS($I:$I,$A:$A,A7,J:J,J7) -> 13000
A8: A | B8: 2026 Automatic Robot ver | C8: US | D8: 105 | E8: Electronic Toy | F8: 123AB | G8: 15000 | H8: 46185 | I8: 13773 | J8: =$M$1+7*INT((H8-$M$1)/7) -> 46181 | K8: =Table14[[#This Row],[week first day]]-7 -> 46174 | L8: =SUMIFS($I:$I,$A:$A,A8,J:J,J8) -> 13773
A9: A | B9: 2026 Automatic Robot ver | C9: US | D9: 105 | E9: Electronic Toy | F9: 123AB | G9: 15000 | H9: 46192 | I9: 7058 | J9: =$M$1+7*INT((H9-$M$1)/7) -> 46188 | K9: =Table14[[#This Row],[week first day]]-7 -> 46181 | L9: =SUMIFS($I:$I,$A:$A,A9,J:J,J9) -> 7058
A10: A | B10: 2026 Automatic Robot ver | C10: US | D10: 105 | E10: Electronic Toy | F10: 123AB | G10: 15000 | H10: 46199 | I10: 2040 | J10: =$M$1+7*INT((H10-$M$1)/7) -> 46195 | K10: =Table14[[#This Row],[week first day]]-7 -> 46188 | L10: =SUMIFS($I:$I,$A:$A,A10,J:J,J10) -> 2040
A11: A | B11: 2026 Automatic Robot ver | C11: US | D11: 105 | E11: Electronic Toy | F11: 123AB | G11: 15000 | H11: 46206 | I11: 1500 | J11: =$M$1+7*INT((H11-$M$1)/7) -> 46202 | K11: =Table14[[#This Row],[week first day]]-7 -> 46195 | L11: =SUMIFS($I:$I,$A:$A,A11,J:J,J11) -> 3541
A12: A | B12: 2026 Automatic Robot ver | C12: US | D12: 105 | E12: Electronic Toy | F12: 123AB | G12: 15000 | H12: 46206 | I12: 2041 | J12: =$M$1+7*INT((H12-$M$1)/7) -> 46202 | K12: =Table14[[#This Row],[week first day]]-7 -> 46195 | L12: =SUMIFS($I:$I,$A:$A,A12,J:J,J12) -> 3541
A13: A | B13: 2026 Automatic Robot ver | C13: US | D13: 105 | E13: Electronic Toy | F13: 123AB | G13: 15000 | H13: 46213 | I13: 2041 | J13: =$M$1+7*INT((H13-$M$1)/7) -> 46209 | K13: =Table14[[#This Row],[week first day]]-7 -> 46202 | L13: =SUMIFS($I:$I,$A:$A,A13,J:J,J13) -> 12041
... A466: F | B466: 2025 Fantasy Spaceship Model DIY kits | C466: US | D466: 90 | E466: Arts & Crafts Toy | F466: 789EF | G466: 3000 | H466: 46381 | I466: 1928 | J466: =$M$1+7*INT((H466-$M$1)/7) -> 46377 | K466: =Table14[[#This Row],[week first day]]-7 -> 46370 | L466: =SUMIFS($I:$I,$A:$A,A466,J:J,J466) -> 1928

Sheet weekly_demand
A1: Item name | B1: market | C1: week first day | D1: Total Demand by SKU-Week | E1: carton | F1: volume
A2: {=_xlfn.UNIQUE(_xlfn.CHOOSECOLS(Demand_!A2:L466,1,3,11,12))} -> A | B2: US | C2: 46139 | D2: 684 | E2: =ROUNDUP(D2/_xlfn.XLOOKUP(A2,$J$3:$J$8,$L$3:$L$8),0) -> 171 | F2: =E2/100*_xlfn.XLOOKUP(A2,$J$3:$J$8,$M$3:$M$8) -> 1.71 | J2: Item name | K2: Des | L2: Packing size (pcs/ carton) | M2: CBM (100 cartons)
A3: A | B3: US | C3: 46146 | D3: 20000 | E3: =ROUNDUP(D3/_xlfn.XLOOKUP(A3,$J$3:$J$8,$L$3:$L$8),0) -> 5000 | F3: =E3/100*_xlfn.XLOOKUP(A3,$J$3:$J$8,$M$3:$M$8) -> 50 | J3: A | K3: 2026 Automatic Robot ver | L3: 4 | M3: 1
A4: A | B4: US | C4: 46153 | D4: 20000 | E4: =ROUNDUP(D4/_xlfn.XLOOKUP(A4,$J$3:$J$8,$L$3:$L$8),0) -> 5000 | F4: =E4/100*_xlfn.XLOOKUP(A4,$J$3:$J$8,$M$3:$M$8) -> 50 | J4: B | K4: 2025 Barbie ver colorful | L4: 4 | M4: 0.625
A5: A | B5: US | C5: 46160 | D5: 11000 | E5: =ROUNDUP(D5/_xlfn.XLOOKUP(A5,$J$3:$J$8,$L$3:$L$8),0) -> 2750 | F5: =E5/100*_xlfn.XLOOKUP(A5,$J$3:$J$8,$M$3:$M$8) -> 27.5 | J5: C | K5: 2026 Castle & Farm Blocks | L5: 2 | M5: 1
A6: A | B6: US | C6: 46167 | D6: 13000 | E6: =ROUNDUP(D6/_xlfn.XLOOKUP(A6,$J$3:$J$8,$L$3:$L$8),0) -> 3250 | F6: =E6/100*_xlfn.XLOOKUP(A6,$J$3:$J$8,$M$3:$M$8) -> 32.5 | J6: D | K6: 2026 Animal Animation Book | L6: 4 | M6: 0.625
A7: A | B7: US | C7: 46174 | D7: 13773 | E7: =ROUNDUP(D7/_xlfn.XLOOKUP(A7,$J$3:$J$8,$L$3:$L$8),0) -> 3444 | F7: =E7/100*_xlfn.XLOOKUP(A7,$J$3:$J$8,$M$3:$M$8) -> 34.44 | J7: E | K7: 2026 Scooter ver | L7: 2 | M7: 0.625
A8: A | B8: US | C8: 46181 | D8: 7058 | E8: =ROUNDUP(D8/_xlfn.XLOOKUP(A8,$J$3:$J$8,$L$3:$L$8),0) -> 1765 | F8: =E8/100*_xlfn.XLOOKUP(A8,$J$3:$J$8,$M$3:$M$8) -> 17.65 | J8: F | K8: 2025 Fantasy Spaceship Model DIY kits | L8: 8 | M8: 0.78125
A9: A | B9: US | C9: 46188 | D9: 2040 | E9: =ROUNDUP(D9/_xlfn.XLOOKUP(A9,$J$3:$J$8,$L$3:$L$8),0) -> 510 | F9: =E9/100*_xlfn.XLOOKUP(A9,$J$3:$J$8,$M$3:$M$8) -> 5.1
A10: A | B10: US | C10: 46195 | D10: 3541 | E10: =ROUNDUP(D10/_xlfn.XLOOKUP(A10,$J$3:$J$8,$L$3:$L$8),0) -> 886 | F10: =E10/100*_xlfn.XLOOKUP(A10,$J$3:$J$8,$M$3:$M$8) -> 8.86
A11: A | B11: US | C11: 46202 | D11: 12041 | E11: =ROUNDUP(D11/_xlfn.XLOOKUP(A11,$J$3:$J$8,$L$3:$L$8),0) -> 3011 | F11: =E11/100*_xlfn.XLOOKUP(A11,$J$3:$J$8,$M$3:$M$8) -> 30.11
A12: A | B12: US | C12: 46209 | D12: 12040 | E12: =ROUNDUP(D12/_xlfn.XLOOKUP(A12,$J$3:$J$8,$L$3:$L$8),0) -> 3010 | F12: =E12/100*_xlfn.XLOOKUP(A12,$J$3:$J$8,$M$3:$M$8) -> 30.1
A13: A | B13: US | C13: 46230 | D13: 27760 | E13: =ROUNDUP(D13/_xlfn.XLOOKUP(A13,$J$3:$J$8,$L$3:$L$8),0) -> 6940 | F13: =E13/100*_xlfn.XLOOKUP(A13,$J$3:$J$8,$M$3:$M$8) -> 69.4
A14: A | B14: US | C14: 46237 | D14: 26486 | E14: =ROUNDUP(D14/_xlfn.XLOOKUP(A14,$J$3:$J$8,$L$3:$L$8),0) -> 6622 | F14: =E14/100*_xlfn.XLOOKUP(A14,$J$3:$J$8,$M$3:$M$8) -> 66.22
A15: A | B15: US | C15: 46244 | D15: 4248 | E15: =ROUNDUP(D15/_xlfn.XLOOKUP(A15,$J$3:$J$8,$L$3:$L$8),0) -> 1062 | F15: =E15/100*_xlfn.XLOOKUP(A15,$J$3:$J$8,$M$3:$M$8) -> 10.62
A16: A | B16: US | C16: 46251 | D16: 4248 | E16: =ROUNDUP(D16/_xlfn.XLOOKUP(A16,$J$3:$J$8,$L$3:$L$8),0) -> 1062 | F16: =E16/100*_xlfn.XLOOKUP(A16,$J$3:$J$8,$M$3:$M$8) -> 10.62
A17: A | B17: US | C17: 46258 | D17: 4249 | E17: =ROUNDUP(D17/_xlfn.XLOOKUP(A17,$J$3:$J$8,$L$3:$L$8),0) -> 1063 | F17: =E17/100*_xlfn.XLOOKUP(A17,$J$3:$J$8,$M$3:$M$8) -> 10.63
A18: A | B18: US | C18: 46265 | D18: 4248 | E18: =ROUNDUP(D18/_xlfn.XLOOKUP(A18,$J$3:$J$8,$L$3:$L$8),0) -> 1062 | F18: =E18/100*_xlfn.XLOOKUP(A18,$J$3:$J$8,$M$3:$M$8) -> 10.62
A19: A | B19: US | C19: 46272 | D19: 2391 | E19: =ROUNDUP(D19/_xlfn.XLOOKUP(A19,$J$3:$J$8,$L$3:$L$8),0) -> 598 | F19: =E19/100*_xlfn.XLOOKUP(A19,$J$3:$J$8,$M$3:$M$8) -> 5.98
A20: A | B20: US | C20: 46279 | D20: 2392 | E20: =ROUNDUP(D20/_xlfn.XLOOKUP(A20,$J$3:$J$8,$L$3:$L$8),0) -> 598 | F20: =E20/100*_xlfn.XLOOKUP(A20,$J$3:$J$8,$M$3:$M$8) -> 5.98
... A172: F | B172: US | C172: 46370 | D172: 1928 | E172: =ROUNDUP(D172/_xlfn.XLOOKUP(A172,$J$3:$J$8,$L$3:$L$8),0) -> 241 | F172: =E172/100*_xlfn.XLOOKUP(A172,$J$3:$J$8,$M$3:$M$8) -> 1.8828125

Sheet demand_matrix
A1: Week | B1: A | C1: B | D1: C | E1: D | F1: E | G1: F
A2: 46132 | B2: =IF($A2="","",SUMIFS(weekly_demand!$D:$D,weekly_demand!$A:$A,B$1,weekly_demand!$C:$C,$A2)) -> 0 | C2: =IF($A2="","",SUMIFS(weekly_demand!$D:$D,weekly_demand!$A:$A,C$1,weekly_demand!$C:$C,$A2)) -> 0 | D2: =IF($A2="","",SUMIFS(weekly_demand!$D:$D,weekly_demand!$A:$A,D$1,weekly_demand!$C:$C,$A2)) -> 0 | E2: =IF($A2="","",SUMIFS(weekly_demand!$D:$D,weekly_demand!$A:$A,E$1,weekly_demand!$C:$C,$A2)) -> 0 | F2: =IF($A2="","",SUMIFS(weekly_demand!$D:$D,weekly_demand!$A:$A,F$1,weekly_demand!$C:$C,$A2)) -> 0 | G2: =IF($A2="","",SUMIFS(weekly_demand!$D:$D,weekly_demand!$A:$A,G$1,weekly_demand!$C:$C,$A2)) -> 588
A3: 46139 | B3: =IF($A3="","",SUMIFS(weekly_demand!$D:$D,weekly_demand!$A:$A,B$1,weekly_demand!$C:$C,$A3)) -> 684 | C3: =IF($A3="","",SUMIFS(weekly_demand!$D:$D,weekly_demand!$A:$A,C$1,weekly_demand!$C:$C,$A3)) -> 0 | D3: =IF($A3="","",SUMIFS(weekly_demand!$D:$D,weekly_demand!$A:$A,D$1,weekly_demand!$C:$C,$A3)) -> 0 | E3: =IF($A3="","",SUMIFS(weekly_demand!$D:$D,weekly_demand!$A:$A,E$1,weekly_demand!$C:$C,$A3)) -> 0 | F3: =IF($A3="","",SUMIFS(weekly_demand!$D:$D,weekly_demand!$A:$A,F$1,weekly_demand!$C:$C,$A3)) -> 472 | G3: =IF($A3="","",SUMIFS(weekly_demand!$D:$D,weekly_demand!$A:$A,G$1,weekly_demand!$C:$C,$A3)) -> 4028
A4: 46146 | B4: =IF($A4="","",SUMIFS(weekly_demand!$D:$D,weekly_demand!$A:$A,B$1,weekly_demand!$C:$C,$A4)) -> 20000 | C4: =IF($A4="","",SUMIFS(weekly_demand!$D:$D,weekly_demand!$A:$A,C$1,weekly_demand!$C:$C,$A4)) -> 5502 | D4: =IF($A4="","",SUMIFS(weekly_demand!$D:$D,weekly_demand!$A:$A,D$1,weekly_demand!$C:$C,$A4)) -> 4320 | E4: =IF($A4="","",SUMIFS(weekly_demand!$D:$D,weekly_demand!$A:$A,E$1,weekly_demand!$C:$C,$A4)) -> 2430 | F4: =IF($A4="","",SUMIFS(weekly_demand!$D:$D,weekly_demand!$A:$A,F$1,weekly_demand!$C:$C,$A4)) -> 300 | G4: =IF($A4="","",SUMIFS(weekly_demand!$D:$D,weekly_demand!$A:$A,G$1,weekly_demand!$C:$C,$A4)) -> 4200
A5: 46153 | B5: =IF($A5="","",SUMIFS(weekly_demand!$D:$D,weekly_demand!$A:$A,B$1,weekly_demand!$C:$C,$A5)) -> 20000 | C5: =IF($A5="","",SUMIFS(weekly_demand!$D:$D,weekly_demand!$A:$A,C$1,weekly_demand!$C:$C,$A5)) -> 15658 | D5: =IF($A5="","",SUMIFS(weekly_demand!$D:$D,weekly_demand!$A:$A,D$1,weekly_demand!$C:$C,$A5)) -> 8370 | E5: =IF($A5="","",SUMIFS(weekly_demand!$D:$D,weekly_demand!$A:$A,E$1,weekly_demand!$C:$C,$A5)) -> 9990 | F5: =IF($A5="","",SUMIFS(weekly_demand!$D:$D,weekly_demand!$A:$A,F$1,weekly_demand!$C:$C,$A5)) -> 698 | G5: =IF($A5="","",SUMIFS(weekly_demand!$D:$D,weekly_demand!$A:$A,G$1,weekly_demand!$C:$C,$A5)) -> 3802
A6: 46160 | B6: =IF($A6="","",SUMIFS(weekly_demand!$D:$D,weekly_demand!$A:$A,B$1,weekly_demand!$C:$C,$A6)) -> 11000 | C6: =IF($A6="","",SUMIFS(weekly_demand!$D:$D,weekly_demand!$A:$A,C$1,weekly_demand!$C:$C,$A6)) -> 8865 | D6: =IF($A6="","",SUMIFS(weekly_demand!$D:$D,weekly_demand!$A:$A,D$1,weekly_demand!$C:$C,$A6)) -> 11782 | E6: =IF($A6="","",SUMIFS(weekly_demand!$D:$D,weekly_demand!$A:$A,E$1,weekly_demand!$C:$C,$A6)) -> 5840 | F6: =IF($A6="","",SUMIFS(weekly_demand!$D:$D,weekly_demand!$A:$A,F$1,weekly_demand!$C:$C,$A6)) -> 0 | G6: =IF($A6="","",SUMIFS(weekly_demand!$D:$D,weekly_demand!$A:$A,G$1,weekly_demand!$C:$C,$A6)) -> 4500
A7: 46167 | B7: =IF($A7="","",SUMIFS(weekly_demand!$D:$D,weekly_demand!$A:$A,B$1,weekly_demand!$C:$C,$A7)) -> 13000 | C7: =IF($A7="","",SUMIFS(weekly_demand!$D:$D,weekly_demand!$A:$A,C$1,weekly_demand!$C:$C,$A7)) -> 2146 | D7: =IF($A7="","",SUMIFS(weekly_demand!$D:$D,weekly_demand!$A:$A,D$1,weekly_demand!$C:$C,$A7)) -> 10524 | E7: =IF($A7="","",SUMIFS(weekly_demand!$D:$D,weekly_demand!$A:$A,E$1,weekly_demand!$C:$C,$A7)) -> 8100 | F7: =IF($A7="","",SUMIFS(weekly_demand!$D:$D,weekly_demand!$A:$A,F$1,weekly_demand!$C:$C,$A7)) -> 300 | G7: =IF($A7="","",SUMIFS(weekly_demand!$D:$D,weekly_demand!$A:$A,G$1,weekly_demand!$C:$C,$A7)) -> 4200
A8: 46174 | B8: =IF($A8="","",SUMIFS(weekly_demand!$D:$D,weekly_demand!$A:$A,B$1,weekly_demand!$C:$C,$A8)) -> 13773 | C8: =IF($A8="","",SUMIFS(weekly_demand!$D:$D,weekly_demand!$A:$A,C$1,weekly_demand!$C:$C,$A8)) -> 7123 | D8: =IF($A8="","",SUMIFS(weekly_demand!$D:$D,weekly_demand!$A:$A,D$1,weekly_demand!$C:$C,$A8)) -> 3240 | E8: =IF($A8="","",SUMIFS(weekly_demand!$D:$D,weekly_demand!$A:$A,E$1,weekly_demand!$C:$C,$A8)) -> 1001 | F8: =IF($A8="","",SUMIFS(weekly_demand!$D:$D,weekly_demand!$A:$A,F$1,weekly_demand!$C:$C,$A8)) -> 0 | G8: =IF($A8="","",SUMIFS(weekly_demand!$D:$D,weekly_demand!$A:$A,G$1,weekly_demand!$C:$C,$A8)) -> 4500
A9: 46181 | B9: =IF($A9="","",SUMIFS(weekly_demand!$D:$D,weekly_demand!$A:$A,B$1,weekly_demand!$C:$C,$A9)) -> 7058 | C9: =IF($A9="","",SUMIFS(weekly_demand!$D:$D,weekly_demand!$A:$A,C$1,weekly_demand!$C:$C,$A9)) -> 5309 | D9: =IF($A9="","",SUMIFS(weekly_demand!$D:$D,weekly_demand!$A:$A,D$1,weekly_demand!$C:$C,$A9)) -> 6442 | E9: =IF($A9="","",SUMIFS(weekly_demand!$D:$D,weekly_demand!$A:$A,E$1,weekly_demand!$C:$C,$A9)) -> 2471 | F9: =IF($A9="","",SUMIFS(weekly_demand!$D:$D,weekly_demand!$A:$A,F$1,weekly_demand!$C:$C,$A9)) -> 0 | G9: =IF($A9="","",SUMIFS(weekly_demand!$D:$D,weekly_demand!$A:$A,G$1,weekly_demand!$C:$C,$A9)) -> 4500
A10: 46188 | B10: =IF($A10="","",SUMIFS(weekly_demand!$D:$D,weekly_demand!$A:$A,B$1,weekly_demand!$C:$C,$A10)) -> 2040 | C10: =IF($A10="","",SUMIFS(weekly_demand!$D:$D,weekly_demand!$A:$A,C$1,weekly_demand!$C:$C,$A10)) -> 5309 | D10: =IF($A10="","",SUMIFS(weekly_demand!$D:$D,weekly_demand!$A:$A,D$1,weekly_demand!$C:$C,$A10)) -> 8802 | E10: =IF($A10="","",SUMIFS(weekly_demand!$D:$D,weekly_demand!$A:$A,E$1,weekly_demand!$C:$C,$A10)) -> 3458 | F10: =IF($A10="","",SUMIFS(weekly_demand!$D:$D,weekly_demand!$A:$A,F$1,weekly_demand!$C:$C,$A10)) -> 300 | G10: =IF($A10="","",SUMIFS(weekly_demand!$D:$D,weekly_demand!$A:$A,G$1,weekly_demand!$C:$C,$A10)) -> 2200
A11: 46195 | B11: =IF($A11="","",SUMIFS(weekly_demand!$D:$D,weekly_demand!$A:$A,B$1,weekly_demand!$C:$C,$A11)) -> 3541 | C11: =IF($A11="","",SUMIFS(weekly_demand!$D:$D,weekly_demand!$A:$A,C$1,weekly_demand!$C:$C,$A11)) -> 3000 | D11: =IF($A11="","",SUMIFS(weekly_demand!$D:$D,weekly_demand!$A:$A,D$1,weekly_demand!$C:$C,$A11)) -> 7695 | E11: =IF($A11="","",SUMIFS(weekly_demand!$D:$D,weekly_demand!$A:$A,E$1,weekly_demand!$C:$C,$A11)) -> 500 | F11: =IF($A11="","",SUMIFS(weekly_demand!$D:$D,weekly_demand!$A:$A,F$1,weekly_demand!$C:$C,$A11)) -> 0 | G11: =IF($A11="","",SUMIFS(weekly_demand!$D:$D,weekly_demand!$A:$A,G$1,weekly_demand!$C:$C,$A11)) -> 5000
A12: 46202 | B12: =IF($A12="","",SUMIFS(weekly_demand!$D:$D,weekly_demand!$A:$A,B$1,weekly_demand!$C:$C,$A12)) -> 12041 | C12: =IF($A12="","",SUMIFS(weekly_demand!$D:$D,weekly_demand!$A:$A,C$1,weekly_demand!$C:$C,$A12)) -> 3000 | D12: =IF($A12="","",SUMIFS(weekly_demand!$D:$D,weekly_demand!$A:$A,D$1,weekly_demand!$C:$C,$A12)) -> 2500 | E12: =IF($A12="","",SUMIFS(weekly_demand!$D:$D,weekly_demand!$A:$A,E$1,weekly_demand!$C:$C,$A12)) -> 500 | F12: =IF($A12="","",SUMIFS(weekly_demand!$D:$D,weekly_demand!$A:$A,F$1,weekly_demand!$C:$C,$A12)) -> 700 | G12: =IF($A12="","",SUMIFS(weekly_demand!$D:$D,weekly_demand!$A:$A,G$1,weekly_demand!$C:$C,$A12)) -> 4300
A13: 46209 | B13: =IF($A13="","",SUMIFS(weekly_demand!$D:$D,weekly_demand!$A:$A,B$1,weekly_demand!$C:$C,$A13)) -> 12040 | C13: =IF($A13="","",SUMIFS(weekly_demand!$D:$D,weekly_demand!$A:$A,C$1,weekly_demand!$C:$C,$A13)) -> 3000 | D13: =IF($A13="","",SUMIFS(weekly_demand!$D:$D,weekly_demand!$A:$A,D$1,weekly_demand!$C:$C,$A13)) -> 2500 | E13: =IF($A13="","",SUMIFS(weekly_demand!$D:$D,weekly_demand!$A:$A,E$1,weekly_demand!$C:$C,$A13)) -> 500 | F13: =IF($A13="","",SUMIFS(weekly_demand!$D:$D,weekly_demand!$A:$A,F$1,weekly_demand!$C:$C,$A13)) -> 300 | G13: =IF($A13="","",SUMIFS(weekly_demand!$D:$D,weekly_demand!$A:$A,G$1,weekly_demand!$C:$C,$A13)) -> 4700
... A36: 46370 | B36: =IF($A36="","",SUMIFS(weekly_demand!$D:$D,weekly_demand!$A:$A,B$1,weekly_demand!$C:$C,$A36)) -> 8325 | C36: =IF($A36="","",SUMIFS(weekly_demand!$D:$D,weekly_demand!$A:$A,C$1,weekly_demand!$C:$C,$A36)) -> 6250 | D36: =IF($A36="","",SUMIFS(weekly_demand!$D:$D,weekly_demand!$A:$A,D$1,weekly_demand!$C:$C,$A36)) -> 3000 | E36: =IF($A36="","",SUMIFS(weekly_demand!$D:$D,weekly_demand!$A:$A,E$1,weekly_demand!$C:$C,$A36)) -> 1250 | F36: =IF($A36="","",SUMIFS(weekly_demand!$D:$D,weekly_demand!$A:$A,F$1,weekly_demand!$C:$C,$A36)) -> 0 | G36: =IF($A36="","",SUMIFS(weekly_demand!$D:$D,weekly_demand!$A:$A,G$1,weekly_demand!$C:$C,$A36)) -> 1928
B37: =IF($A37="","",SUMIFS(weekly_demand!$D:$D,weekly_demand!$A:$A,B$1,weekly_demand!$C:$C,$A37)) | C37: =IF($A37="","",SUMIFS(weekly_demand!$D:$D,weekly_demand!$A:$A,C$1,weekly_demand!$C:$C,$A37)) | D37: =IF($A37="","",SUMIFS(weekly_demand!$D:$D,weekly_demand!$A:$A,D$1,weekly_demand!$C:$C,$A37)) | E37: =IF($A37="","",SUMIFS(weekly_demand!$D:$D,weekly_demand!$A:$A,E$1,weekly_demand!$C:$C,$A37)) | F37: =IF($A37="","",SUMIFS(weekly_demand!$D:$D,weekly_demand!$A:$A,F$1,weekly_demand!$C:$C,$A37)) | G37: =IF($A37="","",SUMIFS(weekly_demand!$D:$D,weekly_demand!$A:$A,G$1,weekly_demand!$C:$C,$A37))
B38: =IF($A38="","",SUMIFS(weekly_demand!$D:$D,weekly_demand!$A:$A,B$1,weekly_demand!$C:$C,$A38)) | C38: =IF($A38="","",SUMIFS(weekly_demand!$D:$D,weekly_demand!$A:$A,C$1,weekly_demand!$C:$C,$A38)) | D38: =IF($A38="","",SUMIFS(weekly_demand!$D:$D,weekly_demand!$A:$A,D$1,weekly_demand!$C:$C,$A38)) | E38: =IF($A38="","",SUMIFS(weekly_demand!$D:$D,weekly_demand!$A:$A,E$1,weekly_demand!$C:$C,$A38)) | F38: =IF($A38="","",SUMIFS(weekly_demand!$D:$D,weekly_demand!$A:$A,F$1,weekly_demand!$C:$C,$A38)) | G38: =IF($A38="","",SUMIFS(weekly_demand!$D:$D,weekly_demand!$A:$A,G$1,weekly_demand!$C:$C,$A38))
B39: =IF($A39="","",SUMIFS(weekly_demand!$D:$D,weekly_demand!$A:$A,B$1,weekly_demand!$C:$C,$A39)) | C39: =IF($A39="","",SUMIFS(weekly_demand!$D:$D,weekly_demand!$A:$A,C$1,weekly_demand!$C:$C,$A39)) | D39: =IF($A39="","",SUMIFS(weekly_demand!$D:$D,weekly_demand!$A:$A,D$1,weekly_demand!$C:$C,$A39)) | E39: =IF($A39="","",SUMIFS(weekly_demand!$D:$D,weekly_demand!$A:$A,E$1,weekly_demand!$C:$C,$A39)) | F39: =IF($A39="","",SUMIFS(weekly_demand!$D:$D,weekly_demand!$A:$A,F$1,weekly_demand!$C:$C,$A39)) | G39: =IF($A39="","",SUMIFS(weekly_demand!$D:$D,weekly_demand!$A:$A,G$1,weekly_demand!$C:$C,$A39))
B40: =IF($A40="","",SUMIFS(weekly_demand!$D:$D,weekly_demand!$A:$A,B$1,weekly_demand!$C:$C,$A40)) | C40: =IF($A40="","",SUMIFS(weekly_demand!$D:$D,weekly_demand!$A:$A,C$1,weekly_demand!$C:$C,$A40)) | D40: =IF($A40="","",SUMIFS(weekly_demand!$D:$D,weekly_demand!$A:$A,D$1,weekly_demand!$C:$C,$A40)) | E40: =IF($A40="","",SUMIFS(weekly_demand!$D:$D,weekly_demand!$A:$A,E$1,weekly_demand!$C:$C,$A40)) | F40: =IF($A40="","",SUMIFS(weekly_demand!$D:$D,weekly_demand!$A:$A,F$1,weekly_demand!$C:$C,$A40)) | G40: =IF($A40="","",SUMIFS(weekly_demand!$D:$D,weekly_demand!$A:$A,G$1,weekly_demand!$C:$C,$A40))
B41: =IF($A41="","",SUMIFS(weekly_demand!$D:$D,weekly_demand!$A:$A,B$1,weekly_demand!$C:$C,$A41)) | C41: =IF($A41="","",SUMIFS(weekly_demand!$D:$D,weekly_demand!$A:$A,C$1,weekly_demand!$C:$C,$A41)) | D41: =IF($A41="","",SUMIFS(weekly_demand!$D:$D,weekly_demand!$A:$A,D$1,weekly_demand!$C:$C,$A41)) | E41: =IF($A41="","",SUMIFS(weekly_demand!$D:$D,weekly_demand!$A:$A,E$1,weekly_demand!$C:$C,$A41)) | F41: =IF($A41="","",SUMIFS(weekly_demand!$D:$D,weekly_demand!$A:$A,F$1,weekly_demand!$C:$C,$A41)) | G41: =IF($A41="","",SUMIFS(weekly_demand!$D:$D,weekly_demand!$A:$A,G$1,weekly_demand!$C:$C,$A41))
B42: =IF($A42="","",SUMIFS(weekly_demand!$D:$D,weekly_demand!$A:$A,B$1,weekly_demand!$C:$C,$A42)) | C42: =IF($A42="","",SUMIFS(weekly_demand!$D:$D,weekly_demand!$A:$A,C$1,weekly_demand!$C:$C,$A42)) | D42: =IF($A42="","",SUMIFS(weekly_demand!$D:$D,weekly_demand!$A:$A,D$1,weekly_demand!$C:$C,$A42)) | E42: =IF($A42="","",SUMIFS(weekly_demand!$D:$D,weekly_demand!$A:$A,E$1,weekly_demand!$C:$C,$A42)) | F42: =IF($A42="","",SUMIFS(weekly_demand!$D:$D,weekly_demand!$A:$A,F$1,weekly_demand!$C:$C,$A42)) | G42: =IF($A42="","",SUMIFS(weekly_demand!$D:$D,weekly_demand!$A:$A,G$1,weekly_demand!$C:$C,$A42))
B43: =IF($A43="","",SUMIFS(weekly_demand!$D:$D,weekly_demand!$A:$A,B$1,weekly_demand!$C:$C,$A43)) | C43: =IF($A43="","",SUMIFS(weekly_demand!$D:$D,weekly_demand!$A:$A,C$1,weekly_demand!$C:$C,$A43)) | D43: =IF($A43="","",SUMIFS(weekly_demand!$D:$D,weekly_demand!$A:$A,D$1,weekly_demand!$C:$C,$A43)) | E43: =IF($A43="","",SUMIFS(weekly_demand!$D:$D,weekly_demand!$A:$A,E$1,weekly_demand!$C:$C,$A43)) | F43: =IF($A43="","",SUMIFS(weekly_demand!$D:$D,weekly_demand!$A:$A,F$1,weekly_demand!$C:$C,$A43)) | G43: =IF($A43="","",SUMIFS(weekly_demand!$D:$D,weekly_demand!$A:$A,G$1,weekly_demand!$C:$C,$A43))
B44: =IF($A44="","",SUMIFS(weekly_demand!$D:$D,weekly_demand!$A:$A,B$1,weekly_demand!$C:$C,$A44)) | C44: =IF($A44="","",SUMIFS(weekly_demand!$D:$D,weekly_demand!$A:$A,C$1,weekly_demand!$C:$C,$A44)) | D44: =IF($A44="","",SUMIFS(weekly_demand!$D:$D,weekly_demand!$A:$A,D$1,weekly_demand!$C:$C,$A44)) | E44: =IF($A44="","",SUMIFS(weekly_demand!$D:$D,weekly_demand!$A:$A,E$1,weekly_demand!$C:$C,$A44)) | F44: =IF($A44="","",SUMIFS(weekly_demand!$D:$D,weekly_demand!$A:$A,F$1,weekly_demand!$C:$C,$A44)) | G44: =IF($A44="","",SUMIFS(weekly_demand!$D:$D,weekly_demand!$A:$A,G$1,weekly_demand!$C:$C,$A44))
B45: =IF($A45="","",SUMIFS(weekly_demand!$D:$D,weekly_demand!$A:$A,B$1,weekly_demand!$C:$C,$A45)) | C45: =IF($A45="","",SUMIFS(weekly_demand!$D:$D,weekly_demand!$A:$A,C$1,weekly_demand!$C:$C,$A45)) | D45: =IF($A45="","",SUMIFS(weekly_demand!$D:$D,weekly_demand!$A:$A,D$1,weekly_demand!$C:$C,$A45)) | E45: =IF($A45="","",SUMIFS(weekly_demand!$D:$D,weekly_demand!$A:$A,E$1,weekly_demand!$C:$C,$A45)) | F45: =IF($A45="","",SUMIFS(weekly_demand!$D:$D,weekly_demand!$A:$A,F$1,weekly_demand!$C:$C,$A45)) | G45: =IF($A45="","",SUMIFS(weekly_demand!$D:$D,weekly_demand!$A:$A,G$1,weekly_demand!$C:$C,$A45))
B46: =IF($A46="","",SUMIFS(weekly_demand!$D:$D,weekly_demand!$A:$A,B$1,weekly_demand!$C:$C,$A46)) | C46: =IF($A46="","",SUMIFS(weekly_demand!$D:$D,weekly_demand!$A:$A,C$1,weekly_demand!$C:$C,$A46)) | D46: =IF($A46="","",SUMIFS(weekly_demand!$D:$D,weekly_demand!$A:$A,D$1,weekly_demand!$C:$C,$A46)) | E46: =IF($A46="","",SUMIFS(weekly_demand!$D:$D,weekly_demand!$A:$A,E$1,weekly_demand!$C:$C,$A46)) | F46: =IF($A46="","",SUMIFS(weekly_demand!$D:$D,weekly_demand!$A:$A,F$1,weekly_demand!$C:$C,$A46)) | G46: =IF($A46="","",SUMIFS(weekly_demand!$D:$D,weekly_demand!$A:$A,G$1,weekly_demand!$C:$C,$A46))
B47: =IF($A47="","",SUMIFS(weekly_demand!$D:$D,weekly_demand!$A:$A,B$1,weekly_demand!$C:$C,$A47)) | C47: =IF($A47="","",SUMIFS(weekly_demand!$D:$D,weekly_demand!$A:$A,C$1,weekly_demand!$C:$C,$A47)) | D47: =IF($A47="","",SUMIFS(weekly_demand!$D:$D,weekly_demand!$A:$A,D$1,weekly_demand!$C:$C,$A47)) | E47: =IF($A47="","",SUMIFS(weekly_demand!$D:$D,weekly_demand!$A:$A,E$1,weekly_demand!$C:$C,$A47)) | F47: =IF($A47="","",SUMIFS(weekly_demand!$D:$D,weekly_demand!$A:$A,F$1,weekly_demand!$C:$C,$A47)) | G47: =IF($A47="","",SUMIFS(weekly_demand!$D:$D,weekly_demand!$A:$A,G$1,weekly_demand!$C:$C,$A47))
B48: =IF($A48="","",SUMIFS(weekly_demand!$D:$D,weekly_demand!$A:$A,B$1,weekly_demand!$C:$C,$A48)) | C48: =IF($A48="","",SUMIFS(weekly_demand!$D:$D,weekly_demand!$A:$A,C$1,weekly_demand!$C:$C,$A48)) | D48: =IF($A48="","",SUMIFS(weekly_demand!$D:$D,weekly_demand!$A:$A,D$1,weekly_demand!$C:$C,$A48)) | E48: =IF($A48="","",SUMIFS(weekly_demand!$D:$D,weekly_demand!$A:$A,E$1,weekly_demand!$C:$C,$A48)) | F48: =IF($A48="","",SUMIFS(weekly_demand!$D:$D,weekly_demand!$A:$A,F$1,weekly_demand!$C:$C,$A48)) | G48: =IF($A48="","",SUMIFS(weekly_demand!$D:$D,weekly_demand!$A:$A,G$1,weekly_demand!$C:$C,$A48))
... B200: =IF($A200="","",SUMIFS(weekly_demand!$D:$D,weekly_demand!$A:$A,B$1,weekly_demand!$C:$C,$A200)) | C200: =IF($A200="","",SUMIFS(weekly_demand!$D:$D,weekly_demand!$A:$A,C$1,weekly_demand!$C:$C,$A200)) | D200: =IF($A200="","",SUMIFS(weekly_demand!$D:$D,weekly_demand!$A:$A,D$1,weekly_demand!$C:$C,$A200)) | E200: =IF($A200="","",SUMIFS(weekly_demand!$D:$D,weekly_demand!$A:$A,E$1,weekly_demand!$C:$C,$A200)) | F200: =IF($A200="","",SUMIFS(weekly_demand!$D:$D,weekly_demand!$A:$A,F$1,weekly_demand!$C:$C,$A200)) | G200: =IF($A200="","",SUMIFS(weekly_demand!$D:$D,weekly_demand!$A:$A,G$1,weekly_demand!$C:$C,$A200))

Sheet sumary
A1: Summary by Week-Fixture | K1: Plant Summary by Week
A2: Week | B2: Fixture | C2: Shared Fixture Cap | D2: Total Demand | E2: Total Planned | F2: Ending FG Total | G2: Total Shortage | H2: Utilization % | I2: Status | K2: Week | L2: Plant Cap | M2: Total Demand | N2: Total Planned | O2: Total Ending FG | P2: Total Shortage
A3: 46125 | B3: 123AB | C3: 15000 | D3: =SUMIFS(MPS!$E$2:$E$217,MPS!$C$2:$C$217,A3,MPS!$B$2:$B$217,B3) -> 0 | E3: =SUMIFS(MPS!$J$2:$J$217,MPS!$C$2:$C$217,A3,MPS!$B$2:$B$217,B3) -> 12751 | F3: =SUMIFS(MPS!$K$2:$K$217,MPS!$C$2:$C$217,A3,MPS!$B$2:$B$217,B3) -> 12751 | G3: =SUMIFS(MPS!$L$2:$L$217,MPS!$C$2:$C$217,A3,MPS!$B$2:$B$217,B3) -> 0 | H3: =IFERROR(E3/C3,0) -> 0.85006667 | I3: =IF(E3>C3,"Over shared cap","OK") -> OK | K3: 46125 | L3: 23000 | M3: =SUMIFS(MPS!$E$2:$E$217,MPS!$C$2:$C$217,K3) -> 0 | N3: =SUMIFS(MPS!$J$2:$J$217,MPS!$C$2:$C$217,K3) -> 20751 | O3: =SUMIFS(MPS!$K$2:$K$217,MPS!$C$2:$C$217,K3) -> 20751 | P3: =SUMIFS(MPS!$L$2:$L$217,MPS!$C$2:$C$217,K3) -> 0
A4: 46125 | B4: 456CD | C4: 5000 | D4: =SUMIFS(MPS!$E$2:$E$217,MPS!$C$2:$C$217,A4,MPS!$B$2:$B$217,B4) -> 0 | E4: =SUMIFS(MPS!$J$2:$J$217,MPS!$C$2:$C$217,A4,MPS!$B$2:$B$217,B4) -> 5000 | F4: =SUMIFS(MPS!$K$2:$K$217,MPS!$C$2:$C$217,A4,MPS!$B$2:$B$217,B4) -> 5000 | G4: =SUMIFS(MPS!$L$2:$L$217,MPS!$C$2:$C$217,A4,MPS!$B$2:$B$217,B4) -> 0 | H4: =IFERROR(E4/C4,0) -> 1 | I4: =IF(E4>C4,"Over shared cap","OK") -> OK | K4: 46132 | L4: 23000 | M4: =SUMIFS(MPS!$E$2:$E$217,MPS!$C$2:$C$217,K4) -> 588 | N4: =SUMIFS(MPS!$J$2:$J$217,MPS!$C$2:$C$217,K4) -> 7837 | O4: =SUMIFS(MPS!$K$2:$K$217,MPS!$C$2:$C$217,K4) -> 28000 | P4: =SUMIFS(MPS!$L$2:$L$217,MPS!$C$2:$C$217,K4) -> 0
A5: 46125 | B5: 789EF | C5: 3000 | D5: =SUMIFS(MPS!$E$2:$E$217,MPS!$C$2:$C$217,A5,MPS!$B$2:$B$217,B5) -> 0 | E5: =SUMIFS(MPS!$J$2:$J$217,MPS!$C$2:$C$217,A5,MPS!$B$2:$B$217,B5) -> 3000 | F5: =SUMIFS(MPS!$K$2:$K$217,MPS!$C$2:$C$217,A5,MPS!$B$2:$B$217,B5) -> 3000 | G5: =SUMIFS(MPS!$L$2:$L$217,MPS!$C$2:$C$217,A5,MPS!$B$2:$B$217,B5) -> 0 | H5: =IFERROR(E5/C5,0) -> 1 | I5: =IF(E5>C5,"Over shared cap","OK") -> OK | K5: 46139 | L5: 23000 | M5: =SUMIFS(MPS!$E$2:$E$217,MPS!$C$2:$C$217,K5) -> 5184 | N5: =SUMIFS(MPS!$J$2:$J$217,MPS!$C$2:$C$217,K5) -> 13684 | O5: =SUMIFS(MPS!$K$2:$K$217,MPS!$C$2:$C$217,K5) -> 36500 | P5: =SUMIFS(MPS!$L$2:$L$217,MPS!$C$2:$C$217,K5) -> 0
A6: 46132 | B6: 123AB | C6: 15000 | D6: =SUMIFS(MPS!$E$2:$E$217,MPS!$C$2:$C$217,A6,MPS!$B$2:$B$217,B6) -> 0 | E6: =SUMIFS(MPS!$J$2:$J$217,MPS!$C$2:$C$217,A6,MPS!$B$2:$B$217,B6) -> 2249 | F6: =SUMIFS(MPS!$K$2:$K$217,MPS!$C$2:$C$217,A6,MPS!$B$2:$B$217,B6) -> 15000 | G6: =SUMIFS(MPS!$L$2:$L$217,MPS!$C$2:$C$217,A6,MPS!$B$2:$B$217,B6) -> 0 | H6: =IFERROR(E6/C6,0) -> 0.14993333 | I6: =IF(E6>C6,"Over shared cap","OK") -> OK | K6: 46146 | L6: 23000 | M6: =SUMIFS(MPS!$E$2:$E$217,MPS!$C$2:$C$217,K6) -> 36752 | N6: =SUMIFS(MPS!$J$2:$J$217,MPS!$C$2:$C$217,K6) -> 23000 | O6: =SUMIFS(MPS!$K$2:$K$217,MPS!$C$2:$C$217,K6) -> 22748 | P6: =SUMIFS(MPS!$L$2:$L$217,MPS!$C$2:$C$217,K6) -> 0
A7: 46132 | B7: 456CD | C7: 5000 | D7: =SUMIFS(MPS!$E$2:$E$217,MPS!$C$2:$C$217,A7,MPS!$B$2:$B$217,B7) -> 0 | E7: =SUMIFS(MPS!$J$2:$J$217,MPS!$C$2:$C$217,A7,MPS!$B$2:$B$217,B7) -> 5000 | F7: =SUMIFS(MPS!$K$2:$K$217,MPS!$C$2:$C$217,A7,MPS!$B$2:$B$217,B7) -> 10000 | G7: =SUMIFS(MPS!$L$2:$L$217,MPS!$C$2:$C$217,A7,MPS!$B$2:$B$217,B7) -> 0 | H7: =IFERROR(E7/C7,0) -> 1 | I7: =IF(E7>C7,"Over shared cap","OK") -> OK | K7: 46153 | L7: 23000 | M7: =SUMIFS(MPS!$E$2:$E$217,MPS!$C$2:$C$217,K7) -> 58518 | N7: =SUMIFS(MPS!$J$2:$J$217,MPS!$C$2:$C$217,K7) -> 23000 | O7: =SUMIFS(MPS!$K$2:$K$217,MPS!$C$2:$C$217,K7) -> 1630 | P7: =SUMIFS(MPS!$L$2:$L$217,MPS!$C$2:$C$217,K7) -> 14400
A8: 46132 | B8: 789EF | C8: 3000 | D8: =SUMIFS(MPS!$E$2:$E$217,MPS!$C$2:$C$217,A8,MPS!$B$2:$B$217,B8) -> 588 | E8: =SUMIFS(MPS!$J$2:$J$217,MPS!$C$2:$C$217,A8,MPS!$B$2:$B$217,B8) -> 588 | F8: =SUMIFS(MPS!$K$2:$K$217,MPS!$C$2:$C$217,A8,MPS!$B$2:$B$217,B8) -> 3000 | G8: =SUMIFS(MPS!$L$2:$L$217,MPS!$C$2:$C$217,A8,MPS!$B$2:$B$217,B8) -> 0 | H8: =IFERROR(E8/C8,0) -> 0.196 | I8: =IF(E8>C8,"Over shared cap","OK") -> OK | K8: 46160 | L8: 23000 | M8: =SUMIFS(MPS!$E$2:$E$217,MPS!$C$2:$C$217,K8) -> 41987 | N8: =SUMIFS(MPS!$J$2:$J$217,MPS!$C$2:$C$217,K8) -> 23000 | O8: =SUMIFS(MPS!$K$2:$K$217,MPS!$C$2:$C$217,K8) -> 0 | P8: =SUMIFS(MPS!$L$2:$L$217,MPS!$C$2:$C$217,K8) -> 17357
A9: 46139 | B9: 123AB | C9: 15000 | D9: =SUMIFS(MPS!$E$2:$E$217,MPS!$C$2:$C$217,A9,MPS!$B$2:$B$217,B9) -> 684 | E9: =SUMIFS(MPS!$J$2:$J$217,MPS!$C$2:$C$217,A9,MPS!$B$2:$B$217,B9) -> 10684 | F9: =SUMIFS(MPS!$K$2:$K$217,MPS!$C$2:$C$217,A9,MPS!$B$2:$B$217,B9) -> 25000 | G9: =SUMIFS(MPS!$L$2:$L$217,MPS!$C$2:$C$217,A9,MPS!$B$2:$B$217,B9) -> 0 | H9: =IFERROR(E9/C9,0) -> 0.71226667 | I9: =IF(E9>C9,"Over shared cap","OK") -> OK | K9: 46167 | L9: 23000 | M9: =SUMIFS(MPS!$E$2:$E$217,MPS!$C$2:$C$217,K9) -> 38270 | N9: =SUMIFS(MPS!$J$2:$J$217,MPS!$C$2:$C$217,K9) -> 23000 | O9: =SUMIFS(MPS!$K$2:$K$217,MPS!$C$2:$C$217,K9) -> 0 | P9: =SUMIFS(MPS!$L$2:$L$217,MPS!$C$2:$C$217,K9) -> 15270
A10: 46139 | B10: 456CD | C10: 5000 | D10: =SUMIFS(MPS!$E$2:$E$217,MPS!$C$2:$C$217,A10,MPS!$B$2:$B$217,B10) -> 0 | E10: =SUMIFS(MPS!$J$2:$J$217,MPS!$C$2:$C$217,A10,MPS!$B$2:$B$217,B10) -> 0 | F10: =SUMIFS(MPS!$K$2:$K$217,MPS!$C$2:$C$217,A10,MPS!$B$2:$B$217,B10) -> 10000 | G10: =SUMIFS(MPS!$L$2:$L$217,MPS!$C$2:$C$217,A10,MPS!$B$2:$B$217,B10) -> 0 | H10: =IFERROR(E10/C10,0) -> 0 | I10: =IF(E10>C10,"Over shared cap","OK") -> OK | K10: 46174 | L10: 23000 | M10: =SUMIFS(MPS!$E$2:$E$217,MPS!$C$2:$C$217,K10) -> 29637 | N10: =SUMIFS(MPS!$J$2:$J$217,MPS!$C$2:$C$217,K10) -> 23000 | O10: =SUMIFS(MPS!$K$2:$K$217,MPS!$C$2:$C$217,K10) -> 1760 | P10: =SUMIFS(MPS!$L$2:$L$217,MPS!$C$2:$C$217,K10) -> 8397
A11: 46139 | B11: 789EF | C11: 3000 | D11: =SUMIFS(MPS!$E$2:$E$217,MPS!$C$2:$C$217,A11,MPS!$B$2:$B$217,B11) -> 4500 | E11: =SUMIFS(MPS!$J$2:$J$217,MPS!$C$2:$C$217,A11,MPS!$B$2:$B$217,B11) -> 3000 | F11: =SUMIFS(MPS!$K$2:$K$217,MPS!$C$2:$C$217,A11,MPS!$B$2:$B$217,B11) -> 1500 | G11: =SUMIFS(MPS!$L$2:$L$217,MPS!$C$2:$C$217,A11,MPS!$B$2:$B$217,B11) -> 0 | H11: =IFERROR(E11/C11,0) -> 1 | I11: =IF(E11>C11,"Over shared cap","OK") -> OK | K11: 46181 | L11: 23000 | M11: =SUMIFS(MPS!$E$2:$E$217,MPS!$C$2:$C$217,K11) -> 25780 | N11: =SUMIFS(MPS!$J$2:$J$217,MPS!$C$2:$C$217,K11) -> 20367 | O11: =SUMIFS(MPS!$K$2:$K$217,MPS!$C$2:$C$217,K11) -> 318 | P11: =SUMIFS(MPS!$L$2:$L$217,MPS!$C$2:$C$217,K11) -> 3971
A12: 46146 | B12: 123AB | C12: 15000 | D12: =SUMIFS(MPS!$E$2:$E$217,MPS!$C$2:$C$217,A12,MPS!$B$2:$B$217,B12) -> 25502 | E12: =SUMIFS(MPS!$J$2:$J$217,MPS!$C$2:$C$217,A12,MPS!$B$2:$B$217,B12) -> 15000 | F12: =SUMIFS(MPS!$K$2:$K$217,MPS!$C$2:$C$217,A12,MPS!$B$2:$B$217,B12) -> 14498 | G12: =SUMIFS(MPS!$L$2:$L$217,MPS!$C$2:$C$217,A12,MPS!$B$2:$B$217,B12) -> 0 | H12: =IFERROR(E12/C12,0) -> 1 | I12: =IF(E12>C12,"Over shared cap","OK") -> OK | K12: 46188 | L12: 23000 | M12: =SUMIFS(MPS!$E$2:$E$217,MPS!$C$2:$C$217,K12) -> 22109 | N12: =SUMIFS(MPS!$J$2:$J$217,MPS!$C$2:$C$217,K12) -> 15349 | O12: =SUMIFS(MPS!$K$2:$K$217,MPS!$C$2:$C$217,K12) -> 500 | P12: =SUMIFS(MPS!$L$2:$L$217,MPS!$C$2:$C$217,K12) -> 6942
A13: 46146 | B13: 456CD | C13: 5000 | D13: =SUMIFS(MPS!$E$2:$E$217,MPS!$C$2:$C$217,A13,MPS!$B$2:$B$217,B13) -> 6750 | E13: =SUMIFS(MPS!$J$2:$J$217,MPS!$C$2:$C$217,A13,MPS!$B$2:$B$217,B13) -> 5000 | F13: =SUMIFS(MPS!$K$2:$K$217,MPS!$C$2:$C$217,A13,MPS!$B$2:$B$217,B13) -> 8250 | G13: =SUMIFS(MPS!$L$2:$L$217,MPS!$C$2:$C$217,A13,MPS!$B$2:$B$217,B13) -> 0 | H13: =IFERROR(E13/C13,0) -> 1 | I13: =IF(E13>C13,"Over shared cap","OK") -> OK | K13: 46195 | L13: 23000 | M13: =SUMIFS(MPS!$E$2:$E$217,MPS!$C$2:$C$217,K13) -> 19736 | N13: =SUMIFS(MPS!$J$2:$J$217,MPS!$C$2:$C$217,K13) -> 14622 | O13: =SUMIFS(MPS!$K$2:$K$217,MPS!$C$2:$C$217,K13) -> 81 | P13: =SUMIFS(MPS!$L$2:$L$217,MPS!$C$2:$C$217,K13) -> 4695
A14: 46146 | B14: 789EF | C14: 3000 | D14: =SUMIFS(MPS!$E$2:$E$217,MPS!$C$2:$C$217,A14,MPS!$B$2:$B$217,B14) -> 4500 | E14: =SUMIFS(MPS!$J$2:$J$217,MPS!$C$2:$C$217,A14,MPS!$B$2:$B$217,B14) -> 3000 | F14: =SUMIFS(MPS!$K$2:$K$217,MPS!$C$2:$C$217,A14,MPS!$B$2:$B$217,B14) -> 0 | G14: =SUMIFS(MPS!$L$2:$L$217,MPS!$C$2:$C$217,A14,MPS!$B$2:$B$217,B14) -> 0 | H14: =IFERROR(E14/C14,0) -> 1 | I14: =IF(E14>C14,"Over shared cap","OK") -> OK | K14: 46202 | L14: 23000 | M14: =SUMIFS(MPS!$E$2:$E$217,MPS!$C$2:$C$217,K14) -> 23041 | N14: =SUMIFS(MPS!$J$2:$J$217,MPS!$C$2:$C$217,K14) -> 21000 | O14: =SUMIFS(MPS!$K$2:$K$217,MPS!$C$2:$C$217,K14) -> 40 | P14: =SUMIFS(MPS!$L$2:$L$217,MPS!$C$2:$C$217,K14) -> 2000
... A38: 46202 | B38: 789EF | C38: 3000 | D38: =SUMIFS(MPS!$E$2:$E$217,MPS!$C$2:$C$217,A38,MPS!$B$2:$B$217,B38) -> 5000 | E38: =SUMIFS(MPS!$J$2:$J$217,MPS!$C$2:$C$217,A38,MPS!$B$2:$B$217,B38) -> 3000 | F38: =SUMIFS(MPS!$K$2:$K$217,MPS!$C$2:$C$217,A38,MPS!$B$2:$B$217,B38) -> 0 | G38: =SUMIFS(MPS!$L$2:$L$217,MPS!$C$2:$C$217,A38,MPS!$B$2:$B$217,B38) -> 2000 | H38: =IFERROR(E38/C38,0) -> 1 | I38: =IF(E38>C38,"Over shared cap","OK") -> OK | K38: 46370 | L38: 23000 | M38: =SUMIFS(MPS!$E$2:$E$217,MPS!$C$2:$C$217,K38) -> 20753 | N38: =SUMIFS(MPS!$J$2:$J$217,MPS!$C$2:$C$217,K38) -> 20753 | O38: =SUMIFS(MPS!$K$2:$K$217,MPS!$C$2:$C$217,K38) -> 0 | P38: =SUMIFS(MPS!$L$2:$L$217,MPS!$C$2:$C$217,K38) -> 0
A39: 46209 | B39: 123AB | C39: 15000 | D39: =SUMIFS(MPS!$E$2:$E$217,MPS!$C$2:$C$217,A39,MPS!$B$2:$B$217,B39) -> 15040 | E39: =SUMIFS(MPS!$J$2:$J$217,MPS!$C$2:$C$217,A39,MPS!$B$2:$B$217,B39) -> 15000 | F39: =SUMIFS(MPS!$K$2:$K$217,MPS!$C$2:$C$217,A39,MPS!$B$2:$B$217,B39) -> 0 | G39: =SUMIFS(MPS!$L$2:$L$217,MPS!$C$2:$C$217,A39,MPS!$B$2:$B$217,B39) -> 0 | H39: =IFERROR(E39/C39,0) -> 1 | I39: =IF(E39>C39,"Over shared cap","OK") -> OK
A40: 46209 | B40: 456CD | C40: 5000 | D40: =SUMIFS(MPS!$E$2:$E$217,MPS!$C$2:$C$217,A40,MPS!$B$2:$B$217,B40) -> 3000 | E40: =SUMIFS(MPS!$J$2:$J$217,MPS!$C$2:$C$217,A40,MPS!$B$2:$B$217,B40) -> 3000 | F40: =SUMIFS(MPS!$K$2:$K$217,MPS!$C$2:$C$217,A40,MPS!$B$2:$B$217,B40) -> 0 | G40: =SUMIFS(MPS!$L$2:$L$217,MPS!$C$2:$C$217,A40,MPS!$B$2:$B$217,B40) -> 0 | H40: =IFERROR(E40/C40,0) -> 0.6 | I40: =IF(E40>C40,"Over shared cap","OK") -> OK
A41: Note | B41: This workbook follows the backward logic from your uploaded MPS sample. Beginning FG of the first week is fixed at 0, shortage is allowed, and week 13-Apr-2026 is added as the first production week. | C41: 3000 | D41: =SUMIFS(MPS!$E$2:$E$217,MPS!$C$2:$C$217,A41,MPS!$B$2:$B$217,B41) -> 0 | E41: =SUMIFS(MPS!$J$2:$J$217,MPS!$C$2:$C$217,A41,MPS!$B$2:$B$217,B41) -> 0 | F41: =SUMIFS(MPS!$K$2:$K$217,MPS!$C$2:$C$217,A41,MPS!$B$2:$B$217,B41) -> 0 | G41: =SUMIFS(MPS!$L$2:$L$217,MPS!$C$2:$C$217,A41,MPS!$B$2:$B$217,B41) -> 0 | H41: =IFERROR(E41/C41,0) -> 0 | I41: =IF(E41>C41,"Over shared cap","OK") -> OK
A42: 46216 | B42: 123AB | C42: 15000 | D42: =SUMIFS(MPS!$E$2:$E$217,MPS!$C$2:$C$217,A42,MPS!$B$2:$B$217,B42) -> 3000 | E42: =SUMIFS(MPS!$J$2:$J$217,MPS!$C$2:$C$217,A42,MPS!$B$2:$B$217,B42) -> 12246 | F42: =SUMIFS(MPS!$K$2:$K$217,MPS!$C$2:$C$217,A42,MPS!$B$2:$B$217,B42) -> 9246 | G42: =SUMIFS(MPS!$L$2:$L$217,MPS!$C$2:$C$217,A42,MPS!$B$2:$B$217,B42) -> 0 | H42: =IFERROR(E42/C42,0) -> 0.8164 | I42: =IF(E42>C42,"Over shared cap","OK") -> OK
A43: 46216 | B43: 456CD | C43: 5000 | D43: =SUMIFS(MPS!$E$2:$E$217,MPS!$C$2:$C$217,A43,MPS!$B$2:$B$217,B43) -> 3000 | E43: =SUMIFS(MPS!$J$2:$J$217,MPS!$C$2:$C$217,A43,MPS!$B$2:$B$217,B43) -> 3000 | F43: =SUMIFS(MPS!$K$2:$K$217,MPS!$C$2:$C$217,A43,MPS!$B$2:$B$217,B43) -> 0 | G43: =SUMIFS(MPS!$L$2:$L$217,MPS!$C$2:$C$217,A43,MPS!$B$2:$B$217,B43) -> 0 | H43: =IFERROR(E43/C43,0) -> 0.6 | I43: =IF(E43>C43,"Over shared cap","OK") -> OK
A44: 46216 | B44: 789EF | C44: 3000 | D44: =SUMIFS(MPS!$E$2:$E$217,MPS!$C$2:$C$217,A44,MPS!$B$2:$B$217,B44) -> 5046 | E44: =SUMIFS(MPS!$J$2:$J$217,MPS!$C$2:$C$217,A44,MPS!$B$2:$B$217,B44) -> 3000 | F44: =SUMIFS(MPS!$K$2:$K$217,MPS!$C$2:$C$217,A44,MPS!$B$2:$B$217,B44) -> 0 | G44: =SUMIFS(MPS!$L$2:$L$217,MPS!$C$2:$C$217,A44,MPS!$B$2:$B$217,B44) -> 2046 | H44: =IFERROR(E44/C44,0) -> 1 | I44: =IF(E44>C44,"Over shared cap","OK") -> OK
A45: 46223 | B45: 123AB | C45: 15000 | D45: =SUMIFS(MPS!$E$2:$E$217,MPS!$C$2:$C$217,A45,MPS!$B$2:$B$217,B45) -> 2400 | E45: =SUMIFS(MPS!$J$2:$J$217,MPS!$C$2:$C$217,A45,MPS!$B$2:$B$217,B45) -> 10554 | F45: =SUMIFS(MPS!$K$2:$K$217,MPS!$C$2:$C$217,A45,MPS!$B$2:$B$217,B45) -> 17400 | G45: =SUMIFS(MPS!$L$2:$L$217,MPS!$C$2:$C$217,A45,MPS!$B$2:$B$217,B45) -> 0 | H45: =IFERROR(E45/C45,0) -> 0.7036 | I45: =IF(E45>C45,"Over shared cap","OK") -> OK
A46: 46223 | B46: 456CD | C46: 5000 | D46: =SUMIFS(MPS!$E$2:$E$217,MPS!$C$2:$C$217,A46,MPS!$B$2:$B$217,B46) -> 1000 | E46: =SUMIFS(MPS!$J$2:$J$217,MPS!$C$2:$C$217,A46,MPS!$B$2:$B$217,B46) -> 1000 | F46: =SUMIFS(MPS!$K$2:$K$217,MPS!$C$2:$C$217,A46,MPS!$B$2:$B$217,B46) -> 0 | G46: =SUMIFS(MPS!$L$2:$L$217,MPS!$C$2:$C$217,A46,MPS!$B$2:$B$217,B46) -> 0 | H46: =IFERROR(E46/C46,0) -> 0.2 | I46: =IF(E46>C46,"Over shared cap","OK") -> OK
A47: 46223 | B47: 789EF | C47: 3000 | D47: =SUMIFS(MPS!$E$2:$E$217,MPS!$C$2:$C$217,A47,MPS!$B$2:$B$217,B47) -> 4600 | E47: =SUMIFS(MPS!$J$2:$J$217,MPS!$C$2:$C$217,A47,MPS!$B$2:$B$217,B47) -> 3000 | F47: =SUMIFS(MPS!$K$2:$K$217,MPS!$C$2:$C$217,A47,MPS!$B$2:$B$217,B47) -> 0 | G47: =SUMIFS(MPS!$L$2:$L$217,MPS!$C$2:$C$217,A47,MPS!$B$2:$B$217,B47) -> 1600 | H47: =IFERROR(E47/C47,0) -> 1 | I47: =IF(E47>C47,"Over shared cap","OK") -> OK
A48: 46230 | B48: 123AB | C48: 15000 | D48: =SUMIFS(MPS!$E$2:$E$217,MPS!$C$2:$C$217,A48,MPS!$B$2:$B$217,B48) -> 30160 | E48: =SUMIFS(MPS!$J$2:$J$217,MPS!$C$2:$C$217,A48,MPS!$B$2:$B$217,B48) -> 15000 | F48: =SUMIFS(MPS!$K$2:$K$217,MPS!$C$2:$C$217,A48,MPS!$B$2:$B$217,B48) -> 2240 | G48: =SUMIFS(MPS!$L$2:$L$217,MPS!$C$2:$C$217,A48,MPS!$B$2:$B$217,B48) -> 0 | H48: =IFERROR(E48/C48,0) -> 1 | I48: =IF(E48>C48,"Over shared cap","OK") -> OK
A49: 46230 | B49: 456CD | C49: 5000 | D49: =SUMIFS(MPS!$E$2:$E$217,MPS!$C$2:$C$217,A49,MPS!$B$2:$B$217,B49) -> 1000 | E49: =SUMIFS(MPS!$J$2:$J$217,MPS!$C$2:$C$217,A49,MPS!$B$2:$B$217,B49) -> 1000 | F49: =SUMIFS(MPS!$K$2:$K$217,MPS!$C$2:$C$217,A49,MPS!$B$2:$B$217,B49) -> 0 | G49: =SUMIFS(MPS!$L$2:$L$217,MPS!$C$2:$C$217,A49,MPS!$B$2:$B$217,B49) -> 0 | H49: =IFERROR(E49/C49,0) -> 0.2 | I49: =IF(E49>C49,"Over shared cap","OK") -> OK
A50: 46230 | B50: 789EF | C50: 3000 | D50: =SUMIFS(MPS!$E$2:$E$217,MPS!$C$2:$C$217,A50,MPS!$B$2:$B$217,B50) -> 476 | E50: =SUMIFS(MPS!$J$2:$J$217,MPS!$C$2:$C$217,A50,MPS!$B$2:$B$217,B50) -> 476 | F50: =SUMIFS(MPS!$K$2:$K$217,MPS!$C$2:$C$217,A50,MPS!$B$2:$B$217,B50) -> 0 | G50: =SUMIFS(MPS!$L$2:$L$217,MPS!$C$2:$C$217,A50,MPS!$B$2:$B$217,B50) -> 0 | H50: =IFERROR(E50/C50,0) -> 0.15866667 | I50: =IF(E50>C50,"Over shared cap","OK") -> OK
A51: 46237 | B51: 123AB | C51: 15000 | D51: =SUMIFS(MPS!$E$2:$E$217,MPS!$C$2:$C$217,A51,MPS!$B$2:$B$217,B51) -> 26486 | E51: =SUMIFS(MPS!$J$2:$J$217,MPS!$C$2:$C$217,A51,MPS!$B$2:$B$217,B51) -> 15000 | F51: =SUMIFS(MPS!$K$2:$K$217,MPS!$C$2:$C$217,A51,MPS!$B$2:$B$217,B51) -> 0 | G51: =SUMIFS(MPS!$L$2:$L$217,MPS!$C$2:$C$217,A51,MPS!$B$2:$B$217,B51) -> 9246 | H51: =IFERROR(E51/C51,0) -> 1 | I51: =IF(E51>C51,"Over shared cap","OK") -> OK
A52: 46237 | B52: 456CD | C52: 5000 | D52: =SUMIFS(MPS!$E$2:$E$217,MPS!$C$2:$C$217,A52,MPS!$B$2:$B$217,B52) -> 1400 | E52: =SUMIFS(MPS!$J$2:$J$217,MPS!$C$2:$C$217,A52,MPS!$B$2:$B$217,B52) -> 1400 | F52: =SUMIFS(MPS!$K$2:$K$217,MPS!$C$2:$C$217,A52,MPS!$B$2:$B$217,B52) -> 0 | G52: =SUMIFS(MPS!$L$2:$L$217,MPS!$C$2:$C$217,A52,MPS!$B$2:$B$217,B52) -> 0 | H52: =IFERROR(E52/C52,0) -> 0.28 | I52: =IF(E52>C52,"Over shared cap","OK") -> OK
A53: 46237 | B53: 789EF | C53: 3000 | D53: =SUMIFS(MPS!$E$2:$E$217,MPS!$C$2:$C$217,A53,MPS!$B$2:$B$217,B53) -> 1298 | E53: =SUMIFS(MPS!$J$2:$J$217,MPS!$C$2:$C$217,A53,MPS!$B$2:$B$217,B53) -> 1298 | F53: =SUMIFS(MPS!$K$2:$K$217,MPS!$C$2:$C$217,A53,MPS!$B$2:$B$217,B53) -> 0 | G53: =SUMIFS(MPS!$L$2:$L$217,MPS!$C$2:$C$217,A53,MPS!$B$2:$B$217,B53) -> 0 | H53: =IFERROR(E53/C53,0) -> 0.43266667 | I53: =IF(E53>C53,"Over shared cap","OK") -> OK
... A110: 46370 | B110: 789EF | C110: 3000 | D110: =SUMIFS(MPS!$E$2:$E$217,MPS!$C$2:$C$217,A110,MPS!$B$2:$B$217,B110) -> 1928 | E110: =SUMIFS(MPS!$J$2:$J$217,MPS!$C$2:$C$217,A110,MPS!$B$2:$B$217,B110) -> 1928 | F110: =SUMIFS(MPS!$K$2:$K$217,MPS!$C$2:$C$217,A110,MPS!$B$2:$B$217,B110) -> 0 | G110: =SUMIFS(MPS!$L$2:$L$217,MPS!$C$2:$C$217,A110,MPS!$B$2:$B$217,B110) -> 0 | H110: =IFERROR(E110/C110,0) -> 0.64266667 | I110: =IF(E110>C110,"Over shared cap","OK") -> OK

Sheet input
A1: Backward MPS Input
A3: Planning logic | B3: Backward scheduling with shared fixture cap lock by fixture-week
A4: Production can start from | B4: 46125
A5: Demand source | B5: SCM_round2.1.xlsx / demand_matrix
A6: Opening FG assumption | B6: 0
A7: Shortage rule | B7: Allowed; not forced to zero; capacity shared by fixture-week with priority A>B, C>D, E>F
A9: SKU | B9: Description | C9: Fixture | D9: Weekly Capacity | E9: Opening FG | F9: Storage Cap | G9: Priority | H9: Week | I9: A | J9: B | K9: C | L9: D | M9: E | N9: F
A10: A | B10: 2026 Automatic Robot ver | C10: 123AB | D10: 15000 | E10: 0 | F10: 15000 | G10: 1 | H10: 46125 | I10: 0 | J10: 0 | K10: 0 | L10: 0 | M10: 0 | N10: 0
A11: B | B11: 2025 Barbie ver colorful | C11: 123AB | D11: 15000 | E11: 0 | F11: 15000 | G11: 2 | H11: 46132 | I11: 0 | J11: 0 | K11: 0 | L11: 0 | M11: 0 | N11: 588
A12: C | B12: 2026 Castle & Farm Blocks | C12: 456CD | D12: 5000 | E12: 0 | F12: 5000 | G12: 1 | H12: 46139 | I12: 684 | J12: 0 | K12: 0 | L12: 0 | M12: 472 | N12: 4028
A13: D | B13: 2026 Animal Animation Book | C13: 456CD | D13: 5000 | E13: 0 | F13: 5000 | G13: 2 | H13: 46146 | I13: 20000 | J13: 5502 | K13: 4320 | L13: 2430 | M13: 300 | N13: 4200
A14: E | B14: 2026 Scooter ver | C14: 789EF | D14: 3000 | E14: 0 | F14: 3000 | G14: 1 | H14: 46153 | I14: 20000 | J14: 15658 | K14: 8370 | L14: 9990 | M14: 698 | N14: 3802
A15: F | B15: 2025 Fantasy Spaceship Model DIY kits | C15: 789EF | D15: 3000 | E15: 0 | F15: 3000 | G15: 2 | H15: 46160 | I15: 11000 | J15: 8865 | K15: 11782 | L15: 5840 | M15: 0 | N15: 4500
H16: 46167 | I16: 13000 | J16: 2146 | K16: 10524 | L16: 8100 | M16: 300 | N16: 4200
H17: 46174 | I17: 13773 | J17: 7123 | K17: 3240 | L17: 1001 | M17: 0 | N17: 4500
H18: 46181 | I18: 7058 | J18: 5309 | K18: 6442 | L18: 2471 | M18: 0 | N18: 4500
H19: 46188 | I19: 2040 | J19: 5309 | K19: 8802 | L19: 3458 | M19: 300 | N19: 2200
H20: 46195 | I20: 3541 | J20: 3000 | K20: 7695 | L20: 500 | M20: 0 | N20: 5000
H21: 46202 | I21: 12041 | J21: 3000 | K21: 2500 | L21: 500 | M21: 700 | N21: 4300
H22: 46209 | I22: 12040 | J22: 3000 | K22: 2500 | L22: 500 | M22: 300 | N22: 4700
H23: 46216 | I23: 0 | J23: 3000 | K23: 2500 | L23: 500 | M23: 300 | N23: 4746
H24: 46223 | I24: 0 | J24: 2400 | K24: 1000 | L24: 0 | M24: 300 | N24: 4300
H25: 46230 | I25: 27760 | J25: 2400 | K25: 1000 | L25: 0 | M25: 0 | N25: 476
H26: 46237 | I26: 26486 | J26: 0 | K26: 1000 | L26: 400 | M26: 0 | N26: 1298
H27: 46244 | I27: 4248 | J27: 2400 | K27: 1000 | L27: 0 | M27: 300 | N27: 1300
... H45: 46370 | I45: 8325 | J45: 6250 | K45: 3000 | L45: 1250 | M45: 0 | N45: 1928

Sheet MPS
A1: SKU | B1: Fixture | C1: Week | D1: Weekly Capacity | E1: Total Demand | F1: Beginning FG Inv | G1: Storage Cap | H1: Carryover Needed | I1: Net Required | J1: Planned Production | K1: Ending FG Inv | L1: Shortage | M1: ATP | N1: Capacity Load % | O1: Planner Note | P1: Shared Planned Before SKU | Q1: Remaining Shared Fixture Cap | R1: Fulfilled Demand | U1: =SUM(L:L) -> 88174
A2: A | B2: 123AB | C2: 46125 | D2: 15000 | E2: 0 | F2: =0 -> 0 | G2: 15000 | H2: =MAX(0,H3+E3-Q3) -> 0 | I2: =MAX(0,E2+H2-F2) -> 0 | J2: =MIN(Q2,I2,MAX(0,E2+G2-F2)) -> 0 | K2: =MIN(G2,MAX(0,F2+J2-E2)) -> 0 | L2: =MAX(0,E2-F2-J2) -> 0 | M2: =MAX(0,F2+J2-E2) -> 0 | N2: =IFERROR(SUMIFS($J$2:$J$217,$B$2:$B$217,B2,$C$2:$C$217,C2)/D2,0) -> 0.85006667 | O2: First week beginning FG fixed at 0; shared cap locked in Q | P2: =0 -> 0 | Q2: =MAX(0,D2-P2) -> 15000 | R2: =MAX(0,MIN(E2,F2+J2)) -> 0 | U2: =SUM(E:E) -> 680312
A3: A | B3: 123AB | C3: 46132 | D3: 15000 | E3: 0 | F3: =K2 -> 0 | G3: 15000 | H3: =MAX(0,H4+E4-Q4) -> 0 | I3: =MAX(0,E3+H3-F3) -> 0 | J3: =MIN(Q3,I3,MAX(0,E3+G3-F3)) -> 0 | K3: =MIN(G3,MAX(0,F3+J3-E3)) -> 0 | L3: =MAX(0,E3-F3-J3) -> 0 | M3: =MAX(0,F3+J3-E3) -> 0 | N3: =IFERROR(SUMIFS($J$2:$J$217,$B$2:$B$217,B3,$C$2:$C$217,C3)/D3,0) -> 0.14993333 | O3: Carryover is computed backward from next week | P3: =SUMIFS($J$2:J2,$B$2:B2,B3,$C$2:C2,C3) -> 0 | Q3: =MAX(0,D3-P3) -> 15000 | R3: =MAX(0,MIN(E3,F3+J3)) -> 0 | U3: =U1/U2 -> 0.12960818
A4: A | B4: 123AB | C4: 46139 | D4: 15000 | E4: 684 | F4: =K3 -> 0 | G4: 15000 | H4: =MAX(0,H5+E5-Q5) -> 10000 | I4: =MAX(0,E4+H4-F4) -> 10684 | J4: =MIN(Q4,I4,MAX(0,E4+G4-F4)) -> 10684 | K4: =MIN(G4,MAX(0,F4+J4-E4)) -> 10000 | L4: =MAX(0,E4-F4-J4) -> 0 | M4: =MAX(0,F4+J4-E4) -> 10000 | N4: =IFERROR(SUMIFS($J$2:$J$217,$B$2:$B$217,B4,$C$2:$C$217,C4)/D4,0) -> 0.71226667 | P4: =SUMIFS($J$2:J3,$B$2:B3,B4,$C$2:C3,C4) -> 0 | Q4: =MAX(0,D4-P4) -> 15000 | R4: =MAX(0,MIN(E4,F4+J4)) -> 684
A5: A | B5: 123AB | C5: 46146 | D5: 15000 | E5: 20000 | F5: =K4 -> 10000 | G5: 15000 | H5: =MAX(0,H6+E6-Q6) -> 5000 | I5: =MAX(0,E5+H5-F5) -> 15000 | J5: =MIN(Q5,I5,MAX(0,E5+G5-F5)) -> 15000 | K5: =MIN(G5,MAX(0,F5+J5-E5)) -> 5000 | L5: =MAX(0,E5-F5-J5) -> 0 | M5: =MAX(0,F5+J5-E5) -> 5000 | N5: =IFERROR(SUMIFS($J$2:$J$217,$B$2:$B$217,B5,$C$2:$C$217,C5)/D5,0) -> 1 | P5: =SUMIFS($J$2:J4,$B$2:B4,B5,$C$2:C4,C5) -> 0 | Q5: =MAX(0,D5-P5) -> 15000 | R5: =MAX(0,MIN(E5,F5+J5)) -> 20000
A6: A | B6: 123AB | C6: 46153 | D6: 15000 | E6: 20000 | F6: =K5 -> 5000 | G6: 15000 | H6: =MAX(0,H7+E7-Q7) -> 0 | I6: =MAX(0,E6+H6-F6) -> 15000 | J6: =MIN(Q6,I6,MAX(0,E6+G6-F6)) -> 15000 | K6: =MIN(G6,MAX(0,F6+J6-E6)) -> 0 | L6: =MAX(0,E6-F6-J6) -> 0 | M6: =MAX(0,F6+J6-E6) -> 0 | N6: =IFERROR(SUMIFS($J$2:$J$217,$B$2:$B$217,B6,$C$2:$C$217,C6)/D6,0) -> 1 | P6: =SUMIFS($J$2:J5,$B$2:B5,B6,$C$2:C5,C6) -> 0 | Q6: =MAX(0,D6-P6) -> 15000 | R6: =MAX(0,MIN(E6,F6+J6)) -> 20000
A7: A | B7: 123AB | C7: 46160 | D7: 15000 | E7: 11000 | F7: =K6 -> 0 | G7: 15000 | H7: =MAX(0,H8+E8-Q8) -> 0 | I7: =MAX(0,E7+H7-F7) -> 11000 | J7: =MIN(Q7,I7,MAX(0,E7+G7-F7)) -> 11000 | K7: =MIN(G7,MAX(0,F7+J7-E7)) -> 0 | L7: =MAX(0,E7-F7-J7) -> 0 | M7: =MAX(0,F7+J7-E7) -> 0 | N7: =IFERROR(SUMIFS($J$2:$J$217,$B$2:$B$217,B7,$C$2:$C$217,C7)/D7,0) -> 1 | P7: =SUMIFS($J$2:J6,$B$2:B6,B7,$C$2:C6,C7) -> 0 | Q7: =MAX(0,D7-P7) -> 15000 | R7: =MAX(0,MIN(E7,F7+J7)) -> 11000
A8: A | B8: 123AB | C8: 46167 | D8: 15000 | E8: 13000 | F8: =K7 -> 0 | G8: 15000 | H8: =MAX(0,H9+E9-Q9) -> 0 | I8: =MAX(0,E8+H8-F8) -> 13000 | J8: =MIN(Q8,I8,MAX(0,E8+G8-F8)) -> 13000 | K8: =MIN(G8,MAX(0,F8+J8-E8)) -> 0 | L8: =MAX(0,E8-F8-J8) -> 0 | M8: =MAX(0,F8+J8-E8) -> 0 | N8: =IFERROR(SUMIFS($J$2:$J$217,$B$2:$B$217,B8,$C$2:$C$217,C8)/D8,0) -> 1 | P8: =SUMIFS($J$2:J7,$B$2:B7,B8,$C$2:C7,C8) -> 0 | Q8: =MAX(0,D8-P8) -> 15000 | R8: =MAX(0,MIN(E8,F8+J8)) -> 13000
A9: A | B9: 123AB | C9: 46174 | D9: 15000 | E9: 13773 | F9: =K8 -> 0 | G9: 15000 | H9: =MAX(0,H10+E10-Q10) -> 0 | I9: =MAX(0,E9+H9-F9) -> 13773 | J9: =MIN(Q9,I9,MAX(0,E9+G9-F9)) -> 13773 | K9: =MIN(G9,MAX(0,F9+J9-E9)) -> 0 | L9: =MAX(0,E9-F9-J9) -> 0 | M9: =MAX(0,F9+J9-E9) -> 0 | N9: =IFERROR(SUMIFS($J$2:$J$217,$B$2:$B$217,B9,$C$2:$C$217,C9)/D9,0) -> 1 | P9: =SUMIFS($J$2:J8,$B$2:B8,B9,$C$2:C8,C9) -> 0 | Q9: =MAX(0,D9-P9) -> 15000 | R9: =MAX(0,MIN(E9,F9+J9)) -> 13773
A10: A | B10: 123AB | C10: 46181 | D10: 15000 | E10: 7058 | F10: =K9 -> 0 | G10: 15000 | H10: =MAX(0,H11+E11-Q11) -> 0 | I10: =MAX(0,E10+H10-F10) -> 7058 | J10: =MIN(Q10,I10,MAX(0,E10+G10-F10)) -> 7058 | K10: =MIN(G10,MAX(0,F10+J10-E10)) -> 0 | L10: =MAX(0,E10-F10-J10) -> 0 | M10: =MAX(0,F10+J10-E10) -> 0 | N10: =IFERROR(SUMIFS($J$2:$J$217,$B$2:$B$217,B10,$C$2:$C$217,C10)/D10,0) -> 0.82446667 | P10: =SUMIFS($J$2:J9,$B$2:B9,B10,$C$2:C9,C10) -> 0 | Q10: =MAX(0,D10-P10) -> 15000 | R10: =MAX(0,MIN(E10,F10+J10)) -> 7058
A11: A | B11: 123AB | C11: 46188 | D11: 15000 | E11: 2040 | F11: =K10 -> 0 | G11: 15000 | H11: =MAX(0,H12+E12-Q12) -> 0 | I11: =MAX(0,E11+H11-F11) -> 2040 | J11: =MIN(Q11,I11,MAX(0,E11+G11-F11)) -> 2040 | K11: =MIN(G11,MAX(0,F11+J11-E11)) -> 0 | L11: =MAX(0,E11-F11-J11) -> 0 | M11: =MAX(0,F11+J11-E11) -> 0 | N11: =IFERROR(SUMIFS($J$2:$J$217,$B$2:$B$217,B11,$C$2:$C$217,C11)/D11,0) -> 0.48993333 | P11: =SUMIFS($J$2:J10,$B$2:B10,B11,$C$2:C10,C11) -> 0 | Q11: =MAX(0,D11-P11) -> 15000 | R11: =MAX(0,MIN(E11,F11+J11)) -> 2040
A12: A | B12: 123AB | C12: 46195 | D12: 15000 | E12: 3541 | F12: =K11 -> 0 | G12: 15000 | H12: =MAX(0,H13+E13-Q13) -> 0 | I12: =MAX(0,E12+H12-F12) -> 3541 | J12: =MIN(Q12,I12,MAX(0,E12+G12-F12)) -> 3541 | K12: =MIN(G12,MAX(0,F12+J12-E12)) -> 0 | L12: =MAX(0,E12-F12-J12) -> 0 | M12: =MAX(0,F12+J12-E12) -> 0 | N12: =IFERROR(SUMIFS($J$2:$J$217,$B$2:$B$217,B12,$C$2:$C$217,C12)/D12,0) -> 0.44146667 | P12: =SUMIFS($J$2:J11,$B$2:B11,B12,$C$2:C11,C12) -> 0 | Q12: =MAX(0,D12-P12) -> 15000 | R12: =MAX(0,MIN(E12,F12+J12)) -> 3541
A13: A | B13: 123AB | C13: 46202 | D13: 15000 | E13: 12041 | F13: =K12 -> 0 | G13: 15000 | H13: =MAX(0,H14+E14-Q14) -> 0 | I13: =MAX(0,E13+H13-F13) -> 12041 | J13: =MIN(Q13,I13,MAX(0,E13+G13-F13)) -> 12041 | K13: =MIN(G13,MAX(0,F13+J13-E13)) -> 0 | L13: =MAX(0,E13-F13-J13) -> 0 | M13: =MAX(0,F13+J13-E13) -> 0 | N13: =IFERROR(SUMIFS($J$2:$J$217,$B$2:$B$217,B13,$C$2:$C$217,C13)/D13,0) -> 1 | P13: =SUMIFS($J$2:J12,$B$2:B12,B13,$C$2:C12,C13) -> 0 | Q13: =MAX(0,D13-P13) -> 15000 | R13: =MAX(0,MIN(E13,F13+J13)) -> 12041
A14: A | B14: 123AB | C14: 46209 | D14: 15000 | E14: 12040 | F14: =K13 -> 0 | G14: 15000 | H14: =MAX(0,H15+E15-Q15) -> 0 | I14: =MAX(0,E14+H14-F14) -> 12040 | J14: =MIN(Q14,I14,MAX(0,E14+G14-F14)) -> 12040 | K14: =MIN(G14,MAX(0,F14+J14-E14)) -> 0 | L14: =MAX(0,E14-F14-J14) -> 0 | M14: =MAX(0,F14+J14-E14) -> 0 | N14: =IFERROR(SUMIFS($J$2:$J$217,$B$2:$B$217,B14,$C$2:$C$217,C14)/D14,0) -> 1 | P14: =SUMIFS($J$2:J13,$B$2:B13,B14,$C$2:C13,C14) -> 0 | Q14: =MAX(0,D14-P14) -> 15000 | R14: =MAX(0,MIN(E14,F14+J14)) -> 12040
A15: A | B15: 123AB | C15: 46216 | D15: 15000 | E15: 0 | F15: =K14 -> 0 | G15: 15000 | H15: =MAX(0,H16+E16-Q16) -> 9246 | I15: =MAX(0,E15+H15-F15) -> 9246 | J15: =MIN(Q15,I15,MAX(0,E15+G15-F15)) -> 9246 | K15: =MIN(G15,MAX(0,F15+J15-E15)) -> 9246 | L15: =MAX(0,E15-F15-J15) -> 0 | M15: =MAX(0,F15+J15-E15) -> 9246 | N15: =IFERROR(SUMIFS($J$2:$J$217,$B$2:$B$217,B15,$C$2:$C$217,C15)/D15,0) -> 0.8164 | P15: =SUMIFS($J$2:J14,$B$2:B14,B15,$C$2:C14,C15) -> 0 | Q15: =MAX(0,D15-P15) -> 15000 | R15: =MAX(0,MIN(E15,F15+J15)) -> 0
... A36: A | B36: 123AB | C36: 46363 | D36: 15000 | E36: 8326 | F36: =K35 -> 0 | G36: 15000 | H36: =MAX(0,H37+E37-Q37) -> 0 | I36: =MAX(0,E36+H36-F36) -> 8326 | J36: =MIN(Q36,I36,MAX(0,E36+G36-F36)) -> 8326 | K36: =MIN(G36,MAX(0,F36+J36-E36)) -> 0 | L36: =MAX(0,E36-F36-J36) -> 0 | M36: =MAX(0,F36+J36-E36) -> 0 | N36: =IFERROR(SUMIFS($J$2:$J$217,$B$2:$B$217,B36,$C$2:$C$217,C36)/D36,0) -> 0.97173333 | P36: =SUMIFS($J$2:J35,$B$2:B35,B36,$C$2:C35,C36) -> 0 | Q36: =MAX(0,D36-P36) -> 15000 | R36: =MAX(0,MIN(E36,F36+J36)) -> 8326
A37: A | B37: 123AB | C37: 46370 | D37: 15000 | E37: 8325 | F37: =K36 -> 0 | G37: 15000 | H37: =0 -> 0 | I37: =MAX(0,E37+H37-F37) -> 8325 | J37: =MIN(Q37,I37,MAX(0,E37+G37-F37)) -> 8325 | K37: =MIN(G37,MAX(0,F37+J37-E37)) -> 0 | L37: =MAX(0,E37-F37-J37) -> 0 | M37: =MAX(0,F37+J37-E37) -> 0 | N37: =IFERROR(SUMIFS($J$2:$J$217,$B$2:$B$217,B37,$C$2:$C$217,C37)/D37,0) -> 0.97166667 | P37: =SUMIFS($J$2:J36,$B$2:B36,B37,$C$2:C36,C37) -> 0 | Q37: =MAX(0,D37-P37) -> 15000 | R37: =MAX(0,MIN(E37,F37+J37)) -> 8325
A38: B | B38: 123AB | C38: 46125 | D38: 15000 | E38: 0 | F38: =0 -> 0 | G38: 15000 | H38: =MAX(0,H39+E39-Q39) -> 12751 | I38: =MAX(0,E38+H38-F38) -> 12751 | J38: =MIN(Q38,I38,MAX(0,E38+G38-F38)) -> 12751 | K38: =MIN(G38,MAX(0,F38+J38-E38)) -> 12751 | L38: =MAX(0,E38-F38-J38) -> 0 | M38: =MAX(0,F38+J38-E38) -> 12751 | N38: =IFERROR(SUMIFS($J$2:$J$217,$B$2:$B$217,B38,$C$2:$C$217,C38)/D38,0) -> 0.85006667 | O38: Lower-priority SKU uses remaining shared fixture capacity only | P38: =SUMIFS($J$2:J37,$B$2:B37,B38,$C$2:C37,C38) -> 0 | Q38: =MAX(0,D38-P38) -> 15000 | R38: =MAX(0,MIN(E38,F38+J38)) -> 0
A39: B | B39: 123AB | C39: 46132 | D39: 15000 | E39: 0 | F39: =K38 -> 12751 | G39: 15000 | H39: =MAX(0,H40+E40-Q40) -> 27751 | I39: =MAX(0,E39+H39-F39) -> 15000 | J39: =MIN(Q39,I39,MAX(0,E39+G39-F39)) -> 2249 | K39: =MIN(G39,MAX(0,F39+J39-E39)) -> 15000 | L39: =MAX(0,E39-F39-J39) -> 0 | M39: =MAX(0,F39+J39-E39) -> 15000 | N39: =IFERROR(SUMIFS($J$2:$J$217,$B$2:$B$217,B39,$C$2:$C$217,C39)/D39,0) -> 0.14993333 | P39: =SUMIFS($J$2:J38,$B$2:B38,B39,$C$2:C38,C39) -> 0 | Q39: =MAX(0,D39-P39) -> 15000 | R39: =MAX(0,MIN(E39,F39+J39)) -> 0
A40: B | B40: 123AB | C40: 46139 | D40: 15000 | E40: 0 | F40: =K39 -> 15000 | G40: 15000 | H40: =MAX(0,H41+E41-Q41) -> 32067 | I40: =MAX(0,E40+H40-F40) -> 17067 | J40: =MIN(Q40,I40,MAX(0,E40+G40-F40)) -> 0 | K40: =MIN(G40,MAX(0,F40+J40-E40)) -> 15000 | L40: =MAX(0,E40-F40-J40) -> 0 | M40: =MAX(0,F40+J40-E40) -> 15000 | N40: =IFERROR(SUMIFS($J$2:$J$217,$B$2:$B$217,B40,$C$2:$C$217,C40)/D40,0) -> 0.71226667 | P40: =SUMIFS($J$2:J39,$B$2:B39,B40,$C$2:C39,C40) -> 10684 | Q40: =MAX(0,D40-P40) -> 4316 | R40: =MAX(0,MIN(E40,F40+J40)) -> 0
A41: B | B41: 123AB | C41: 46146 | D41: 15000 | E41: 5502 | F41: =K40 -> 15000 | G41: 15000 | H41: =MAX(0,H42+E42-Q42) -> 26565 | I41: =MAX(0,E41+H41-F41) -> 17067 | J41: =MIN(Q41,I41,MAX(0,E41+G41-F41)) -> 0 | K41: =MIN(G41,MAX(0,F41+J41-E41)) -> 9498 | L41: =MAX(0,E41-F41-J41) -> 0 | M41: =MAX(0,F41+J41-E41) -> 9498 | N41: =IFERROR(SUMIFS($J$2:$J$217,$B$2:$B$217,B41,$C$2:$C$217,C41)/D41,0) -> 1 | P41: =SUMIFS($J$2:J40,$B$2:B40,B41,$C$2:C40,C41) -> 15000 | Q41: =MAX(0,D41-P41) -> 0 | R41: =MAX(0,MIN(E41,F41+J41)) -> 5502
A42: B | B42: 123AB | C42: 46153 | D42: 15000 | E42: 15658 | F42: =K41 -> 9498 | G42: 15000 | H42: =MAX(0,H43+E43-Q43) -> 10907 | I42: =MAX(0,E42+H42-F42) -> 17067 | J42: =MIN(Q42,I42,MAX(0,E42+G42-F42)) -> 0 | K42: =MIN(G42,MAX(0,F42+J42-E42)) -> 0 | L42: =MAX(0,E42-F42-J42) -> 6160 | M42: =MAX(0,F42+J42-E42) -> 0 | N42: =IFERROR(SUMIFS($J$2:$J$217,$B$2:$B$217,B42,$C$2:$C$217,C42)/D42,0) -> 1 | P42: =SUMIFS($J$2:J41,$B$2:B41,B42,$C$2:C41,C42) -> 15000 | Q42: =MAX(0,D42-P42) -> 0 | R42: =MAX(0,MIN(E42,F42+J42)) -> 9498
A43: B | B43: 123AB | C43: 46160 | D43: 15000 | E43: 8865 | F43: =K42 -> 0 | G43: 15000 | H43: =MAX(0,H44+E44-Q44) -> 6042 | I43: =MAX(0,E43+H43-F43) -> 14907 | J43: =MIN(Q43,I43,MAX(0,E43+G43-F43)) -> 4000 | K43: =MIN(G43,MAX(0,F43+J43-E43)) -> 0 | L43: =MAX(0,E43-F43-J43) -> 4865 | M43: =MAX(0,F43+J43-E43) -> 0 | N43: =IFERROR(SUMIFS($J$2:$J$217,$B$2:$B$217,B43,$C$2:$C$217,C43)/D43,0) -> 1 | P43: =SUMIFS($J$2:J42,$B$2:B42,B43,$C$2:C42,C43) -> 11000 | Q43: =MAX(0,D43-P43) -> 4000 | R43: =MAX(0,MIN(E43,F43+J43)) -> 4000
A44: B | B44: 123AB | C44: 46167 | D44: 15000 | E44: 2146 | F44: =K43 -> 0 | G44: 15000 | H44: =MAX(0,H45+E45-Q45) -> 5896 | I44: =MAX(0,E44+H44-F44) -> 8042 | J44: =MIN(Q44,I44,MAX(0,E44+G44-F44)) -> 2000 | K44: =MIN(G44,MAX(0,F44+J44-E44)) -> 0 | L44: =MAX(0,E44-F44-J44) -> 146 | M44: =MAX(0,F44+J44-E44) -> 0 | N44: =IFERROR(SUMIFS($J$2:$J$217,$B$2:$B$217,B44,$C$2:$C$217,C44)/D44,0) -> 1 | P44: =SUMIFS($J$2:J43,$B$2:B43,B44,$C$2:C43,C44) -> 13000 | Q44: =MAX(0,D44-P44) -> 2000 | R44: =MAX(0,MIN(E44,F44+J44)) -> 2000
A45: B | B45: 123AB | C45: 46174 | D45: 15000 | E45: 7123 | F45: =K44 -> 0 | G45: 15000 | H45: =MAX(0,H46+E46-Q46) -> 0 | I45: =MAX(0,E45+H45-F45) -> 7123 | J45: =MIN(Q45,I45,MAX(0,E45+G45-F45)) -> 1227 | K45: =MIN(G45,MAX(0,F45+J45-E45)) -> 0 | L45: =MAX(0,E45-F45-J45) -> 5896 | M45: =MAX(0,F45+J45-E45) -> 0 | N45: =IFERROR(SUMIFS($J$2:$J$217,$B$2:$B$217,B45,$C$2:$C$217,C45)/D45,0) -> 1 | P45: =SUMIFS($J$2:J44,$B$2:B44,B45,$C$2:C44,C45) -> 13773 | Q45: =MAX(0,D45-P45) -> 1227 | R45: =MAX(0,MIN(E45,F45+J45)) -> 1227
A46: B | B46: 123AB | C46: 46181 | D46: 15000 | E46: 5309 | F46: =K45 -> 0 | G46: 15000 | H46: =MAX(0,H47+E47-Q47) -> 0 | I46: =MAX(0,E46+H46-F46) -> 5309 | J46: =MIN(Q46,I46,MAX(0,E46+G46-F46)) -> 5309 | K46: =MIN(G46,MAX(0,F46+J46-E46)) -> 0 | L46: =MAX(0,E46-F46-J46) -> 0 | M46: =MAX(0,F46+J46-E46) -> 0 | N46: =IFERROR(SUMIFS($J$2:$J$217,$B$2:$B$217,B46,$C$2:$C$217,C46)/D46,0) -> 0.82446667 | P46: =SUMIFS($J$2:J45,$B$2:B45,B46,$C$2:C45,C46) -> 7058 | Q46: =MAX(0,D46-P46) -> 7942 | R46: =MAX(0,MIN(E46,F46+J46)) -> 5309
