Workbook
Name Type: #REF!
Name Type: #REF!

Sheet Production Plan_new scenario
A1: Production Planning | J1: Calendar Buckets & Available Capacity (6 workdays/week, Sunday off) | R1: PCBA Supply Scenario (Robotic A) | U1: PCBA logistics cost & inventory check (SKU A) | AD1: Scenario KPI Summary
J2: Bucket | K2: Start | L2: End | M2: Workdays | N2: Workdays/6 | O2: Notes | R2: Affected SKU | S2: A | U2: Air units | V2: =SUM(W6:W32) | W2: Air cost/pc | X2: =$S$11 | AD2: Total shortage | AE2: =SUM(AM43:AM63)
A3: Start date | B3: 46127 | J3: B1 | K3: =$B$3 | L3: =MIN(B3+($B$5-WEEKDAY(B3,2)), $B$4) | M3: =L3-K3+1 | N3: 0.67 | O3: Mon–Sat; Sunday off | R3: PCBA per FG (pcs) | S3: 1 | U3: Sea units | V3: =SUM(X6:X32) | W3: Sea cost/pc | X3: =$S$12 | AD3: Total late qty | AE3: =SUM(AO43:AO63)
A4: End date | B4: 46157 | J4: B2 | K4: =L3+2 | L4: =K4+5 | M4: =L4-K4+1 | N4: 1 | O4: Mon–Sat; Sunday off | R4: On-hand GOOD PCBA in VN (pcs) | S4: 0 | U4: Total cost | V4: =V2*X2+V3*X3 | AD4: Total air units | AE4: =SUM(W6:W32)
A5: Workdays / week | B5: 6 | J5: B3 | K5: =L4+2 | L5: =K5+5 | M5: =L5-K5+1 | N5: 1 | O5: Mon–Sat; Sunday off | R5: Vendor held DEFECT PCBA (pcs) | S5: 30000 | U5: Date | V5: Production (A) | W5: Air arr | X5: Sea arr | Y5: Reflash arr | Z5: Beg Inv | AA5: End Inv | AB5: Flag | AD5: Total sea units | AE5: =SUM(X6:X32)
A6: Shifts / day | B6: 2 | J6: B4 | K6: =L5+2 | L6: =K6+5 | M6: =L6-K6+1 | N6: 1 | O6: Mon–Sat; Sunday off | R6: Reflash equipment available date | S6: =$B$3+21 | U6: 46127 | V6: 0 | W6: 0 | X6: 0 | Y6: 0 | Z6: 0 | AA6: 0 | AB6: OK | AD6: Estimated number of air shipments | AE6: =ROUNDUP(AE4/$AE$11,0)
A7: Lead time min (days) | B7: 7 | J7: B5 | K7: =L6+2 | L7: =$B$4 | M7: =L7-K7+1 | N7: 0.83 | O7: Mon–Sat; Sunday off | R7: Reflash capacity (pcs/day) | S7: 4000 | U7: 46128 | V7: 0 | W7: 0 | X7: 0 | Y7: 0 | Z7: 0 | AA7: 0 | AB7: OK | AD7: Estimated number of sea shipments | AE7: =ROUNDUP(AE5/$AE$12,0)
A8: Lead time max (days) | B8: 14 | R8: Supplier new PCBA capacity (pcs/day) | S8: 4000 | U8: 46129 | V8: 0 | W8: 0 | X8: 0 | Y8: 0 | Z8: 0 | AA8: 0 | AB8: OK | AD8: Total logistics cost (USD | AE8: =AE4*$S$11+AE5*$S$12
A9: Note | B9: Factory runs 2 shifts/day, 6 days/week (Sunday off). Plan buckets follow Mon–Sat weeks. | R9: Air lead time (days) | S9: 3 | U9: 46130 | V9: 0 | W9: 0 | X9: 0 | Y9: 0 | Z9: 0 | AA9: 0 | AB9: OK
A10: Overall | R10: Sea lead time (days) | S10: 21 | U10: 46132 | V10: 0 | W10: 0 | X10: 0 | Y10: 0 | Z10: 0 | AA10: 0 | AB10: OK | AD10: Shipment assumptions
A11: Total workdays in horizon | B11: =(B4-B3-4)+1 | R11: Air freight cost (USD/pc) | S11: 2 | U11: 46133 | V11: 0 | W11: 0 | X11: 0 | Y11: 0 | Z11: 0 | AA11: 0 | AB11: OK | AD11: Air shipment capacity per trip (PCBA units) | AE11: 1700
A12: Theoretical shipment request estimated by lead time | B12: =TEXT(B3+B7,"dd/mm")&" - "&TEXT(B4+B8,"dd/mm") | R12: Sea freight cost (USD/pc) | S12: 0 | U12: 46134 | V12: 0 | W12: 0 | X12: 0 | Y12: 0 | Z12: 0 | AA12: 0 | AB12: OK | AD12: Sea shipment capacity per trip (PCBA units) | AE12: 10000
U13: 46135 | V13: 0 | W13: 0 | X13: 0 | Y13: 0 | Z13: 0 | AA13: 0 | AB13: OK
A14: Demand Aggregated for Production Horizon (15.4-15.5) | Q14: NOTE | U14: 46136 | V14: 0 | W14: 0 | X14: 0 | Y14: 0 | Z14: 0 | AA14: 0 | AB14: OK
Q15: Air cost/pc | R15: Air cost per piece | S15: Chi phí vận chuyển hàng không trên mỗi đơn vị PCBA. | U15: 46137 | V15: 684 | W15: 684 | X15: 0 | Y15: 0 | Z15: 0 | AA15: 0 | AB15: OK
A16: SKU | B16: Description | C16: Market | D16: Product group | E16: Fixture | F16: Weekly capacity | G16: Ship request | H16: Demand quantity | I16: Earliest production date (Ship-LeadMax) | J16: Latest production date (Ship-LeadMin) | Q16: Sea cost/pc | R16: Sea cost per piece | S16: Chi phí vận chuyển đường biển trên mỗi đơn vị PCBA. | U16: 46139 | V16: 0 | W16: 0 | X16: 0 | Y16: 0 | Z16: 0 | AA16: 0 | AB16: OK
A17: A | B17: 2026 Automatic Robot ver | C17: US | D17: Electronic Toy | E17: 123AB | F17: 15000 | G17: 46150 | H17: =SUMIFS('Demand for Production Plan'!$I:$I,'Demand for Production Plan'!$A:$A,$A17,'Demand for Production Plan'!$C:$C,$C17,'Demand for Production Plan'!$F:$F,$E17,'Demand for Production Plan'!$H:$H,$G17) | I17: =G17-$B$8 | J17: =G17-$B$7 | Q17: Total cost | R17: Total logistics cost | S17: Tổng chi phí logistics phát sinh từ phương án air/sea cho PCBA. | U17: 46140 | V17: 0 | W17: 0 | X17: 0 | Y17: 0 | Z17: 0 | AA17: 0 | AB17: OK
A18: A | B18: 2026 Automatic Robot ver | C18: US | D18: Electronic Toy | E18: 123AB | F18: 15000 | G18: 46157 | H18: =SUMIFS('Demand for Production Plan'!$I:$I,'Demand for Production Plan'!$A:$A,$A18,'Demand for Production Plan'!$C:$C,$C18,'Demand for Production Plan'!$F:$F,$E18,'Demand for Production Plan'!$H:$H,$G18) | I18: =G18-$B$8 | J18: =G18-$B$7 | Q18: Prod(A) | R18: Production quantity of SKU A | S18: Số lượng SKU A được sản xuất trong ngày; cũng là lượng PCBA bị tiêu hao trong ngày nếu 1 sản phẩm dùng 1 PCBA. | U18: 46141 | V18: 0 | W18: 0 | X18: 0 | Y18: 0 | Z18: 0 | AA18: 0 | AB18: OK
A19: A | B19: 2026 Automatic Robot ver | C19: US | D19: Electronic Toy | E19: 123AB | F19: 15000 | G19: 46164 | H19: =SUMIFS('Demand for Production Plan'!$I:$I,'Demand for Production Plan'!$A:$A,$A19,'Demand for Production Plan'!$C:$C,$C19,'Demand for Production Plan'!$F:$F,$E19,'Demand for Production Plan'!$H:$H,$G19) | I19: =G19-$B$8 | J19: =G19-$B$7 | Q19: Air arr | R19: Air arrival | S19: Số lượng PCBA thực nhận trong ngày từ phương án vận chuyển air. | U19: 46142 | V19: 0 | W19: 0 | X19: 0 | Y19: 0 | Z19: 0 | AA19: 0 | AB19: OK
A20: A | B20: 2026 Automatic Robot ver | C20: US | D20: Electronic Toy | E20: 123AB | F20: 15000 | G20: 46171 | H20: =SUMIFS('Demand for Production Plan'!$I:$I,'Demand for Production Plan'!$A:$A,$A20,'Demand for Production Plan'!$C:$C,$C20,'Demand for Production Plan'!$F:$F,$E20,'Demand for Production Plan'!$H:$H,$G20) | I20: =G20-$B$8 | J20: =G20-$B$7 | Q20: Sea arr | R20: Sea arrival | S20: Số lượng PCBA thực nhận trong ngày từ phương án vận chuyển sea. | U20: 46143 | V20: 0 | W20: 0 | X20: 0 | Y20: 0 | Z20: 0 | AA20: 0 | AB20: OK
A21: B | B21: 2025 Barbie ver colorful | C21: US | D21: Doll | E21: 123AB | F21: 15000 | G21: 46157 | H21: =SUMIFS('Demand for Production Plan'!$I:$I,'Demand for Production Plan'!$A:$A,$A21,'Demand for Production Plan'!$C:$C,$C21,'Demand for Production Plan'!$F:$F,$E21,'Demand for Production Plan'!$H:$H,$G21) | I21: =G21-$B$8 | J21: =G21-$B$7 | Q21: Reflash arr | R21: Reflash arrival / recovered usable PCBA arrival | S21: Số lượng PCBA bổ sung trong ngày từ nguồn reflash/rework/phục hồi nội bộ. | U21: 46144 | V21: 2500 | W21: 2500 | X21: 0 | Y21: 0 | Z21: 0 | AA21: 0 | AB21: OK
A22: B | B22: 2025 Barbie ver colorful | C22: US | D22: Doll | E22: 123AB | F22: 15000 | G22: 46164 | H22: =SUMIFS('Demand for Production Plan'!$I:$I,'Demand for Production Plan'!$A:$A,$A22,'Demand for Production Plan'!$C:$C,$C22,'Demand for Production Plan'!$F:$F,$E22,'Demand for Production Plan'!$H:$H,$G22) | I22: =G22-$B$8 | J22: =G22-$B$7 | Q22: Beg Inv | R22: Beginning Inventory | S22: Tồn kho đầu ngày của PCBA. | U22: 46146 | V22: 1998 | W22: 1998 | X22: 0 | Y22: 0 | Z22: 0 | AA22: 0 | AB22: OK
A23: B | B23: 2025 Barbie ver colorful | C23: US | D23: Doll | E23: 123AB | F23: 15000 | G23: 46171 | H23: =SUMIFS('Demand for Production Plan'!$I:$I,'Demand for Production Plan'!$A:$A,$A23,'Demand for Production Plan'!$C:$C,$C23,'Demand for Production Plan'!$F:$F,$E23,'Demand for Production Plan'!$H:$H,$G23) | I23: =G23-$B$8 | J23: =G23-$B$7 | Q23: End Inv | R23: Ending Inventory | S23: Tồn kho cuối ngày của PCBA sau khi cộng arrival và trừ lượng dùng cho sản xuất. | U23: 46147 | V23: 0 | W23: 0 | X23: 0 | Y23: 0 | Z23: 0 | AA23: 0 | AB23: OK
A24: C | B24: 2026 Castle & Farm Blocks | C24: UK | D24: Building & Construction Toy | E24: 456CD | F24: 5000 | G24: 46157 | H24: =SUMIFS('Demand for Production Plan'!$I:$I,'Demand for Production Plan'!$A:$A,$A24,'Demand for Production Plan'!$C:$C,$C24,'Demand for Production Plan'!$F:$F,$E24,'Demand for Production Plan'!$H:$H,$G24) | I24: =G24-$B$8 | J24: =G24-$B$7 | Q24: Inv | R24: Inventory | S24: Tồn kho. | U24: 46148 | V24: 2500 | W24: 0 | X24: 0 | Y24: 4000 | Z24: 0 | AA24: 1500 | AB24: OK
A25: C | B25: 2026 Castle & Farm Blocks | C25: UK | D25: Building & Construction Toy | E25: 456CD | F25: 5000 | G25: 46164 | H25: =SUMIFS('Demand for Production Plan'!$I:$I,'Demand for Production Plan'!$A:$A,$A25,'Demand for Production Plan'!$C:$C,$C25,'Demand for Production Plan'!$F:$F,$E25,'Demand for Production Plan'!$H:$H,$G25) | I25: =G25-$B$8 | J25: =G25-$B$7 | Q25: Flag | R25: Status flag | S25: Cờ cảnh báo tình trạng tồn kho trong ngày. | U25: 46149 | V25: 2500 | W25: 0 | X25: 0 | Y25: 4000 | Z25: 1500 | AA25: 3000 | AB25: OK
A26: C | B26: 2026 Castle & Farm Blocks | C26: UK | D26: Building & Construction Toy | E26: 456CD | F26: 5000 | G26: 46171 | H26: =SUMIFS('Demand for Production Plan'!$I:$I,'Demand for Production Plan'!$A:$A,$A26,'Demand for Production Plan'!$C:$C,$C26,'Demand for Production Plan'!$F:$F,$E26,'Demand for Production Plan'!$H:$H,$G26) | I26: =G26-$B$8 | J26: =G26-$B$7 | Q26: OK | R26: OK / Inventory feasible | S26: Tồn kho không âm, ngày đó khả thi về mặt vật tư. | U26: 46150 | V26: 2500 | W26: 0 | X26: 0 | Y26: 4000 | Z26: 3000 | AA26: 4500 | AB26: OK
A27: D | B27: 2026 Animal Animation Book | C27: UK | D27: Educational Toy | E27: 456CD | F27: 5000 | G27: 46157 | H27: =SUMIFS('Demand for Production Plan'!$I:$I,'Demand for Production Plan'!$A:$A,$A27,'Demand for Production Plan'!$C:$C,$C27,'Demand for Production Plan'!$F:$F,$E27,'Demand for Production Plan'!$H:$H,$G27) | I27: =G27-$B$8 | J27: =G27-$B$7 | Q27: NEG_INV | R27: Negative Inventory | S27: Tồn kho âm, nghĩa là kế hoạch sản xuất ngày đó không khả thi nếu không có thêm PCBA. | U27: 46151 | V27: 2500 | W27: 0 | X27: 0 | Y27: 4000 | Z27: 4500 | AA27: 6000 | AB27: OK
A28: D | B28: 2026 Animal Animation Book | C28: UK | D28: Educational Toy | E28: 456CD | F28: 5000 | G28: 46164 | H28: =SUMIFS('Demand for Production Plan'!$I:$I,'Demand for Production Plan'!$A:$A,$A28,'Demand for Production Plan'!$C:$C,$C28,'Demand for Production Plan'!$F:$F,$E28,'Demand for Production Plan'!$H:$H,$G28) | I28: =G28-$B$8 | J28: =G28-$B$7 | Q28: units | R28: Units / quantity | S28: Số đơn vị, số lượng. | U28: 46153 | V28: 2500 | W28: 0 | X28: 0 | Y28: 4000 | Z28: 6000 | AA28: 7500 | AB28: OK
A29: D | B29: 2026 Animal Animation Book | C29: UK | D29: Educational Toy | E29: 456CD | F29: 5000 | G29: 46171 | H29: =SUMIFS('Demand for Production Plan'!$I:$I,'Demand for Production Plan'!$A:$A,$A29,'Demand for Production Plan'!$C:$C,$C29,'Demand for Production Plan'!$F:$F,$E29,'Demand for Production Plan'!$H:$H,$G29) | I29: =G29-$B$8 | J29: =G29-$B$7 | Q29: pc | R29: piece | S29: Một đơn vị/cái. | U29: 46154 | V29: 2500 | W29: 0 | X29: 0 | Y29: 4000 | Z29: 7500 | AA29: 9000 | AB29: OK
A30: E | B30: 2026 Scooter ver | C30: Australia | D30: Outdoor & Sports Toy | E30: 789EF | F30: 3000 | G30: 46150 | H30: =SUMIFS('Demand for Production Plan'!$I:$I,'Demand for Production Plan'!$A:$A,$A30,'Demand for Production Plan'!$C:$C,$C30,'Demand for Production Plan'!$F:$F,$E30,'Demand for Production Plan'!$H:$H,$G30) | I30: =G30-$B$8 | J30: =G30-$B$7 | U30: 46155 | V30: 2500 | W30: 0 | X30: 0 | Y30: 4000 | Z30: 9000 | AA30: 10500 | AB30: OK
A31: E | B31: 2026 Scooter ver | C31: Australia | D31: Outdoor & Sports Toy | E31: 789EF | F31: 3000 | G31: 46157 | H31: =SUMIFS('Demand for Production Plan'!$I:$I,'Demand for Production Plan'!$A:$A,$A31,'Demand for Production Plan'!$C:$C,$C31,'Demand for Production Plan'!$F:$F,$E31,'Demand for Production Plan'!$H:$H,$G31) | I31: =G31-$B$8 | J31: =G31-$B$7 | U31: 46156 | V31: 2500 | W31: 0 | X31: 0 | Y31: 2000 | Z31: 10500 | AA31: 10000 | AB31: OK
A32: E | B32: 2026 Scooter ver | C32: Australia | D32: Outdoor & Sports Toy | E32: 789EF | F32: 3000 | G32: 46164 | H32: =SUMIFS('Demand for Production Plan'!$I:$I,'Demand for Production Plan'!$A:$A,$A32,'Demand for Production Plan'!$C:$C,$C32,'Demand for Production Plan'!$F:$F,$E32,'Demand for Production Plan'!$H:$H,$G32) | I32: =G32-$B$8 | J32: =G32-$B$7 | U32: 46157 | V32: 2500 | W32: 0 | X32: 0 | Y32: 0 | Z32: 10000 | AA32: 7500 | AB32: OK
A33: F | B33: 2025 Fantasy Spaceship Model DIY kits | C33: US | D33: Arts & Crafts Toy | E33: 789EF | F33: 3000 | G33: 46143 | H33: =SUMIFS('Demand for Production Plan'!$I:$I,'Demand for Production Plan'!$A:$A,$A33,'Demand for Production Plan'!$C:$C,$C33,'Demand for Production Plan'!$F:$F,$E33,'Demand for Production Plan'!$H:$H,$G33) | I33: =G33-$B$8 | J33: =G33-$B$7
A34: F | B34: 2025 Fantasy Spaceship Model DIY kits | C34: US | D34: Arts & Crafts Toy | E34: 789EF | F34: 3000 | G34: 46150 | H34: =SUMIFS('Demand for Production Plan'!$I:$I,'Demand for Production Plan'!$A:$A,$A34,'Demand for Production Plan'!$C:$C,$C34,'Demand for Production Plan'!$F:$F,$E34,'Demand for Production Plan'!$H:$H,$G34) | I34: =G34-$B$8 | J34: =G34-$B$7
A35: F | B35: 2025 Fantasy Spaceship Model DIY kits | C35: US | D35: Arts & Crafts Toy | E35: 789EF | F35: 3000 | G35: 46157 | H35: =SUMIFS('Demand for Production Plan'!$I:$I,'Demand for Production Plan'!$A:$A,$A35,'Demand for Production Plan'!$C:$C,$C35,'Demand for Production Plan'!$F:$F,$E35,'Demand for Production Plan'!$H:$H,$G35) | I35: =G35-$B$8 | J35: =G35-$B$7
A36: F | B36: 2025 Fantasy Spaceship Model DIY kits | C36: US | D36: Arts & Crafts Toy | E36: 789EF | F36: 3000 | G36: 46164 | H36: =SUMIFS('Demand for Production Plan'!$I:$I,'Demand for Production Plan'!$A:$A,$A36,'Demand for Production Plan'!$C:$C,$C36,'Demand for Production Plan'!$F:$F,$E36,'Demand for Production Plan'!$H:$H,$G36) | I36: =G36-$B$8 | J36: =G36-$B$7
A37: F | B37: 2025 Fantasy Spaceship Model DIY kits | C37: US | D37: Arts & Crafts Toy | E37: 789EF | F37: 3000 | G37: 46171 | H37: =SUMIFS('Demand for Production Plan'!$I:$I,'Demand for Production Plan'!$A:$A,$A37,'Demand for Production Plan'!$C:$C,$C37,'Demand for Production Plan'!$F:$F,$E37,'Demand for Production Plan'!$H:$H,$G37) | I37: =G37-$B$8 | J37: =G37-$B$7
A39: Production Plan (Daily workday view)
A41: SKU | B41: Description | C41: Market | D41: Product group | E41: Fixture | F41: Weekly cap | G41: Ship request | H41: Demand quantity | I41: Earliest production date | J41: Latest production date | K41: Week 1 | O41: Week 2 | U41: Week 3 | AA41: Week 4 | AG41: Week 5 | AL41: Planned total | AM41: Shortage | AN41: Risk | AO41: Late quantity | AP41: Horizon status
K42: 46127 | L42: 46128 | M42: 46129 | N42: 46130 | O42: 46132 | P42: 46133 | Q42: 46134 | R42: 46135 | S42: 46136 | T42: 46137 | U42: 46139 | V42: 46140 | W42: 46141 | X42: 46142 | Y42: 46143 | Z42: 46144 | AA42: 46146 | AB42: 46147 | AC42: 46148 | AD42: 46149 | AE42: 46150 | AF42: 46151 | AG42: 46153 | AH42: 46154 | AI42: 46155 | AJ42: 46156 | AK42: 46157
...
