Workbook
Name Type: #REF!

Sheet Overall Case Study
C2: Context
C3: A toy company is facing troubles with planning and data visualization
C5: Problems:
C6: 1. Need to visualize master data
C7: 2. Need to balance demand & create master production scheduling (MPS) with inhouse capacity constraints
C8: 3. Need to create material requirement planning (MRP) then determine reorder point based on leadtime (LT)
B13: No | C13: Question | D13: Requirement
B14: 1 | C14: Visualize demand of 6 SKUs | D14: By Regions, Category, Total Value
B15: 2 | C15: Create master production scheduling (MPS) | D15: Generate a master production planning for whole year
B16: 3 | C16: Balance demand | D16: Based on current fixture set and weekly capacity to balance and suggest solution if over 1. Leverage demand 2. Buy more fixture
B17: 4 | C17: Create Material requirment Planning (MRP) | D17: Generate a material requirement planning following 6 SKUs' demand and BOM usage
B18: 5 | C18: Determine supply plan | D18: Based on leadtime, current stock on hand and pending PO to find out reorder point and fill out/ layout supply plan
B19: 6 | C19: Figure out safety stock strategy | D19: Based on vendor location to define stock on hand level by week or day or hour (local and oversea)

Sheet Sheet1
A1: Item name | B1: Des | C1: Market | D1: Price ($) | E1: Product group | F1: Fixture | G1: Weekly Capcity | H1: Shipment Request | I1: Demand Quantity | J1: week first day | K1: production day | L1: Total Demand by SKU-Week
A2: A | B2: 2026 Automatic Robot ver | C2: US | D2: 105 | E2: Electronic Toy | F2: 123AB | G2: 15000 | H2: 46150 | I2: 684 | J2: =$M$1+7*INT((H2-$M$1)/7) -> 46144 | K2: =Table14[[#This Row],[week first day]]-7 -> 46137 | L2: =SUMIFS($I:$I,$A:$A,A2,J:J,J2) -> 684
A3: A | B3: 2026 Automatic Robot ver | C3: US | D3: 105 | E3: Electronic Toy | F3: 123AB | G3: 15000 | H3: 46157 | I3: 20000 | J3: =$M$1+7*INT((H3-$M$1)/7) -> 46151 | K3: =Table14[[#This Row],[week first day]]-7 -> 46144 | L3: =SUMIFS($I:$I,$A:$A,A3,J:J,J3) -> 20000
A4: A | B4: 2026 Automatic Robot ver | C4: US | D4: 105 | E4: Electronic Toy | F4: 123AB | G4: 15000 | H4: 46164 | I4: 15000 | J4: =$M$1+7*INT((H4-$M$1)/7) -> 46158 | K4: =Table14[[#This Row],[week first day]]-7 -> 46151 | L4: =SUMIFS($I:$I,$A:$A,A4,J:J,J4) -> 20000
A5: A | B5: 2026 Automatic Robot ver | C5: US | D5: 105 | E5: Electronic Toy | F5: 123AB | G5: 15000 | H5: 46164 | I5: 5000 | J5: =$M$1+7*INT((H5-$M$1)/7) -> 46158 | K5: =Table14[[#This Row],[week first day]]-7 -> 46151 | L5: =SUMIFS($I:$I,$A:$A,A5,J:J,J5) -> 20000
A6: A | B6: 2026 Automatic Robot ver | C6: US | D6: 105 | E6: Electronic Toy | F6: 123AB | G6: 15000 | H6: 46171 | I6: 11000 | J6: =$M$1+7*INT((H6-$M$1)/7) -> 46165 | K6: =Table14[[#This Row],[week first day]]-7 -> 46158 | L6: =SUMIFS($I:$I,$A:$A,A6,J:J,J6) -> 11000
A7: A | B7: 2026 Automatic Robot ver | C7: US | D7: 105 | E7: Electronic Toy | F7: 123AB | G7: 15000 | H7: 46178 | I7: 13000 | J7: =$M$1+7*INT((H7-$M$1)/7) -> 46172 | K7: =Table14[[#This Row],[week first day]]-7 -> 46165 | L7: =SUMIFS($I:$I,$A:$A,A7,J:J,J7) -> 13000
A8: A | B8: 2026 Automatic Robot ver | C8: US | D8: 105 | E8: Electronic Toy | F8: 123AB | G8: 15000 | H8: 46185 | I8: 13773 | J8: =$M$1+7*INT((H8-$M$1)/7) -> 46179 | K8: =Table14[[#This Row],[week first day]]-7 -> 46172 | L8: =SUMIFS($I:$I,$A:$A,A8,J:J,J8) -> 13773
A9: A | B9: 2026 Automatic Robot ver | C9: US | D9: 105 | E9: Electronic Toy | F9: 123AB | G9: 15000 | H9: 46192 | I9: 7058 | J9: =$M$1+7*INT((H9-$M$1)/7) -> 46186 | K9: =Table14[[#This Row],[week first day]]-7 -> 46179 | L9: =SUMIFS($I:$I,$A:$A,A9,J:J,J9) -> 7058
A10: A | B10: 2026 Automatic Robot ver | C10: US | D10: 105 | E10: Electronic Toy | F10: 123AB | G10: 15000 | H10: 46199 | I10: 2040 | J10: =$M$1+7*INT((H10-$M$1)/7) -> 46193 | K10: =Table14[[#This Row],[week first day]]-7 -> 46186 | L10: =SUMIFS($I:$I,$A:$A,A10,J:J,J10) -> 2040
A11: A | B11: 2026 Automatic Robot ver | C11: US | D11: 105 | E11: Electronic Toy | F11: 123AB | G11: 15000 | H11: 46206 | I11: 1500 | J11: =$M$1+7*INT((H11-$M$1)/7) -> 46200 | K11: =Table14[[#This Row],[week first day]]-7 -> 46193 | L11: =SUMIFS($I:$I,$A:$A,A11,J:J,J11) -> 3541
A12: A | B12: 2026 Automatic Robot ver | C12: US | D12: 105 | E12: Electronic Toy | F12: 123AB | G12: 15000 | H12: 46206 | I12: 2041 | J12: =$M$1+7*INT((H12-$M$1)/7) -> 46200 | K12: =Table14[[#This Row],[week first day]]-7 -> 46193 | L12: =SUMIFS($I:$I,$A:$A,A12,J:J,J12) -> 3541
A13: A | B13: 2026 Automatic Robot ver | C13: US | D13: 105 | E13: Electronic Toy | F13: 123AB | G13: 15000 | H13: 46213 | I13: 2041 | J13: =$M$1+7*INT((H13-$M$1)/7) -> 46207 | K13: =Table14[[#This Row],[week first day]]-7 -> 46200 | L13: =SUMIFS($I:$I,$A:$A,A13,J:J,J13) -> 12041
... A466: F | B466: 2025 Fantasy Spaceship Model DIY kits | C466: US | D466: 90 | E466: Arts & Crafts Toy | F466: 789EF | G466: 3000 | H466: 46381 | I466: 1928 | J466: =$M$1+7*INT((H466-$M$1)/7) -> 46375 | K466: =Table14[[#This Row],[week first day]]-7 -> 46368 | L466: =SUMIFS($I:$I,$A:$A,A466,J:J,J466) -> 1928

Sheet Demand
A1: Item name | B1: Des | C1: Market | D1: Price ($) | E1: Product group | F1: Fixture | G1: Weekly Capcity | H1: Shipment Request | I1: Demand Quantity
A2: F | B2: 2025 Fantasy Spaceship Model DIY kits | C2: US | D2: 90 | E2: Arts & Crafts Toy | F2: 789EF | G2: 3000 | H2: 46143 | I2: 588
A3: A | B3: 2026 Automatic Robot ver | C3: US | D3: 105 | E3: Electronic Toy | F3: 123AB | G3: 15000 | H3: 46150 | I3: 684
A4: E | B4: 2026 Scooter ver | C4: Australia | D4: 30 | E4: Outdoor & Sports Toy | F4: 789EF | G4: 3000 | H4: 46150 | I4: 472
A5: F | B5: 2025 Fantasy Spaceship Model DIY kits | C5: US | D5: 90 | E5: Arts & Crafts Toy | F5: 789EF | G5: 3000 | H5: 46150 | I5: 4028
A6: A | B6: 2026 Automatic Robot ver | C6: US | D6: 105 | E6: Electronic Toy | F6: 123AB | G6: 15000 | H6: 46157 | I6: 20000
A7: B | B7: 2025 Barbie ver colorful | C7: US | D7: 55 | E7: Doll | F7: 123AB | G7: 15000 | H7: 46157 | I7: 2731
A8: B | B8: 2025 Barbie ver colorful | C8: US | D8: 55 | E8: Doll | F8: 123AB | G8: 15000 | H8: 46157 | I8: 2771
A9: C | B9: 2026 Castle & Farm Blocks | C9: UK | D9: 80 | E9: Building & Construction Toy | F9: 456CD | G9: 5000 | H9: 46157 | I9: 270
A10: C | B10: 2026 Castle & Farm Blocks | C10: UK | D10: 80 | E10: Building & Construction Toy | F10: 456CD | G10: 5000 | H10: 46157 | I10: 270
A11: C | B11: 2026 Castle & Farm Blocks | C11: UK | D11: 80 | E11: Building & Construction Toy | F11: 456CD | G11: 5000 | H11: 46157 | I11: 270
A12: C | B12: 2026 Castle & Farm Blocks | C12: UK | D12: 80 | E12: Building & Construction Toy | F12: 456CD | G12: 5000 | H12: 46157 | I12: 270
A13: C | B13: 2026 Castle & Farm Blocks | C13: UK | D13: 80 | E13: Building & Construction Toy | F13: 456CD | G13: 5000 | H13: 46157 | I13: 270
... A466: F | B466: 2025 Fantasy Spaceship Model DIY kits | C466: US | D466: 90 | E466: Arts & Crafts Toy | F466: 789EF | G466: 3000 | H466: 46381 | I466: 1928

Sheet weekly_demand
A1: Item name | B1: market | C1: week first day | D1: Total Demand by SKU-Week | E1: carton | F1: volume
A2: {=_xlfn.UNIQUE(_xlfn.CHOOSECOLS(Sheet1!A2:L466,1,3,11,12))} -> A | B2: US | C2: 46137 | D2: 684 | E2: =ROUNDUP(D2/_xlfn.XLOOKUP(A2,$J$3:$J$8,$L$3:$L$8),0) -> 171 | F2: =E2/100*_xlfn.XLOOKUP(A2,$J$3:$J$8,$M$3:$M$8) -> 1.71 | J2: Item name | K2: Des | L2: Packing size (pcs/ carton) | M2: CBM (100 cartons)
A3: A | B3: US | C3: 46144 | D3: 20000 | E3: =ROUNDUP(D3/_xlfn.XLOOKUP(A3,$J$3:$J$8,$L$3:$L$8),0) -> 5000 | F3: =E3/100*_xlfn.XLOOKUP(A3,$J$3:$J$8,$M$3:$M$8) -> 50 | J3: A | K3: 2026 Automatic Robot ver | L3: 4 | M3: 1
A4: A | B4: US | C4: 46151 | D4: 20000 | E4: =ROUNDUP(D4/_xlfn.XLOOKUP(A4,$J$3:$J$8,$L$3:$L$8),0) -> 5000 | F4: =E4/100*_xlfn.XLOOKUP(A4,$J$3:$J$8,$M$3:$M$8) -> 50 | J4: B | K4: 2025 Barbie ver colorful | L4: 4 | M4: 0.625
A5: A | B5: US | C5: 46158 | D5: 11000 | E5: =ROUNDUP(D5/_xlfn.XLOOKUP(A5,$J$3:$J$8,$L$3:$L$8),0) -> 2750 | F5: =E5/100*_xlfn.XLOOKUP(A5,$J$3:$J$8,$M$3:$M$8) -> 27.5 | J5: C | K5: 2026 Castle & Farm Blocks | L5: 2 | M5: 1
A6: A | B6: US | C6: 46165 | D6: 13000 | E6: =ROUNDUP(D6/_xlfn.XLOOKUP(A6,$J$3:$J$8,$L$3:$L$8),0) -> 3250 | F6: =E6/100*_xlfn.XLOOKUP(A6,$J$3:$J$8,$M$3:$M$8) -> 32.5 | J6: D | K6: 2026 Animal Animation Book | L6: 4 | M6: 0.625
A7: A | B7: US | C7: 46172 | D7: 13773 | E7: =ROUNDUP(D7/_xlfn.XLOOKUP(A7,$J$3:$J$8,$L$3:$L$8),0) -> 3444 | F7: =E7/100*_xlfn.XLOOKUP(A7,$J$3:$J$8,$M$3:$M$8) -> 34.44 | J7: E | K7: 2026 Scooter ver | L7: 2 | M7: 0.625
A8: A | B8: US | C8: 46179 | D8: 7058 | E8: =ROUNDUP(D8/_xlfn.XLOOKUP(A8,$J$3:$J$8,$L$3:$L$8),0) -> 1765 | F8: =E8/100*_xlfn.XLOOKUP(A8,$J$3:$J$8,$M$3:$M$8) -> 17.65 | J8: F | K8: 2025 Fantasy Spaceship Model DIY kits | L8: 8 | M8: 0.78125
A9: A | B9: US | C9: 46186 | D9: 2040 | E9: =ROUNDUP(D9/_xlfn.XLOOKUP(A9,$J$3:$J$8,$L$3:$L$8),0) -> 510 | F9: =E9/100*_xlfn.XLOOKUP(A9,$J$3:$J$8,$M$3:$M$8) -> 5.1
A10: A | B10: US | C10: 46193 | D10: 3541 | E10: =ROUNDUP(D10/_xlfn.XLOOKUP(A10,$J$3:$J$8,$L$3:$L$8),0) -> 886 | F10: =E10/100*_xlfn.XLOOKUP(A10,$J$3:$J$8,$M$3:$M$8) -> 8.86
A11: A | B11: US | C11: 46200 | D11: 12041 | E11: =ROUNDUP(D11/_xlfn.XLOOKUP(A11,$J$3:$J$8,$L$3:$L$8),0) -> 3011 | F11: =E11/100*_xlfn.XLOOKUP(A11,$J$3:$J$8,$M$3:$M$8) -> 30.11
A12: A | B12: US | C12: 46207 | D12: 12040 | E12: =ROUNDUP(D12/_xlfn.XLOOKUP(A12,$J$3:$J$8,$L$3:$L$8),0) -> 3010 | F12: =E12/100*_xlfn.XLOOKUP(A12,$J$3:$J$8,$M$3:$M$8) -> 30.1
A13: A | B13: US | C13: 46228 | D13: 27760 | E13: =ROUNDUP(D13/_xlfn.XLOOKUP(A13,$J$3:$J$8,$L$3:$L$8),0) -> 6940 | F13: =E13/100*_xlfn.XLOOKUP(A13,$J$3:$J$8,$M$3:$M$8) -> 69.4
A14: A | B14: US | C14: 46235 | D14: 26486 | E14: =ROUNDUP(D14/_xlfn.XLOOKUP(A14,$J$3:$J$8,$L$3:$L$8),0) -> 6622 | F14: =E14/100*_xlfn.XLOOKUP(A14,$J$3:$J$8,$M$3:$M$8) -> 66.22
A15: A | B15: US | C15: 46242 | D15: 4248 | E15: =ROUNDUP(D15/_xlfn.XLOOKUP(A15,$J$3:$J$8,$L$3:$L$8),0) -> 1062 | F15: =E15/100*_xlfn.XLOOKUP(A15,$J$3:$J$8,$M$3:$M$8) -> 10.62
A16: A | B16: US | C16: 46249 | D16: 4248 | E16: =ROUNDUP(D16/_xlfn.XLOOKUP(A16,$J$3:$J$8,$L$3:$L$8),0) -> 1062 | F16: =E16/100*_xlfn.XLOOKUP(A16,$J$3:$J$8,$M$3:$M$8) -> 10.62
A17: A | B17: US | C17: 46256 | D17: 4249 | E17: =ROUNDUP(D17/_xlfn.XLOOKUP(A17,$J$3:$J$8,$L$3:$L$8),0) -> 1063 | F17: =E17/100*_xlfn.XLOOKUP(A17,$J$3:$J$8,$M$3:$M$8) -> 10.63
A18: A | B18: US | C18: 46263 | D18: 4248 | E18: =ROUNDUP(D18/_xlfn.XLOOKUP(A18,$J$3:$J$8,$L$3:$L$8),0) -> 1062 | F18: =E18/100*_xlfn.XLOOKUP(A18,$J$3:$J$8,$M$3:$M$8) -> 10.62
A19: A | B19: US | C19: 46270 | D19: 2391 | E19: =ROUNDUP(D19/_xlfn.XLOOKUP(A19,$J$3:$J$8,$L$3:$L$8),0) -> 598 | F19: =E19/100*_xlfn.XLOOKUP(A19,$J$3:$J$8,$M$3:$M$8) -> 5.98
A20: A | B20: US | C20: 46277 | D20: 2392 | E20: =ROUNDUP(D20/_xlfn.XLOOKUP(A20,$J$3:$J$8,$L$3:$L$8),0) -> 598 | F20: =E20/100*_xlfn.XLOOKUP(A20,$J$3:$J$8,$M$3:$M$8) -> 5.98
... A172: F | B172: US | C172: 46368 | D172: 1928 | E172: =ROUNDUP(D172/_xlfn.XLOOKUP(A172,$J$3:$J$8,$L$3:$L$8),0) -> 241 | F172: =E172/100*_xlfn.XLOOKUP(A172,$J$3:$J$8,$M$3:$M$8) -> 1.8828125

Sheet MPS
A1: SKU | B1: Fixture | C1: Week | D1: Weekly Capacity | E1: Total Demand | F1: Beginning FG Inv | G1: Carryover Needed | H1: Net Required | I1: Planned Production | J1: Ending FG Inv | K1: Shortage | L1: ATP | M1: Capacity Load % | N1: Planner Note | P1: Logic
A2: {=_xlfn.UNIQUE(_xlfn.CHOOSECOLS(Sheet1!A2:L466,1,6,11,7,12))} -> A | B2: 123AB | C2: 46137 | D2: 15000 | E2: 684 | F2: =IF($A2="","",IF($A2<>$A1,IFERROR(INDEX([1]FG_Begin_Inventory!$B:$B,MATCH($A2,[1]FG_Begin_Inventory!$A:$A,0)),0),J1)) -> 0 | G2: =IF($A2="","",IF($A2<>$A3,0,MAX(0,G3+E3-D3))) -> 10000 | H2: =IF($A2="","",MAX(0,E2+G2-F2)) -> 10684 | I2: =IF($A2="","",MIN(D2,H2)) -> 10684 | J2: =IF($A2="","",MAX(0,F2+I2-E2)) -> 10000 | K2: =IF($A2="","",MAX(0,E2-F2-I2)) -> 0 | L2: =IF($A2="","",MAX(0,F2+I2-E2)) -> 10000 | M2: =IF($A2="","",IFERROR(I2/D2,0)) -> 0.71226667 | P2: Carryover Needed = lượng tồn phải build trước để cover tuần sau bị quá tải.
A3: A | B3: 123AB | C3: 46144 | D3: 15000 | E3: 20000 | F3: =IF($A3="","",IF($A3<>$A2,IFERROR(INDEX([1]FG_Begin_Inventory!$B:$B,MATCH($A3,[1]FG_Begin_Inventory!$A:$A,0)),0),J2)) -> 10000 | G3: =IF($A3="","",IF($A3<>$A4,0,MAX(0,G4+E4-D4))) -> 5000 | H3: =IF($A3="","",MAX(0,E3+G3-F3)) -> 15000 | I3: =IF($A3="","",MIN(D3,H3)) -> 15000 | J3: =IF($A3="","",MAX(0,F3+I3-E3)) -> 5000 | K3: =IF($A3="","",MAX(0,E3-F3-I3)) -> 0 | L3: =IF($A3="","",MAX(0,F3+I3-E3)) -> 5000 | M3: =IF($A3="","",IFERROR(I3/D3,0)) -> 1 | P3: Nếu Fixture_Capacity_Input có dữ liệu cho fixture-week, MPS sẽ dùng capacity đó.
A4: A | B4: 123AB | C4: 46151 | D4: 15000 | E4: 20000 | F4: =IF($A4="","",IF($A4<>$A3,IFERROR(INDEX([1]FG_Begin_Inventory!$B:$B,MATCH($A4,[1]FG_Begin_Inventory!$A:$A,0)),0),J3)) -> 5000 | G4: =IF($A4="","",IF($A4<>$A5,0,MAX(0,G5+E5-D5))) -> 0 | H4: =IF($A4="","",MAX(0,E4+G4-F4)) -> 15000 | I4: =IF($A4="","",MIN(D4,H4)) -> 15000 | J4: =IF($A4="","",MAX(0,F4+I4-E4)) -> 0 | K4: =IF($A4="","",MAX(0,E4-F4-I4)) -> 0 | L4: =IF($A4="","",MAX(0,F4+I4-E4)) -> 0 | M4: =IF($A4="","",IFERROR(I4/D4,0)) -> 1 | P4: Nếu Fixture_Capacity_Input trống, MPS dùng Weekly Capacity từ weekly_demand.
A5: A | B5: 123AB | C5: 46158 | D5: 15000 | E5: 11000 | F5: =IF($A5="","",IF($A5<>$A4,IFERROR(INDEX([1]FG_Begin_Inventory!$B:$B,MATCH($A5,[1]FG_Begin_Inventory!$A:$A,0)),0),J4)) -> 0 | G5: =IF($A5="","",IF($A5<>$A6,0,MAX(0,G6+E6-D6))) -> 0 | H5: =IF($A5="","",MAX(0,E5+G5-F5)) -> 11000 | I5: =IF($A5="","",MIN(D5,H5)) -> 11000 | J5: =IF($A5="","",MAX(0,F5+I5-E5)) -> 0 | K5: =IF($A5="","",MAX(0,E5-F5-I5)) -> 0 | L5: =IF($A5="","",MAX(0,F5+I5-E5)) -> 0 | M5: =IF($A5="","",IFERROR(I5/D5,0)) -> 0.73333333
A6: A | B6: 123AB | C6: 46165 | D6: 15000 | E6: 13000 | F6: =IF($A6="","",IF($A6<>$A5,IFERROR(INDEX([1]FG_Begin_Inventory!$B:$B,MATCH($A6,[1]FG_Begin_Inventory!$A:$A,0)),0),J5)) -> 0 | G6: =IF($A6="","",IF($A6<>$A7,0,MAX(0,G7+E7-D7))) -> 0 | H6: =IF($A6="","",MAX(0,E6+G6-F6)) -> 13000 | I6: =IF($A6="","",MIN(D6,H6)) -> 13000 | J6: =IF($A6="","",MAX(0,F6+I6-E6)) -> 0 | K6: =IF($A6="","",MAX(0,E6-F6-I6)) -> 0 | L6: =IF($A6="","",MAX(0,F6+I6-E6)) -> 0 | M6: =IF($A6="","",IFERROR(I6/D6,0)) -> 0.86666667
A7: A | B7: 123AB | C7: 46172 | D7: 15000 | E7: 13773 | F7: =IF($A7="","",IF($A7<>$A6,IFERROR(INDEX([1]FG_Begin_Inventory!$B:$B,MATCH($A7,[1]FG_Begin_Inventory!$A:$A,0)),0),J6)) -> 0 | G7: =IF($A7="","",IF($A7<>$A8,0,MAX(0,G8+E8-D8))) -> 0 | H7: =IF($A7="","",MAX(0,E7+G7-F7)) -> 13773 | I7: =IF($A7="","",MIN(D7,H7)) -> 13773 | J7: =IF($A7="","",MAX(0,F7+I7-E7)) -> 0 | K7: =IF($A7="","",MAX(0,E7-F7-I7)) -> 0 | L7: =IF($A7="","",MAX(0,F7+I7-E7)) -> 0 | M7: =IF($A7="","",IFERROR(I7/D7,0)) -> 0.9182
A8: A | B8: 123AB | C8: 46179 | D8: 15000 | E8: 7058 | F8: =IF($A8="","",IF($A8<>$A7,IFERROR(INDEX([1]FG_Begin_Inventory!$B:$B,MATCH($A8,[1]FG_Begin_Inventory!$A:$A,0)),0),J7)) -> 0 | G8: =IF($A8="","",IF($A8<>$A9,0,MAX(0,G9+E9-D9))) -> 0 | H8: =IF($A8="","",MAX(0,E8+G8-F8)) -> 7058 | I8: =IF($A8="","",MIN(D8,H8)) -> 7058 | J8: =IF($A8="","",MAX(0,F8+I8-E8)) -> 0 | K8: =IF($A8="","",MAX(0,E8-F8-I8)) -> 0 | L8: =IF($A8="","",MAX(0,F8+I8-E8)) -> 0 | M8: =IF($A8="","",IFERROR(I8/D8,0)) -> 0.47053333
A9: A | B9: 123AB | C9: 46186 | D9: 15000 | E9: 2040 | F9: =IF($A9="","",IF($A9<>$A8,IFERROR(INDEX([1]FG_Begin_Inventory!$B:$B,MATCH($A9,[1]FG_Begin_Inventory!$A:$A,0)),0),J8)) -> 0 | G9: =IF($A9="","",IF($A9<>$A10,0,MAX(0,G10+E10-D10))) -> 6868 | H9: =IF($A9="","",MAX(0,E9+G9-F9)) -> 8908 | I9: =IF($A9="","",MIN(D9,H9)) -> 8908 | J9: =IF($A9="","",MAX(0,F9+I9-E9)) -> 6868 | K9: =IF($A9="","",MAX(0,E9-F9-I9)) -> 0 | L9: =IF($A9="","",MAX(0,F9+I9-E9)) -> 6868 | M9: =IF($A9="","",IFERROR(I9/D9,0)) -> 0.59386667
A10: A | B10: 123AB | C10: 46193 | D10: 15000 | E10: 3541 | F10: =IF($A10="","",IF($A10<>$A9,IFERROR(INDEX([1]FG_Begin_Inventory!$B:$B,MATCH($A10,[1]FG_Begin_Inventory!$A:$A,0)),0),J9)) -> 6868 | G10: =IF($A10="","",IF($A10<>$A11,0,MAX(0,G11+E11-D11))) -> 18327 | H10: =IF($A10="","",MAX(0,E10+G10-F10)) -> 15000 | I10: =IF($A10="","",MIN(D10,H10)) -> 15000 | J10: =IF($A10="","",MAX(0,F10+I10-E10)) -> 18327 | K10: =IF($A10="","",MAX(0,E10-F10-I10)) -> 0 | L10: =IF($A10="","",MAX(0,F10+I10-E10)) -> 18327 | M10: =IF($A10="","",IFERROR(I10/D10,0)) -> 1
A11: A | B11: 123AB | C11: 46200 | D11: 15000 | E11: 12041 | F11: =IF($A11="","",IF($A11<>$A10,IFERROR(INDEX([1]FG_Begin_Inventory!$B:$B,MATCH($A11,[1]FG_Begin_Inventory!$A:$A,0)),0),J10)) -> 18327 | G11: =IF($A11="","",IF($A11<>$A12,0,MAX(0,G12+E12-D12))) -> 21286 | H11: =IF($A11="","",MAX(0,E11+G11-F11)) -> 15000 | I11: =IF($A11="","",MIN(D11,H11)) -> 15000 | J11: =IF($A11="","",MAX(0,F11+I11-E11)) -> 21286 | K11: =IF($A11="","",MAX(0,E11-F11-I11)) -> 0 | L11: =IF($A11="","",MAX(0,F11+I11-E11)) -> 21286 | M11: =IF($A11="","",IFERROR(I11/D11,0)) -> 1
A12: A | B12: 123AB | C12: 46207 | D12: 15000 | E12: 12040 | F12: =IF($A12="","",IF($A12<>$A11,IFERROR(INDEX([1]FG_Begin_Inventory!$B:$B,MATCH($A12,[1]FG_Begin_Inventory!$A:$A,0)),0),J11)) -> 21286 | G12: =IF($A12="","",IF($A12<>$A13,0,MAX(0,G13+E13-D13))) -> 24246 | H12: =IF($A12="","",MAX(0,E12+G12-F12)) -> 15000 | I12: =IF($A12="","",MIN(D12,H12)) -> 15000 | J12: =IF($A12="","",MAX(0,F12+I12-E12)) -> 24246 | K12: =IF($A12="","",MAX(0,E12-F12-I12)) -> 0 | L12: =IF($A12="","",MAX(0,F12+I12-E12)) -> 24246 | M12: =IF($A12="","",IFERROR(I12/D12,0)) -> 1
A13: A | B13: 123AB | C13: 46228 | D13: 15000 | E13: 27760 | F13: =IF($A13="","",IF($A13<>$A12,IFERROR(INDEX([1]FG_Begin_Inventory!$B:$B,MATCH($A13,[1]FG_Begin_Inventory!$A:$A,0)),0),J12)) -> 24246 | G13: =IF($A13="","",IF($A13<>$A14,0,MAX(0,G14+E14-D14))) -> 11486 | H13: =IF($A13="","",MAX(0,E13+G13-F13)) -> 15000 | I13: =IF($A13="","",MIN(D13,H13)) -> 15000 | J13: =IF($A13="","",MAX(0,F13+I13-E13)) -> 11486 | K13: =IF($A13="","",MAX(0,E13-F13-I13)) -> 0 | L13: =IF($A13="","",MAX(0,F13+I13-E13)) -> 11486 | M13: =IF($A13="","",IFERROR(I13/D13,0)) -> 1
A14: A | B14: 123AB | C14: 46235 | D14: 15000 | E14: 26486 | F14: =IF($A14="","",IF($A14<>$A13,IFERROR(INDEX([1]FG_Begin_Inventory!$B:$B,MATCH($A14,[1]FG_Begin_Inventory!$A:$A,0)),0),J13)) -> 11486 | G14: =IF($A14="","",IF($A14<>$A15,0,MAX(0,G15+E15-D15))) -> 0 | H14: =IF($A14="","",MAX(0,E14+G14-F14)) -> 15000 | I14: =IF($A14="","",MIN(D14,H14)) -> 15000 | J14: =IF($A14="","",MAX(0,F14+I14-E14)) -> 0 | K14: =IF($A14="","",MAX(0,E14-F14-I14)) -> 0 | L14: =IF($A14="","",MAX(0,F14+I14-E14)) -> 0 | M14: =IF($A14="","",IFERROR(I14/D14,0)) -> 1
A15: A | B15: 123AB | C15: 46242 | D15: 15000 | E15: 4248 | F15: =IF($A15="","",IF($A15<>$A14,IFERROR(INDEX([1]FG_Begin_Inventory!$B:$B,MATCH($A15,[1]FG_Begin_Inventory!$A:$A,0)),0),J14)) -> 0 | G15: =IF($A15="","",IF($A15<>$A16,0,MAX(0,G16+E16-D16))) -> 0 | H15: =IF($A15="","",MAX(0,E15+G15-F15)) -> 4248 | I15: =IF($A15="","",MIN(D15,H15)) -> 4248 | J15: =IF($A15="","",MAX(0,F15+I15-E15)) -> 0 | K15: =IF($A15="","",MAX(0,E15-F15-I15)) -> 0 | L15: =IF($A15="","",MAX(0,F15+I15-E15)) -> 0 | M15: =IF($A15="","",IFERROR(I15/D15,0)) -> 0.2832
A16: A | B16: 123AB | C16: 46249 | D16: 15000 | E16: 4248 | F16: =IF($A16="","",IF($A16<>$A15,IFERROR(INDEX([1]FG_Begin_Inventory!$B:$B,MATCH($A16,[1]FG_Begin_Inventory!$A:$A,0)),0),J15)) -> 0 | G16: =IF($A16="","",IF($A16<>$A17,0,MAX(0,G17+E17-D17))) -> 0 | H16: =IF($A16="","",MAX(0,E16+G16-F16)) -> 4248 | I16: =IF($A16="","",MIN(D16,H16)) -> 4248 | J16: =IF($A16="","",MAX(0,F16+I16-E16)) -> 0 | K16: =IF($A16="","",MAX(0,E16-F16-I16)) -> 0 | L16: =IF($A16="","",MAX(0,F16+I16-E16)) -> 0 | M16: =IF($A16="","",IFERROR(I16/D16,0)) -> 0.2832
... A172: F | B172: 789EF | C172: 46368 | D172: 3000 | E172: 1928 | F172: =IF($A172="","",IF($A172<>$A171,IFERROR(INDEX([1]FG_Begin_Inventory!$B:$B,MATCH($A172,[1]FG_Begin_Inventory!$A:$A,0)),0),J171)) -> 0 | G172: =IF($A172="","",IF($A172<>$A173,0,MAX(0,G173+E173-D173))) -> 0 | H172: =IF($A172="","",MAX(0,E172+G172-F172)) -> 1928 | I172: =IF($A172="","",MIN(D172,H172)) -> 1928 | J172: =IF($A172="","",MAX(0,F172+I172-E172)) -> 0 | K172: =IF($A172="","",MAX(0,E172-F172-I172)) -> 0 | L172: =IF($A172="","",MAX(0,F172+I172-E172)) -> 0 | M172: =IF($A172="","",IFERROR(I172/D172,0)) -> 0.64266667
F173: =IF($A173="","",IF($A173<>$A172,IFERROR(INDEX([1]FG_Begin_Inventory!$B:$B,MATCH($A173,[1]FG_Begin_Inventory!$A:$A,0)),0),J172)) | G173: =IF($A173="","",IF($A173<>$A174,0,MAX(0,G174+E174-D174))) | H173: =IF($A173="","",MAX(0,E173+G173-F173)) | I173: =IF($A173="","",MIN(D173,H173)) | J173: =IF($A173="","",MAX(0,F173+I173-E173)) | K173: =IF($A173="","",MAX(0,E173-F173-I173)) | L173: =IF($A173="","",MAX(0,F173+I173-E173)) | M173: =IF($A173="","",IFERROR(I173/D173,0))
F174: =IF($A174="","",IF($A174<>$A173,IFERROR(INDEX([1]FG_Begin_Inventory!$B:$B,MATCH($A174,[1]FG_Begin_Inventory!$A:$A,0)),0),J173)) | G174: =IF($A174="","",IF($A174<>$A175,0,MAX(0,G175+E175-D175))) | H174: =IF($A174="","",MAX(0,E174+G174-F174)) | I174: =IF($A174="","",MIN(D174,H174)) | J174: =IF($A174="","",MAX(0,F174+I174-E174)) | K174: =IF($A174="","",MAX(0,E174-F174-I174)) | L174: =IF($A174="","",MAX(0,F174+I174-E174)) | M174: =IF($A174="","",IFERROR(I174/D174,0))
F175: =IF($A175="","",IF($A175<>$A174,IFERROR(INDEX([1]FG_Begin_Inventory!$B:$B,MATCH($A175,[1]FG_Begin_Inventory!$A:$A,0)),0),J174)) | G175: =IF($A175="","",IF($A175<>$A176,0,MAX(0,G176+E176-D176))) | H175: =IF($A175="","",MAX(0,E175+G175-F175)) | I175: =IF($A175="","",MIN(D175,H175)) | J175: =IF($A175="","",MAX(0,F175+I175-E175)) | K175: =IF($A175="","",MAX(0,E175-F175-I175)) | L175: =IF($A175="","",MAX(0,F175+I175-E175)) | M175: =IF($A175="","",IFERROR(I175/D175,0))
F176: =IF($A176="","",IF($A176<>$A175,IFERROR(INDEX([1]FG_Begin_Inventory!$B:$B,MATCH($A176,[1]FG_Begin_Inventory!$A:$A,0)),0),J175)) | G176: =IF($A176="","",IF($A176<>$A177,0,MAX(0,G177+E177-D177))) | H176: =IF($A176="","",MAX(0,E176+G176-F176)) | I176: =IF($A176="","",MIN(D176,H176)) | J176: =IF($A176="","",MAX(0,F176+I176-E176)) | K176: =IF($A176="","",MAX(0,E176-F176-I176)) | L176: =IF($A176="","",MAX(0,F176+I176-E176)) | M176: =IF($A176="","",IFERROR(I176/D176,0))
F177: =IF($A177="","",IF($A177<>$A176,IFERROR(INDEX([1]FG_Begin_Inventory!$B:$B,MATCH($A177,[1]FG_Begin_Inventory!$A:$A,0)),0),J176)) | G177: =IF($A177="","",IF($A177<>$A178,0,MAX(0,G178+E178-D178))) | H177: =IF($A177="","",MAX(0,E177+G177-F177)) | I177: =IF($A177="","",MIN(D177,H177)) | J177: =IF($A177="","",MAX(0,F177+I177-E177)) | K177: =IF($A177="","",MAX(0,E177-F177-I177)) | L177: =IF($A177="","",MAX(0,F177+I177-E177)) | M177: =IF($A177="","",IFERROR(I177/D177,0))
F178: =IF($A178="","",IF($A178<>$A177,IFERROR(INDEX([1]FG_Begin_Inventory!$B:$B,MATCH($A178,[1]FG_Begin_Inventory!$A:$A,0)),0),J177)) | G178: =IF($A178="","",IF($A178<>#REF!,0,MAX(0,#REF!+#REF!-#REF!))) | H178: =IF($A178="","",MAX(0,E178+G178-F178)) | I178: =IF($A178="","",MIN(D178,H178)) | J178: =IF($A178="","",MAX(0,F178+I178-E178)) | K178: =IF($A178="","",MAX(0,E178-F178-I178)) | L178: =IF($A178="","",MAX(0,F178+I178-E178)) | M178: =IF($A178="","",IFERROR(I178/D178,0))
F179: =IF($A179="","",IF($A179<>#REF!,IFERROR(INDEX([1]FG_Begin_Inventory!$B:$B,MATCH($A179,[1]FG_Begin_Inventory!$A:$A,0)),0),#REF!)) | G179: =IF($A179="","",IF($A179<>$A180,0,MAX(0,G180+E180-D180))) | H179: =IF($A179="","",MAX(0,E179+G179-F179)) | I179: =IF($A179="","",MIN(D179,H179)) | J179: =IF($A179="","",MAX(0,F179+I179-E179)) | K179: =IF($A179="","",MAX(0,E179-F179-I179)) | L179: =IF($A179="","",MAX(0,F179+I179-E179)) | M179: =IF($A179="","",IFERROR(I179/D179,0))
F180: =IF($A180="","",IF($A180<>$A179,IFERROR(INDEX([1]FG_Begin_Inventory!$B:$B,MATCH($A180,[1]FG_Begin_Inventory!$A:$A,0)),0),J179)) | G180: =IF($A180="","",IF($A180<>$A181,0,MAX(0,G181+E181-D181))) | H180: =IF($A180="","",MAX(0,E180+G180-F180)) | I180: =IF($A180="","",MIN(D180,H180)) | J180: =IF($A180="","",MAX(0,F180+I180-E180)) | K180: =IF($A180="","",MAX(0,E180-F180-I180)) | L180: =IF($A180="","",MAX(0,F180+I180-E180)) | M180: =IF($A180="","",IFERROR(I180/D180,0))
F181: =IF($A181="","",IF($A181<>$A180,IFERROR(INDEX([1]FG_Begin_Inventory!$B:$B,MATCH($A181,[1]FG_Begin_Inventory!$A:$A,0)),0),J180)) | G181: =IF($A181="","",IF($A181<>$A182,0,MAX(0,G182+E182-D182))) | H181: =IF($A181="","",MAX(0,E181+G181-F181)) | I181: =IF($A181="","",MIN(D181,H181)) | J181: =IF($A181="","",MAX(0,F181+I181-E181)) | K181: =IF($A181="","",MAX(0,E181-F181-I181)) | L181: =IF($A181="","",MAX(0,F181+I181-E181)) | M181: =IF($A181="","",IFERROR(I181/D181,0))
F182: =IF($A182="","",IF($A182<>$A181,IFERROR(INDEX([1]FG_Begin_Inventory!$B:$B,MATCH($A182,[1]FG_Begin_Inventory!$A:$A,0)),0),J181)) | G182: =IF($A182="","",IF($A182<>$A183,0,MAX(0,G183+E183-D183))) | H182: =IF($A182="","",MAX(0,E182+G182-F182)) | I182: =IF($A182="","",MIN(D182,H182)) | J182: =IF($A182="","",MAX(0,F182+I182-E182)) | K182: =IF($A182="","",MAX(0,E182-F182-I182)) | L182: =IF($A182="","",MAX(0,F182+I182-E182)) | M182: =IF($A182="","",IFERROR(I182/D182,0))
F183: =IF($A183="","",IF($A183<>$A182,IFERROR(INDEX([1]FG_Begin_Inventory!$B:$B,MATCH($A183,[1]FG_Begin_Inventory!$A:$A,0)),0),J182)) | G183: =IF($A183="","",IF($A183<>$A184,0,MAX(0,G184+E184-D184))) | H183: =IF($A183="","",MAX(0,E183+G183-F183)) | I183: =IF($A183="","",MIN(D183,H183)) | J183: =IF($A183="","",MAX(0,F183+I183-E183)) | K183: =IF($A183="","",MAX(0,E183-F183-I183)) | L183: =IF($A183="","",MAX(0,F183+I183-E183)) | M183: =IF($A183="","",IFERROR(I183/D183,0))
F184: =IF($A184="","",IF($A184<>$A183,IFERROR(INDEX([1]FG_Begin_Inventory!$B:$B,MATCH($A184,[1]FG_Begin_Inventory!$A:$A,0)),0),J183)) | G184: =IF($A184="","",IF($A184<>$A185,0,MAX(0,G185+E185-D185))) | H184: =IF($A184="","",MAX(0,E184+G184-F184)) | I184: =IF($A184="","",MIN(D184,H184)) | J184: =IF($A184="","",MAX(0,F184+I184-E184)) | K184: =IF($A184="","",MAX(0,E184-F184-I184)) | L184: =IF($A184="","",MAX(0,F184+I184-E184)) | M184: =IF($A184="","",IFERROR(I184/D184,0))
F185: =IF($A185="","",IF($A185<>$A184,IFERROR(INDEX([1]FG_Begin_Inventory!$B:$B,MATCH($A185,[1]FG_Begin_Inventory!$A:$A,0)),0),J184)) | G185: =IF($A185="","",IF($A185<>$A186,0,MAX(0,G186+E186-D186))) | H185: =IF($A185="","",MAX(0,E185+G185-F185)) | I185: =IF($A185="","",MIN(D185,H185)) | J185: =IF($A185="","",MAX(0,F185+I185-E185)) | K185: =IF($A185="","",MAX(0,E185-F185-I185)) | L185: =IF($A185="","",MAX(0,F185+I185-E185)) | M185: =IF($A185="","",IFERROR(I185/D185,0))
F186: =IF($A186="","",IF($A186<>$A185,IFERROR(INDEX([1]FG_Begin_Inventory!$B:$B,MATCH($A186,[1]FG_Begin_Inventory!$A:$A,0)),0),J185)) | G186: =IF($A186="","",IF($A186<>$A187,0,MAX(0,G187+E187-D187))) | H186: =IF($A186="","",MAX(0,E186+G186-F186)) | I186: =IF($A186="","",MIN(D186,H186)) | J186: =IF($A186="","",MAX(0,F186+I186-E186)) | K186: =IF($A186="","",MAX(0,E186-F186-I186)) | L186: =IF($A186="","",MAX(0,F186+I186-E186)) | M186: =IF($A186="","",IFERROR(I186/D186,0))
F187: =IF($A187="","",IF($A187<>$A186,IFERROR(INDEX([1]FG_Begin_Inventory!$B:$B,MATCH($A187,[1]FG_Begin_Inventory!$A:$A,0)),0),J186)) | G187: =IF($A187="","",IF($A187<>$A188,0,MAX(0,G188+E188-D188))) | H187: =IF($A187="","",MAX(0,E187+G187-F187)) | I187: =IF($A187="","",MIN(D187,H187)) | J187: =IF($A187="","",MAX(0,F187+I187-E187)) | K187: =IF($A187="","",MAX(0,E187-F187-I187)) | L187: =IF($A187="","",MAX(0,F187+I187-E187)) | M187: =IF($A187="","",IFERROR(I187/D187,0))
F188: =IF($A188="","",IF($A188<>$A187,IFERROR(INDEX([1]FG_Begin_Inventory!$B:$B,MATCH($A188,[1]FG_Begin_Inventory!$A:$A,0)),0),J187)) | G188: =IF($A188="","",IF($A188<>$A189,0,MAX(0,G189+E189-D189))) | H188: =IF($A188="","",MAX(0,E188+G188-F188)) | I188: =IF($A188="","",MIN(D188,H188)) | J188: =IF($A188="","",MAX(0,F188+I188-E188)) | K188: =IF($A188="","",MAX(0,E188-F188-I188)) | L188: =IF($A188="","",MAX(0,F188+I188-E188)) | M188: =IF($A188="","",IFERROR(I188/D188,0))
F189: =IF($A189="","",IF($A189<>$A188,IFERROR(INDEX([1]FG_Begin_Inventory!$B:$B,MATCH($A189,[1]FG_Begin_Inventory!$A:$A,0)),0),J188)) | G189: =IF($A189="","",IF($A189<>$A190,0,MAX(0,G190+E190-D190))) | H189: =IF($A189="","",MAX(0,E189+G189-F189)) | I189: =IF($A189="","",MIN(D189,H189)) | J189: =IF($A189="","",MAX(0,F189+I189-E189)) | K189: =IF($A189="","",MAX(0,E189-F189-I189)) | L189: =IF($A189="","",MAX(0,F189+I189-E189)) | M189: =IF($A189="","",IFERROR(I189/D189,0))
F190: =IF($A190="","",IF($A190<>$A189,IFERROR(INDEX([1]FG_Begin_Inventory!$B:$B,MATCH($A190,[1]FG_Begin_Inventory!$A:$A,0)),0),J189)) | G190: =IF($A190="","",IF($A190<>$A191,0,MAX(0,G191+E191-D191))) | H190: =IF($A190="","",MAX(0,E190+G190-F190)) | I190: =IF($A190="","",MIN(D190,H190)) | J190: =IF($A190="","",MAX(0,F190+I190-E190)) | K190: =IF($A190="","",MAX(0,E190-F190-I190)) | L190: =IF($A190="","",MAX(0,F190+I190-E190)) | M190: =IF($A190="","",IFERROR(I190/D190,0))
F191: =IF($A191="","",IF($A191<>$A190,IFERROR(INDEX([1]FG_Begin_Inventory!$B:$B,MATCH($A191,[1]FG_Begin_Inventory!$A:$A,0)),0),J190)) | G191: =IF($A191="","",IF($A191<>$A192,0,MAX(0,G192+E192-D192))) | H191: =IF($A191="","",MAX(0,E191+G191-F191)) | I191: =IF($A191="","",MIN(D191,H191)) | J191: =IF($A191="","",MAX(0,F191+I191-E191)) | K191: =IF($A191="","",MAX(0,E191-F191-I191)) | L191: =IF($A191="","",MAX(0,F191+I191-E191)) | M191: =IF($A191="","",IFERROR(I191/D191,0))
... F255: =IF($A255="","",IF($A255<>$A254,IFERROR(INDEX([1]FG_Begin_Inventory!$B:$B,MATCH($A255,[1]FG_Begin_Inventory!$A:$A,0)),0),J254)) | G255: =IF($A255="","",IF($A255<>$A256,0,MAX(0,G256+E256-D256))) | H255: =IF($A255="","",MAX(0,E255+G255-F255)) | I255: =IF($A255="","",MIN(D255,H255)) | J255: =IF($A255="","",MAX(0,F255+I255-E255)) | K255: =IF($A255="","",MAX(0,E255-F255-I255)) | L255: =IF($A255="","",MAX(0,F255+I255-E255)) | M255: =IF($A255="","",IFERROR(I255/D255,0))
A256: =IF([1]weekly_demand!A257="","",[1]weekly_demand!A257) | B256: =IF($A256="","",[1]weekly_demand!F257) | C256: =IF($A256="","",[1]weekly_demand!H257) | D256: =IF($A256="","",IF(SUMIFS([1]Fixture_Capacity_Input!$C:$C,[1]Fixture_Capacity_Input!$A:$A,$B256,[1]Fixture_Capacity_Input!$B:$B,$C256)>0,SUMIFS([1]Fixture_Capacity_Input!$C:$C,[1]Fixture_Capacity_Input!$A:$A,$B256,[1]Fixture_Capacity_Input!$B:$B,$C256),[1]weekly_demand!G257)) | E256: =IF($A256="","",[1]weekly_demand!I257) | F256: =IF($A256="","",IF($A256<>$A255,IFERROR(INDEX([1]FG_Begin_Inventory!$B:$B,MATCH($A256,[1]FG_Begin_Inventory!$A:$A,0)),0),J255)) | G256: =IF($A256="","",IF($A256<>$A257,0,MAX(0,G257+E257-D257))) | H256: =IF($A256="","",MAX(0,E256+G256-F256)) | I256: =IF($A256="","",MIN(D256,H256)) | J256: =IF($A256="","",MAX(0,F256+I256-E256)) | K256: =IF($A256="","",MAX(0,E256-F256-I256)) | L256: =IF($A256="","",MAX(0,F256+I256-E256)) | M256: =IF($A256="","",IFERROR(I256/D256,0))
A257: =IF([1]weekly_demand!A258="","",[1]weekly_demand!A258) | B257: =IF($A257="","",[1]weekly_demand!F258) | C257: =IF($A257="","",[1]weekly_demand!H258) | D257: =IF($A257="","",IF(SUMIFS([1]Fixture_Capacity_Input!$C:$C,[1]Fixture_Capacity_Input!$A:$A,$B257,[1]Fixture_Capacity_Input!$B:$B,$C257)>0,SUMIFS([1]Fixture_Capacity_Input!$C:$C,[1]Fixture_Capacity_Input!$A:$A,$B257,[1]Fixture_Capacity_Input!$B:$B,$C257),[1]weekly_demand!G258)) | E257: =IF($A257="","",[1]weekly_demand!I258) | F257: =IF($A257="","",IF($A257<>$A256,IFERROR(INDEX([1]FG_Begin_Inventory!$B:$B,MATCH($A257,[1]FG_Begin_Inventory!$A:$A,0)),0),J256)) | G257: =IF($A257="","",IF($A257<>$A258,0,MAX(0,G258+E258-D258))) | H257: =IF($A257="","",MAX(0,E257+G257-F257)) | I257: =IF($A257="","",MIN(D257,H257)) | J257: =IF($A257="","",MAX(0,F257+I257-E257)) | K257: =IF($A257="","",MAX(0,E257-F257-I257)) | L257: =IF($A257="","",MAX(0,F257+I257-E257)) | M257: =IF($A257="","",IFERROR(I257/D257,0))
A258: =IF([1]weekly_demand!A259="","",[1]weekly_demand!A259) | B258: =IF($A258="","",[1]weekly_demand!F259) | C258: =IF($A258="","",[1]weekly_demand!H259) | D258: =IF($A258="","",IF(SUMIFS([1]Fixture_Capacity_Input!$C:$C,[1]Fixture_Capacity_Input!$A:$A,$B258,[1]Fixture_Capacity_Input!$B:$B,$C258)>0,SUMIFS([1]Fixture_Capacity_Input!$C:$C,[1]Fixture_Capacity_Input!$A:$A,$B258,[1]Fixture_Capacity_Input!$B:$B,$C258),[1]weekly_demand!G259)) | E258: =IF($A258="","",[1]weekly_demand!I259) | F258: =IF($A258="","",IF($A258<>$A257,IFERROR(INDEX([1]FG_Begin_Inventory!$B:$B,MATCH($A258,[1]FG_Begin_Inventory!$A:$A,0)),0),J257)) | G258: =IF($A258="","",IF($A258<>$A259,0,MAX(0,G259+E259-D259))) | H258: =IF($A258="","",MAX(0,E258+G258-F258)) | I258: =IF($A258="","",MIN(D258,H258)) | J258: =IF($A258="","",MAX(0,F258+I258-E258)) | K258: =IF($A258="","",MAX(0,E258-F258-I258)) | L258: =IF($A258="","",MAX(0,F258+I258-E258)) | M258: =IF($A258="","",IFERROR(I258/D258,0))
...

Sheet BOM_demand
A1: Week | B1: A | C1: B | D1: C | E1: D | F1: E | G1: F | H1: RM01 | I1: RM02 | J1: RM03 | K1: RM04 | L1: RM05 | M1: RM06 | N1: RM07 | O1: RM08 | P1: RM09 | Q1: RM10 | R1: RM11 | S1: RM12 | T1: RM13 | U1: RM14 | V1: RM15 | X1: BOM usage helper | Y1: A | Z1: B | AA1: C | AB1: D | AC1: E | AD1: F
A2: 46132 | B2: =IF($A2="","",SUMIFS(weekly_demand!$D:$D,weekly_demand!$A:$A,B$1,weekly_demand!$C:$C,$A2)) -> 0 | C2: =IF($A2="","",SUMIFS(weekly_demand!$D:$D,weekly_demand!$A:$A,C$1,weekly_demand!$C:$C,$A2)) -> 0 | D2: =IF($A2="","",SUMIFS(weekly_demand!$D:$D,weekly_demand!$A:$A,D$1,weekly_demand!$C:$C,$A2)) -> 0 | E2: =IF($A2="","",SUMIFS(weekly_demand!$D:$D,weekly_demand!$A:$A,E$1,weekly_demand!$C:$C,$A2)) -> 0 | F2: =IF($A2="","",SUMIFS(weekly_demand!$D:$D,weekly_demand!$A:$A,F$1,weekly_demand!$C:$C,$A2)) -> 0 | G2: =IF($A2="","",SUMIFS(weekly_demand!$D:$D,weekly_demand!$A:$A,G$1,weekly_demand!$C:$C,$A2)) -> 0 | H2: =IF($A2="","",SUMPRODUCT($B2:$G2,INDEX($Y$2:$AD$16,MATCH(H$1,$X$2:$X$16,0),0))) -> 0 | I2: =IF($A2="","",SUMPRODUCT($B2:$G2,INDEX($Y$2:$AD$16,MATCH(I$1,$X$2:$X$16,0),0))) -> 0 | J2: =IF($A2="","",SUMPRODUCT($B2:$G2,INDEX($Y$2:$AD$16,MATCH(J$1,$X$2:$X$16,0),0))) -> 0 | K2: =IF($A2="","",SUMPRODUCT($B2:$G2,INDEX($Y$2:$AD$16,MATCH(K$1,$X$2:$X$16,0),0))) -> 0 | L2: =IF($A2="","",SUMPRODUCT($B2:$G2,INDEX($Y$2:$AD$16,MATCH(L$1,$X$2:$X$16,0),0))) -> 0 | M2: =IF($A2="","",SUMPRODUCT($B2:$G2,INDEX($Y$2:$AD$16,MATCH(M$1,$X$2:$X$16,0),0))) -> 0 | N2: =IF($A2="","",SUMPRODUCT($B2:$G2,INDEX($Y$2:$AD$16,MATCH(N$1,$X$2:$X$16,0),0))) -> 0 | O2: =IF($A2="","",SUMPRODUCT($B2:$G2,INDEX($Y$2:$AD$16,MATCH(O$1,$X$2:$X$16,0),0))) -> 0 | ... V2: =IF($A2="","",SUMPRODUCT($B2:$G2,INDEX($Y$2:$AD$16,MATCH(V$1,$X$2:$X$16,0),0))) -> 0 | X2: RM01 | Y2: 1 | Z2: 1 | AA2: 1 | AB2: 1 | AC2: 1 | AD2: 1
A3: 46139 | B3: =IF($A3="","",SUMIFS(weekly_demand!$D:$D,weekly_demand!$A:$A,B$1,weekly_demand!$C:$C,$A3)) -> 0 | C3: =IF($A3="","",SUMIFS(weekly_demand!$D:$D,weekly_demand!$A:$A,C$1,weekly_demand!$C:$C,$A3)) -> 0 | D3: =IF($A3="","",SUMIFS(weekly_demand!$D:$D,weekly_demand!$A:$A,D$1,weekly_demand!$C:$C,$A3)) -> 0 | E3: =IF($A3="","",SUMIFS(weekly_demand!$D:$D,weekly_demand!$A:$A,E$1,weekly_demand!$C:$C,$A3)) -> 0 | F3: =IF($A3="","",SUMIFS(weekly_demand!$D:$D,weekly_demand!$A:$A,F$1,weekly_demand!$C:$C,$A3)) -> 0 | G3: =IF($A3="","",SUMIFS(weekly_demand!$D:$D,weekly_demand!$A:$A,G$1,weekly_demand!$C:$C,$A3)) -> 0 | H3: =IF($A3="","",SUMPRODUCT($B3:$G3,INDEX($Y$2:$AD$16,MATCH(H$1,$X$2:$X$16,0),0))) -> 0 | I3: =IF($A3="","",SUMPRODUCT($B3:$G3,INDEX($Y$2:$AD$16,MATCH(I$1,$X$2:$X$16,0),0))) -> 0 | J3: =IF($A3="","",SUMPRODUCT($B3:$G3,INDEX($Y$2:$AD$16,MATCH(J$1,$X$2:$X$16,0),0))) -> 0 | K3: =IF($A3="","",SUMPRODUCT($B3:$G3,INDEX($Y$2:$AD$16,MATCH(K$1,$X$2:$X$16,0),0))) -> 0 | L3: =IF($A3="","",SUMPRODUCT($B3:$G3,INDEX($Y$2:$AD$16,MATCH(L$1,$X$2:$X$16,0),0))) -> 0 | M3: =IF($A3="","",SUMPRODUCT($B3:$G3,INDEX($Y$2:$AD$16,MATCH(M$1,$X$2:$X$16,0),0))) -> 0 | N3: =IF($A3="","",SUMPRODUCT($B3:$G3,INDEX($Y$2:$AD$16,MATCH(N$1,$X$2:$X$16,0),0))) -> 0 | O3: =IF($A3="","",SUMPRODUCT($B3:$G3,INDEX($Y$2:$AD$16,MATCH(O$1,$X$2:$X$16,0),0))) -> 0 | ... V3: =IF($A3="","",SUMPRODUCT($B3:$G3,INDEX($Y$2:$AD$16,MATCH(V$1,$X$2:$X$16,0),0))) -> 0 | X3: RM02 | Y3: 0.25 | Z3: 0.25 | AA3: 0.5 | AB3: 0.25 | AC3: 0.5 | AD3: 0.125
A4: 46146 | B4: =IF($A4="","",SUMIFS(weekly_demand!$D:$D,weekly_demand!$A:$A,B$1,weekly_demand!$C:$C,$A4)) -> 0 | C4: =IF($A4="","",SUMIFS(weekly_demand!$D:$D,weekly_demand!$A:$A,C$1,weekly_demand!$C:$C,$A4)) -> 0 | D4: =IF($A4="","",SUMIFS(weekly_demand!$D:$D,weekly_demand!$A:$A,D$1,weekly_demand!$C:$C,$A4)) -> 0 | E4: =IF($A4="","",SUMIFS(weekly_demand!$D:$D,weekly_demand!$A:$A,E$1,weekly_demand!$C:$C,$A4)) -> 0 | F4: =IF($A4="","",SUMIFS(weekly_demand!$D:$D,weekly_demand!$A:$A,F$1,weekly_demand!$C:$C,$A4)) -> 0 | G4: =IF($A4="","",SUMIFS(weekly_demand!$D:$D,weekly_demand!$A:$A,G$1,weekly_demand!$C:$C,$A4)) -> 0 | H4: =IF($A4="","",SUMPRODUCT($B4:$G4,INDEX($Y$2:$AD$16,MATCH(H$1,$X$2:$X$16,0),0))) -> 0 | I4: =IF($A4="","",SUMPRODUCT($B4:$G4,INDEX($Y$2:$AD$16,MATCH(I$1,$X$2:$X$16,0),0))) -> 0 | J4: =IF($A4="","",SUMPRODUCT($B4:$G4,INDEX($Y$2:$AD$16,MATCH(J$1,$X$2:$X$16,0),0))) -> 0 | K4: =IF($A4="","",SUMPRODUCT($B4:$G4,INDEX($Y$2:$AD$16,MATCH(K$1,$X$2:$X$16,0),0))) -> 0 | L4: =IF($A4="","",SUMPRODUCT($B4:$G4,INDEX($Y$2:$AD$16,MATCH(L$1,$X$2:$X$16,0),0))) -> 0 | M4: =IF($A4="","",SUMPRODUCT($B4:$G4,INDEX($Y$2:$AD$16,MATCH(M$1,$X$2:$X$16,0),0))) -> 0 | N4: =IF($A4="","",SUMPRODUCT($B4:$G4,INDEX($Y$2:$AD$16,MATCH(N$1,$X$2:$X$16,0),0))) -> 0 | O4: =IF($A4="","",SUMPRODUCT($B4:$G4,INDEX($Y$2:$AD$16,MATCH(O$1,$X$2:$X$16,0),0))) -> 0 | ... V4: =IF($A4="","",SUMPRODUCT($B4:$G4,INDEX($Y$2:$AD$16,MATCH(V$1,$X$2:$X$16,0),0))) -> 0 | X4: RM03 | Y4: 1 | Z4: 1 | AA4: 1 | AB4: 1 | AC4: 1 | AD4: 1
A5: 46153 | B5: =IF($A5="","",SUMIFS(weekly_demand!$D:$D,weekly_demand!$A:$A,B$1,weekly_demand!$C:$C,$A5)) -> 0 | C5: =IF($A5="","",SUMIFS(weekly_demand!$D:$D,weekly_demand!$A:$A,C$1,weekly_demand!$C:$C,$A5)) -> 0 | D5: =IF($A5="","",SUMIFS(weekly_demand!$D:$D,weekly_demand!$A:$A,D$1,weekly_demand!$C:$C,$A5)) -> 0 | E5: =IF($A5="","",SUMIFS(weekly_demand!$D:$D,weekly_demand!$A:$A,E$1,weekly_demand!$C:$C,$A5)) -> 0 | F5: =IF($A5="","",SUMIFS(weekly_demand!$D:$D,weekly_demand!$A:$A,F$1,weekly_demand!$C:$C,$A5)) -> 0 | G5: =IF($A5="","",SUMIFS(weekly_demand!$D:$D,weekly_demand!$A:$A,G$1,weekly_demand!$C:$C,$A5)) -> 0 | H5: =IF($A5="","",SUMPRODUCT($B5:$G5,INDEX($Y$2:$AD$16,MATCH(H$1,$X$2:$X$16,0),0))) -> 0 | I5: =IF($A5="","",SUMPRODUCT($B5:$G5,INDEX($Y$2:$AD$16,MATCH(I$1,$X$2:$X$16,0),0))) -> 0 | J5: =IF($A5="","",SUMPRODUCT($B5:$G5,INDEX($Y$2:$AD$16,MATCH(J$1,$X$2:$X$16,0),0))) -> 0 | K5: =IF($A5="","",SUMPRODUCT($B5:$G5,INDEX($Y$2:$AD$16,MATCH(K$1,$X$2:$X$16,0),0))) -> 0 | L5: =IF($A5="","",SUMPRODUCT($B5:$G5,INDEX($Y$2:$AD$16,MATCH(L$1,$X$2:$X$16,0),0))) -> 0 | M5: =IF($A5="","",SUMPRODUCT($B5:$G5,INDEX($Y$2:$AD$16,MATCH(M$1,$X$2:$X$16,0),0))) -> 0 | N5: =IF($A5="","",SUMPRODUCT($B5:$G5,INDEX($Y$2:$AD$16,MATCH(N$1,$X$2:$X$16,0),0))) -> 0 | O5: =IF($A5="","",SUMPRODUCT($B5:$G5,INDEX($Y$2:$AD$16,MATCH(O$1,$X$2:$X$16,0),0))) -> 0 | ... V5: =IF($A5="","",SUMPRODUCT($B5:$G5,INDEX($Y$2:$AD$16,MATCH(V$1,$X$2:$X$16,0),0))) -> 0 | X5: RM04 | Y5: 2 | Z5: 0 | AA5: 0 | AB5: 0 | AC5: 0 | AD5: 0
A6: 46160 | B6: =IF($A6="","",SUMIFS(weekly_demand!$D:$D,weekly_demand!$A:$A,B$1,weekly_demand!$C:$C,$A6)) -> 0 | C6: =IF($A6="","",SUMIFS(weekly_demand!$D:$D,weekly_demand!$A:$A,C$1,weekly_demand!$C:$C,$A6)) -> 0 | D6: =IF($A6="","",SUMIFS(weekly_demand!$D:$D,weekly_demand!$A:$A,D$1,weekly_demand!$C:$C,$A6)) -> 0 | E6: =IF($A6="","",SUMIFS(weekly_demand!$D:$D,weekly_demand!$A:$A,E$1,weekly_demand!$C:$C,$A6)) -> 0 | F6: =IF($A6="","",SUMIFS(weekly_demand!$D:$D,weekly_demand!$A:$A,F$1,weekly_demand!$C:$C,$A6)) -> 0 | G6: =IF($A6="","",SUMIFS(weekly_demand!$D:$D,weekly_demand!$A:$A,G$1,weekly_demand!$C:$C,$A6)) -> 0 | H6: =IF($A6="","",SUMPRODUCT($B6:$G6,INDEX($Y$2:$AD$16,MATCH(H$1,$X$2:$X$16,0),0))) -> 0 | I6: =IF($A6="","",SUMPRODUCT($B6:$G6,INDEX($Y$2:$AD$16,MATCH(I$1,$X$2:$X$16,0),0))) -> 0 | J6: =IF($A6="","",SUMPRODUCT($B6:$G6,INDEX($Y$2:$AD$16,MATCH(J$1,$X$2:$X$16,0),0))) -> 0 | K6: =IF($A6="","",SUMPRODUCT($B6:$G6,INDEX($Y$2:$AD$16,MATCH(K$1,$X$2:$X$16,0),0))) -> 0 | L6: =IF($A6="","",SUMPRODUCT($B6:$G6,INDEX($Y$2:$AD$16,MATCH(L$1,$X$2:$X$16,0),0))) -> 0 | M6: =IF($A6="","",SUMPRODUCT($B6:$G6,INDEX($Y$2:$AD$16,MATCH(M$1,$X$2:$X$16,0),0))) -> 0 | N6: =IF($A6="","",SUMPRODUCT($B6:$G6,INDEX($Y$2:$AD$16,MATCH(N$1,$X$2:$X$16,0),0))) -> 0 | O6: =IF($A6="","",SUMPRODUCT($B6:$G6,INDEX($Y$2:$AD$16,MATCH(O$1,$X$2:$X$16,0),0))) -> 0 | ... V6: =IF($A6="","",SUMPRODUCT($B6:$G6,INDEX($Y$2:$AD$16,MATCH(V$1,$X$2:$X$16,0),0))) -> 0 | X6: RM05 | Y6: 1 | Z6: 0 | AA6: 0 | AB6: 0 | AC6: 0 | AD6: 0
A7: 46167 | B7: =IF($A7="","",SUMIFS(weekly_demand!$D:$D,weekly_demand!$A:$A,B$1,weekly_demand!$C:$C,$A7)) -> 0 | C7: =IF($A7="","",SUMIFS(weekly_demand!$D:$D,weekly_demand!$A:$A,C$1,weekly_demand!$C:$C,$A7)) -> 0 | D7: =IF($A7="","",SUMIFS(weekly_demand!$D:$D,weekly_demand!$A:$A,D$1,weekly_demand!$C:$C,$A7)) -> 0 | E7: =IF($A7="","",SUMIFS(weekly_demand!$D:$D,weekly_demand!$A:$A,E$1,weekly_demand!$C:$C,$A7)) -> 0 | F7: =IF($A7="","",SUMIFS(weekly_demand!$D:$D,weekly_demand!$A:$A,F$1,weekly_demand!$C:$C,$A7)) -> 0 | G7: =IF($A7="","",SUMIFS(weekly_demand!$D:$D,weekly_demand!$A:$A,G$1,weekly_demand!$C:$C,$A7)) -> 0 | H7: =IF($A7="","",SUMPRODUCT($B7:$G7,INDEX($Y$2:$AD$16,MATCH(H$1,$X$2:$X$16,0),0))) -> 0 | I7: =IF($A7="","",SUMPRODUCT($B7:$G7,INDEX($Y$2:$AD$16,MATCH(I$1,$X$2:$X$16,0),0))) -> 0 | J7: =IF($A7="","",SUMPRODUCT($B7:$G7,INDEX($Y$2:$AD$16,MATCH(J$1,$X$2:$X$16,0),0))) -> 0 | K7: =IF($A7="","",SUMPRODUCT($B7:$G7,INDEX($Y$2:$AD$16,MATCH(K$1,$X$2:$X$16,0),0))) -> 0 | L7: =IF($A7="","",SUMPRODUCT($B7:$G7,INDEX($Y$2:$AD$16,MATCH(L$1,$X$2:$X$16,0),0))) -> 0 | M7: =IF($A7="","",SUMPRODUCT($B7:$G7,INDEX($Y$2:$AD$16,MATCH(M$1,$X$2:$X$16,0),0))) -> 0 | N7: =IF($A7="","",SUMPRODUCT($B7:$G7,INDEX($Y$2:$AD$16,MATCH(N$1,$X$2:$X$16,0),0))) -> 0 | O7: =IF($A7="","",SUMPRODUCT($B7:$G7,INDEX($Y$2:$AD$16,MATCH(O$1,$X$2:$X$16,0),0))) -> 0 | ... V7: =IF($A7="","",SUMPRODUCT($B7:$G7,INDEX($Y$2:$AD$16,MATCH(V$1,$X$2:$X$16,0),0))) -> 0 | X7: RM06 | Y7: 0 | Z7: 2.5 | AA7: 0 | AB7: 0 | AC7: 0 | AD7: 0
A8: 46174 | B8: =IF($A8="","",SUMIFS(weekly_demand!$D:$D,weekly_demand!$A:$A,B$1,weekly_demand!$C:$C,$A8)) -> 0 | C8: =IF($A8="","",SUMIFS(weekly_demand!$D:$D,weekly_demand!$A:$A,C$1,weekly_demand!$C:$C,$A8)) -> 0 | D8: =IF($A8="","",SUMIFS(weekly_demand!$D:$D,weekly_demand!$A:$A,D$1,weekly_demand!$C:$C,$A8)) -> 0 | E8: =IF($A8="","",SUMIFS(weekly_demand!$D:$D,weekly_demand!$A:$A,E$1,weekly_demand!$C:$C,$A8)) -> 0 | F8: =IF($A8="","",SUMIFS(weekly_demand!$D:$D,weekly_demand!$A:$A,F$1,weekly_demand!$C:$C,$A8)) -> 0 | G8: =IF($A8="","",SUMIFS(weekly_demand!$D:$D,weekly_demand!$A:$A,G$1,weekly_demand!$C:$C,$A8)) -> 0 | H8: =IF($A8="","",SUMPRODUCT($B8:$G8,INDEX($Y$2:$AD$16,MATCH(H$1,$X$2:$X$16,0),0))) -> 0 | I8: =IF($A8="","",SUMPRODUCT($B8:$G8,INDEX($Y$2:$AD$16,MATCH(I$1,$X$2:$X$16,0),0))) -> 0 | J8: =IF($A8="","",SUMPRODUCT($B8:$G8,INDEX($Y$2:$AD$16,MATCH(J$1,$X$2:$X$16,0),0))) -> 0 | K8: =IF($A8="","",SUMPRODUCT($B8:$G8,INDEX($Y$2:$AD$16,MATCH(K$1,$X$2:$X$16,0),0))) -> 0 | L8: =IF($A8="","",SUMPRODUCT($B8:$G8,INDEX($Y$2:$AD$16,MATCH(L$1,$X$2:$X$16,0),0))) -> 0 | M8: =IF($A8="","",SUMPRODUCT($B8:$G8,INDEX($Y$2:$AD$16,MATCH(M$1,$X$2:$X$16,0),0))) -> 0 | N8: =IF($A8="","",SUMPRODUCT($B8:$G8,INDEX($Y$2:$AD$16,MATCH(N$1,$X$2:$X$16,0),0))) -> 0 | O8: =IF($A8="","",SUMPRODUCT($B8:$G8,INDEX($Y$2:$AD$16,MATCH(O$1,$X$2:$X$16,0),0))) -> 0 | ... V8: =IF($A8="","",SUMPRODUCT($B8:$G8,INDEX($Y$2:$AD$16,MATCH(V$1,$X$2:$X$16,0),0))) -> 0 | X8: RM07 | Y8: 0 | Z8: 1.5 | AA8: 0 | AB8: 0 | AC8: 0 | AD8: 0
A9: 46181 | B9: =IF($A9="","",SUMIFS(weekly_demand!$D:$D,weekly_demand!$A:$A,B$1,weekly_demand!$C:$C,$A9)) -> 0 | C9: =IF($A9="","",SUMIFS(weekly_demand!$D:$D,weekly_demand!$A:$A,C$1,weekly_demand!$C:$C,$A9)) -> 0 | D9: =IF($A9="","",SUMIFS(weekly_demand!$D:$D,weekly_demand!$A:$A,D$1,weekly_demand!$C:$C,$A9)) -> 0 | E9: =IF($A9="","",SUMIFS(weekly_demand!$D:$D,weekly_demand!$A:$A,E$1,weekly_demand!$C:$C,$A9)) -> 0 | F9: =IF($A9="","",SUMIFS(weekly_demand!$D:$D,weekly_demand!$A:$A,F$1,weekly_demand!$C:$C,$A9)) -> 0 | G9: =IF($A9="","",SUMIFS(weekly_demand!$D:$D,weekly_demand!$A:$A,G$1,weekly_demand!$C:$C,$A9)) -> 0 | H9: =IF($A9="","",SUMPRODUCT($B9:$G9,INDEX($Y$2:$AD$16,MATCH(H$1,$X$2:$X$16,0),0))) -> 0 | I9: =IF($A9="","",SUMPRODUCT($B9:$G9,INDEX($Y$2:$AD$16,MATCH(I$1,$X$2:$X$16,0),0))) -> 0 | J9: =IF($A9="","",SUMPRODUCT($B9:$G9,INDEX($Y$2:$AD$16,MATCH(J$1,$X$2:$X$16,0),0))) -> 0 | K9: =IF($A9="","",SUMPRODUCT($B9:$G9,INDEX($Y$2:$AD$16,MATCH(K$1,$X$2:$X$16,0),0))) -> 0 | L9: =IF($A9="","",SUMPRODUCT($B9:$G9,INDEX($Y$2:$AD$16,MATCH(L$1,$X$2:$X$16,0),0))) -> 0 | M9: =IF($A9="","",SUMPRODUCT($B9:$G9,INDEX($Y$2:$AD$16,MATCH(M$1,$X$2:$X$16,0),0))) -> 0 | N9: =IF($A9="","",SUMPRODUCT($B9:$G9,INDEX($Y$2:$AD$16,MATCH(N$1,$X$2:$X$16,0),0))) -> 0 | O9: =IF($A9="","",SUMPRODUCT($B9:$G9,INDEX($Y$2:$AD$16,MATCH(O$1,$X$2:$X$16,0),0))) -> 0 | ... V9: =IF($A9="","",SUMPRODUCT($B9:$G9,INDEX($Y$2:$AD$16,MATCH(V$1,$X$2:$X$16,0),0))) -> 0 | X9: RM08 | Y9: 0 | Z9: 0 | AA9: 3 | AB9: 0 | AC9: 0 | AD9: 0
A10: 46188 | B10: =IF($A10="","",SUMIFS(weekly_demand!$D:$D,weekly_demand!$A:$A,B$1,weekly_demand!$C:$C,$A10)) -> 0 | C10: =IF($A10="","",SUMIFS(weekly_demand!$D:$D,weekly_demand!$A:$A,C$1,weekly_demand!$C:$C,$A10)) -> 0 | D10: =IF($A10="","",SUMIFS(weekly_demand!$D:$D,weekly_demand!$A:$A,D$1,weekly_demand!$C:$C,$A10)) -> 0 | E10: =IF($A10="","",SUMIFS(weekly_demand!$D:$D,weekly_demand!$A:$A,E$1,weekly_demand!$C:$C,$A10)) -> 0 | F10: =IF($A10="","",SUMIFS(weekly_demand!$D:$D,weekly_demand!$A:$A,F$1,weekly_demand!$C:$C,$A10)) -> 0 | G10: =IF($A10="","",SUMIFS(weekly_demand!$D:$D,weekly_demand!$A:$A,G$1,weekly_demand!$C:$C,$A10)) -> 0 | H10: =IF($A10="","",SUMPRODUCT($B10:$G10,INDEX($Y$2:$AD$16,MATCH(H$1,$X$2:$X$16,0),0))) -> 0 | I10: =IF($A10="","",SUMPRODUCT($B10:$G10,INDEX($Y$2:$AD$16,MATCH(I$1,$X$2:$X$16,0),0))) -> 0 | J10: =IF($A10="","",SUMPRODUCT($B10:$G10,INDEX($Y$2:$AD$16,MATCH(J$1,$X$2:$X$16,0),0))) -> 0 | K10: =IF($A10="","",SUMPRODUCT($B10:$G10,INDEX($Y$2:$AD$16,MATCH(K$1,$X$2:$X$16,0),0))) -> 0 | L10: =IF($A10="","",SUMPRODUCT($B10:$G10,INDEX($Y$2:$AD$16,MATCH(L$1,$X$2:$X$16,0),0))) -> 0 | M10: =IF($A10="","",SUMPRODUCT($B10:$G10,INDEX($Y$2:$AD$16,MATCH(M$1,$X$2:$X$16,0),0))) -> 0 | N10: =IF($A10="","",SUMPRODUCT($B10:$G10,INDEX($Y$2:$AD$16,MATCH(N$1,$X$2:$X$16,0),0))) -> 0 | O10: =IF($A10="","",SUMPRODUCT($B10:$G10,INDEX($Y$2:$AD$16,MATCH(O$1,$X$2:$X$16,0),0))) -> 0 | ... V10: =IF($A10="","",SUMPRODUCT($B10:$G10,INDEX($Y$2:$AD$16,MATCH(V$1,$X$2:$X$16,0),0))) -> 0 | X10: RM09 | Y10: 0 | Z10: 0 | AA10: 0.5 | AB10: 0 | AC10: 0 | AD10: 0
A11: 46195 | B11: =IF($A11="","",SUMIFS(weekly_demand!$D:$D,weekly_demand!$A:$A,B$1,weekly_demand!$C:$C,$A11)) -> 0 | C11: =IF($A11="","",SUMIFS(weekly_demand!$D:$D,weekly_demand!$A:$A,C$1,weekly_demand!$C:$C,$A11)) -> 0 | D11: =IF($A11="","",SUMIFS(weekly_demand!$D:$D,weekly_demand!$A:$A,D$1,weekly_demand!$C:$C,$A11)) -> 0 | E11: =IF($A11="","",SUMIFS(weekly_demand!$D:$D,weekly_demand!$A:$A,E$1,weekly_demand!$C:$C,$A11)) -> 0 | F11: =IF($A11="","",SUMIFS(weekly_demand!$D:$D,weekly_demand!$A:$A,F$1,weekly_demand!$C:$C,$A11)) -> 0 | G11: =IF($A11="","",SUMIFS(weekly_demand!$D:$D,weekly_demand!$A:$A,G$1,weekly_demand!$C:$C,$A11)) -> 0 | H11: =IF($A11="","",SUMPRODUCT($B11:$G11,INDEX($Y$2:$AD$16,MATCH(H$1,$X$2:$X$16,0),0))) -> 0 | I11: =IF($A11="","",SUMPRODUCT($B11:$G11,INDEX($Y$2:$AD$16,MATCH(I$1,$X$2:$X$16,0),0))) -> 0 | J11: =IF($A11="","",SUMPRODUCT($B11:$G11,INDEX($Y$2:$AD$16,MATCH(J$1,$X$2:$X$16,0),0))) -> 0 | K11: =IF($A11="","",SUMPRODUCT($B11:$G11,INDEX($Y$2:$AD$16,MATCH(K$1,$X$2:$X$16,0),0))) -> 0 | L11: =IF($A11="","",SUMPRODUCT($B11:$G11,INDEX($Y$2:$AD$16,MATCH(L$1,$X$2:$X$16,0),0))) -> 0 | M11: =IF($A11="","",SUMPRODUCT($B11:$G11,INDEX($Y$2:$AD$16,MATCH(M$1,$X$2:$X$16,0),0))) -> 0 | N11: =IF($A11="","",SUMPRODUCT($B11:$G11,INDEX($Y$2:$AD$16,MATCH(N$1,$X$2:$X$16,0),0))) -> 0 | O11: =IF($A11="","",SUMPRODUCT($B11:$G11,INDEX($Y$2:$AD$16,MATCH(O$1,$X$2:$X$16,0),0))) -> 0 | ... V11: =IF($A11="","",SUMPRODUCT($B11:$G11,INDEX($Y$2:$AD$16,MATCH(V$1,$X$2:$X$16,0),0))) -> 0 | X11: RM10 | Y11: 0 | Z11: 0 | AA11: 0 | AB11: 2 | AC11: 0 | AD11: 0
A12: 46202 | B12: =IF($A12="","",SUMIFS(weekly_demand!$D:$D,weekly_demand!$A:$A,B$1,weekly_demand!$C:$C,$A12)) -> 0 | C12: =IF($A12="","",SUMIFS(weekly_demand!$D:$D,weekly_demand!$A:$A,C$1,weekly_demand!$C:$C,$A12)) -> 0 | D12: =IF($A12="","",SUMIFS(weekly_demand!$D:$D,weekly_demand!$A:$A,D$1,weekly_demand!$C:$C,$A12)) -> 0 | E12: =IF($A12="","",SUMIFS(weekly_demand!$D:$D,weekly_demand!$A:$A,E$1,weekly_demand!$C:$C,$A12)) -> 0 | F12: =IF($A12="","",SUMIFS(weekly_demand!$D:$D,weekly_demand!$A:$A,F$1,weekly_demand!$C:$C,$A12)) -> 0 | G12: =IF($A12="","",SUMIFS(weekly_demand!$D:$D,weekly_demand!$A:$A,G$1,weekly_demand!$C:$C,$A12)) -> 0 | H12: =IF($A12="","",SUMPRODUCT($B12:$G12,INDEX($Y$2:$AD$16,MATCH(H$1,$X$2:$X$16,0),0))) -> 0 | I12: =IF($A12="","",SUMPRODUCT($B12:$G12,INDEX($Y$2:$AD$16,MATCH(I$1,$X$2:$X$16,0),0))) -> 0 | J12: =IF($A12="","",SUMPRODUCT($B12:$G12,INDEX($Y$2:$AD$16,MATCH(J$1,$X$2:$X$16,0),0))) -> 0 | K12: =IF($A12="","",SUMPRODUCT($B12:$G12,INDEX($Y$2:$AD$16,MATCH(K$1,$X$2:$X$16,0),0))) -> 0 | L12: =IF($A12="","",SUMPRODUCT($B12:$G12,INDEX($Y$2:$AD$16,MATCH(L$1,$X$2:$X$16,0),0))) -> 0 | M12: =IF($A12="","",SUMPRODUCT($B12:$G12,INDEX($Y$2:$AD$16,MATCH(M$1,$X$2:$X$16,0),0))) -> 0 | N12: =IF($A12="","",SUMPRODUCT($B12:$G12,INDEX($Y$2:$AD$16,MATCH(N$1,$X$2:$X$16,0),0))) -> 0 | O12: =IF($A12="","",SUMPRODUCT($B12:$G12,INDEX($Y$2:$AD$16,MATCH(O$1,$X$2:$X$16,0),0))) -> 0 | ... V12: =IF($A12="","",SUMPRODUCT($B12:$G12,INDEX($Y$2:$AD$16,MATCH(V$1,$X$2:$X$16,0),0))) -> 0 | X12: RM11 | Y12: 0 | Z12: 0 | AA12: 0 | AB12: 1.5 | AC12: 0 | AD12: 0
A13: 46209 | B13: =IF($A13="","",SUMIFS(weekly_demand!$D:$D,weekly_demand!$A:$A,B$1,weekly_demand!$C:$C,$A13)) -> 0 | C13: =IF($A13="","",SUMIFS(weekly_demand!$D:$D,weekly_demand!$A:$A,C$1,weekly_demand!$C:$C,$A13)) -> 0 | D13: =IF($A13="","",SUMIFS(weekly_demand!$D:$D,weekly_demand!$A:$A,D$1,weekly_demand!$C:$C,$A13)) -> 0 | E13: =IF($A13="","",SUMIFS(weekly_demand!$D:$D,weekly_demand!$A:$A,E$1,weekly_demand!$C:$C,$A13)) -> 0 | F13: =IF($A13="","",SUMIFS(weekly_demand!$D:$D,weekly_demand!$A:$A,F$1,weekly_demand!$C:$C,$A13)) -> 0 | G13: =IF($A13="","",SUMIFS(weekly_demand!$D:$D,weekly_demand!$A:$A,G$1,weekly_demand!$C:$C,$A13)) -> 0 | H13: =IF($A13="","",SUMPRODUCT($B13:$G13,INDEX($Y$2:$AD$16,MATCH(H$1,$X$2:$X$16,0),0))) -> 0 | I13: =IF($A13="","",SUMPRODUCT($B13:$G13,INDEX($Y$2:$AD$16,MATCH(I$1,$X$2:$X$16,0),0))) -> 0 | J13: =IF($A13="","",SUMPRODUCT($B13:$G13,INDEX($Y$2:$AD$16,MATCH(J$1,$X$2:$X$16,0),0))) -> 0 | K13: =IF($A13="","",SUMPRODUCT($B13:$G13,INDEX($Y$2:$AD$16,MATCH(K$1,$X$2:$X$16,0),0))) -> 0 | L13: =IF($A13="","",SUMPRODUCT($B13:$G13,INDEX($Y$2:$AD$16,MATCH(L$1,$X$2:$X$16,0),0))) -> 0 | M13: =IF($A13="","",SUMPRODUCT($B13:$G13,INDEX($Y$2:$AD$16,MATCH(M$1,$X$2:$X$16,0),0))) -> 0 | N13: =IF($A13="","",SUMPRODUCT($B13:$G13,INDEX($Y$2:$AD$16,MATCH(N$1,$X$2:$X$16,0),0))) -> 0 | O13: =IF($A13="","",SUMPRODUCT($B13:$G13,INDEX($Y$2:$AD$16,MATCH(O$1,$X$2:$X$16,0),0))) -> 0 | ... V13: =IF($A13="","",SUMPRODUCT($B13:$G13,INDEX($Y$2:$AD$16,MATCH(V$1,$X$2:$X$16,0),0))) -> 0 | X13: RM12 | Y13: 0 | Z13: 0 | AA13: 0 | AB13: 0 | AC13: 3 | AD13: 0
... A16: 46230 | B16: =IF($A16="","",SUMIFS(weekly_demand!$D:$D,weekly_demand!$A:$A,B$1,weekly_demand!$C:$C,$A16)) -> 0 | C16: =IF($A16="","",SUMIFS(weekly_demand!$D:$D,weekly_demand!$A:$A,C$1,weekly_demand!$C:$C,$A16)) -> 0 | D16: =IF($A16="","",SUMIFS(weekly_demand!$D:$D,weekly_demand!$A:$A,D$1,weekly_demand!$C:$C,$A16)) -> 0 | E16: =IF($A16="","",SUMIFS(weekly_demand!$D:$D,weekly_demand!$A:$A,E$1,weekly_demand!$C:$C,$A16)) -> 0 | F16: =IF($A16="","",SUMIFS(weekly_demand!$D:$D,weekly_demand!$A:$A,F$1,weekly_demand!$C:$C,$A16)) -> 0 | G16: =IF($A16="","",SUMIFS(weekly_demand!$D:$D,weekly_demand!$A:$A,G$1,weekly_demand!$C:$C,$A16)) -> 0 | H16: =IF($A16="","",SUMPRODUCT($B16:$G16,INDEX($Y$2:$AD$16,MATCH(H$1,$X$2:$X$16,0),0))) -> 0 | I16: =IF($A16="","",SUMPRODUCT($B16:$G16,INDEX($Y$2:$AD$16,MATCH(I$1,$X$2:$X$16,0),0))) -> 0 | J16: =IF($A16="","",SUMPRODUCT($B16:$G16,INDEX($Y$2:$AD$16,MATCH(J$1,$X$2:$X$16,0),0))) -> 0 | K16: =IF($A16="","",SUMPRODUCT($B16:$G16,INDEX($Y$2:$AD$16,MATCH(K$1,$X$2:$X$16,0),0))) -> 0 | L16: =IF($A16="","",SUMPRODUCT($B16:$G16,INDEX($Y$2:$AD$16,MATCH(L$1,$X$2:$X$16,0),0))) -> 0 | M16: =IF($A16="","",SUMPRODUCT($B16:$G16,INDEX($Y$2:$AD$16,MATCH(M$1,$X$2:$X$16,0),0))) -> 0 | N16: =IF($A16="","",SUMPRODUCT($B16:$G16,INDEX($Y$2:$AD$16,MATCH(N$1,$X$2:$X$16,0),0))) -> 0 | O16: =IF($A16="","",SUMPRODUCT($B16:$G16,INDEX($Y$2:$AD$16,MATCH(O$1,$X$2:$X$16,0),0))) -> 0 | ... V16: =IF($A16="","",SUMPRODUCT($B16:$G16,INDEX($Y$2:$AD$16,MATCH(V$1,$X$2:$X$16,0),0))) -> 0 | X16: RM15 | Y16: 0 | Z16: 0 | AA16: 0 | AB16: 0 | AC16: 0 | AD16: 2
A17: 46237 | B17: =IF($A17="","",SUMIFS(weekly_demand!$D:$D,weekly_demand!$A:$A,B$1,weekly_demand!$C:$C,$A17)) -> 0 | C17: =IF($A17="","",SUMIFS(weekly_demand!$D:$D,weekly_demand!$A:$A,C$1,weekly_demand!$C:$C,$A17)) -> 0 | D17: =IF($A17="","",SUMIFS(weekly_demand!$D:$D,weekly_demand!$A:$A,D$1,weekly_demand!$C:$C,$A17)) -> 0 | E17: =IF($A17="","",SUMIFS(weekly_demand!$D:$D,weekly_demand!$A:$A,E$1,weekly_demand!$C:$C,$A17)) -> 0 | F17: =IF($A17="","",SUMIFS(weekly_demand!$D:$D,weekly_demand!$A:$A,F$1,weekly_demand!$C:$C,$A17)) -> 0 | G17: =IF($A17="","",SUMIFS(weekly_demand!$D:$D,weekly_demand!$A:$A,G$1,weekly_demand!$C:$C,$A17)) -> 0 | H17: =IF($A17="","",SUMPRODUCT($B17:$G17,INDEX($Y$2:$AD$16,MATCH(H$1,$X$2:$X$16,0),0))) -> 0 | I17: =IF($A17="","",SUMPRODUCT($B17:$G17,INDEX($Y$2:$AD$16,MATCH(I$1,$X$2:$X$16,0),0))) -> 0 | J17: =IF($A17="","",SUMPRODUCT($B17:$G17,INDEX($Y$2:$AD$16,MATCH(J$1,$X$2:$X$16,0),0))) -> 0 | K17: =IF($A17="","",SUMPRODUCT($B17:$G17,INDEX($Y$2:$AD$16,MATCH(K$1,$X$2:$X$16,0),0))) -> 0 | L17: =IF($A17="","",SUMPRODUCT($B17:$G17,INDEX($Y$2:$AD$16,MATCH(L$1,$X$2:$X$16,0),0))) -> 0 | M17: =IF($A17="","",SUMPRODUCT($B17:$G17,INDEX($Y$2:$AD$16,MATCH(M$1,$X$2:$X$16,0),0))) -> 0 | N17: =IF($A17="","",SUMPRODUCT($B17:$G17,INDEX($Y$2:$AD$16,MATCH(N$1,$X$2:$X$16,0),0))) -> 0 | O17: =IF($A17="","",SUMPRODUCT($B17:$G17,INDEX($Y$2:$AD$16,MATCH(O$1,$X$2:$X$16,0),0))) -> 0 | ... V17: =IF($A17="","",SUMPRODUCT($B17:$G17,INDEX($Y$2:$AD$16,MATCH(V$1,$X$2:$X$16,0),0))) -> 0
A18: 46244 | B18: =IF($A18="","",SUMIFS(weekly_demand!$D:$D,weekly_demand!$A:$A,B$1,weekly_demand!$C:$C,$A18)) -> 0 | C18: =IF($A18="","",SUMIFS(weekly_demand!$D:$D,weekly_demand!$A:$A,C$1,weekly_demand!$C:$C,$A18)) -> 0 | D18: =IF($A18="","",SUMIFS(weekly_demand!$D:$D,weekly_demand!$A:$A,D$1,weekly_demand!$C:$C,$A18)) -> 0 | E18: =IF($A18="","",SUMIFS(weekly_demand!$D:$D,weekly_demand!$A:$A,E$1,weekly_demand!$C:$C,$A18)) -> 0 | F18: =IF($A18="","",SUMIFS(weekly_demand!$D:$D,weekly_demand!$A:$A,F$1,weekly_demand!$C:$C,$A18)) -> 0 | G18: =IF($A18="","",SUMIFS(weekly_demand!$D:$D,weekly_demand!$A:$A,G$1,weekly_demand!$C:$C,$A18)) -> 0 | H18: =IF($A18="","",SUMPRODUCT($B18:$G18,INDEX($Y$2:$AD$16,MATCH(H$1,$X$2:$X$16,0),0))) -> 0 | I18: =IF($A18="","",SUMPRODUCT($B18:$G18,INDEX($Y$2:$AD$16,MATCH(I$1,$X$2:$X$16,0),0))) -> 0 | J18: =IF($A18="","",SUMPRODUCT($B18:$G18,INDEX($Y$2:$AD$16,MATCH(J$1,$X$2:$X$16,0),0))) -> 0 | K18: =IF($A18="","",SUMPRODUCT($B18:$G18,INDEX($Y$2:$AD$16,MATCH(K$1,$X$2:$X$16,0),0))) -> 0 | L18: =IF($A18="","",SUMPRODUCT($B18:$G18,INDEX($Y$2:$AD$16,MATCH(L$1,$X$2:$X$16,0),0))) -> 0 | M18: =IF($A18="","",SUMPRODUCT($B18:$G18,INDEX($Y$2:$AD$16,MATCH(M$1,$X$2:$X$16,0),0))) -> 0 | N18: =IF($A18="","",SUMPRODUCT($B18:$G18,INDEX($Y$2:$AD$16,MATCH(N$1,$X$2:$X$16,0),0))) -> 0 | O18: =IF($A18="","",SUMPRODUCT($B18:$G18,INDEX($Y$2:$AD$16,MATCH(O$1,$X$2:$X$16,0),0))) -> 0 | ... V18: =IF($A18="","",SUMPRODUCT($B18:$G18,INDEX($Y$2:$AD$16,MATCH(V$1,$X$2:$X$16,0),0))) -> 0
A19: 46251 | B19: =IF($A19="","",SUMIFS(weekly_demand!$D:$D,weekly_demand!$A:$A,B$1,weekly_demand!$C:$C,$A19)) -> 0 | C19: =IF($A19="","",SUMIFS(weekly_demand!$D:$D,weekly_demand!$A:$A,C$1,weekly_demand!$C:$C,$A19)) -> 0 | D19: =IF($A19="","",SUMIFS(weekly_demand!$D:$D,weekly_demand!$A:$A,D$1,weekly_demand!$C:$C,$A19)) -> 0 | E19: =IF($A19="","",SUMIFS(weekly_demand!$D:$D,weekly_demand!$A:$A,E$1,weekly_demand!$C:$C,$A19)) -> 0 | F19: =IF($A19="","",SUMIFS(weekly_demand!$D:$D,weekly_demand!$A:$A,F$1,weekly_demand!$C:$C,$A19)) -> 0 | G19: =IF($A19="","",SUMIFS(weekly_demand!$D:$D,weekly_demand!$A:$A,G$1,weekly_demand!$C:$C,$A19)) -> 0 | H19: =IF($A19="","",SUMPRODUCT($B19:$G19,INDEX($Y$2:$AD$16,MATCH(H$1,$X$2:$X$16,0),0))) -> 0 | I19: =IF($A19="","",SUMPRODUCT($B19:$G19,INDEX($Y$2:$AD$16,MATCH(I$1,$X$2:$X$16,0),0))) -> 0 | J19: =IF($A19="","",SUMPRODUCT($B19:$G19,INDEX($Y$2:$AD$16,MATCH(J$1,$X$2:$X$16,0),0))) -> 0 | K19: =IF($A19="","",SUMPRODUCT($B19:$G19,INDEX($Y$2:$AD$16,MATCH(K$1,$X$2:$X$16,0),0))) -> 0 | L19: =IF($A19="","",SUMPRODUCT($B19:$G19,INDEX($Y$2:$AD$16,MATCH(L$1,$X$2:$X$16,0),0))) -> 0 | M19: =IF($A19="","",SUMPRODUCT($B19:$G19,INDEX($Y$2:$AD$16,MATCH(M$1,$X$2:$X$16,0),0))) -> 0 | N19: =IF($A19="","",SUMPRODUCT($B19:$G19,INDEX($Y$2:$AD$16,MATCH(N$1,$X$2:$X$16,0),0))) -> 0 | O19: =IF($A19="","",SUMPRODUCT($B19:$G19,INDEX($Y$2:$AD$16,MATCH(O$1,$X$2:$X$16,0),0))) -> 0 | ... V19: =IF($A19="","",SUMPRODUCT($B19:$G19,INDEX($Y$2:$AD$16,MATCH(V$1,$X$2:$X$16,0),0))) -> 0
A20: 46258 | B20: =IF($A20="","",SUMIFS(weekly_demand!$D:$D,weekly_demand!$A:$A,B$1,weekly_demand!$C:$C,$A20)) -> 0 | C20: =IF($A20="","",SUMIFS(weekly_demand!$D:$D,weekly_demand!$A:$A,C$1,weekly_demand!$C:$C,$A20)) -> 0 | D20: =IF($A20="","",SUMIFS(weekly_demand!$D:$D,weekly_demand!$A:$A,D$1,weekly_demand!$C:$C,$A20)) -> 0 | E20: =IF($A20="","",SUMIFS(weekly_demand!$D:$D,weekly_demand!$A:$A,E$1,weekly_demand!$C:$C,$A20)) -> 0 | F20: =IF($A20="","",SUMIFS(weekly_demand!$D:$D,weekly_demand!$A:$A,F$1,weekly_demand!$C:$C,$A20)) -> 0 | G20: =IF($A20="","",SUMIFS(weekly_demand!$D:$D,weekly_demand!$A:$A,G$1,weekly_demand!$C:$C,$A20)) -> 0 | H20: =IF($A20="","",SUMPRODUCT($B20:$G20,INDEX($Y$2:$AD$16,MATCH(H$1,$X$2:$X$16,0),0))) -> 0 | I20: =IF($A20="","",SUMPRODUCT($B20:$G20,INDEX($Y$2:$AD$16,MATCH(I$1,$X$2:$X$16,0),0))) -> 0 | J20: =IF($A20="","",SUMPRODUCT($B20:$G20,INDEX($Y$2:$AD$16,MATCH(J$1,$X$2:$X$16,0),0))) -> 0 | K20: =IF($A20="","",SUMPRODUCT($B20:$G20,INDEX($Y$2:$AD$16,MATCH(K$1,$X$2:$X$16,0),0))) -> 0 | L20: =IF($A20="","",SUMPRODUCT($B20:$G20,INDEX($Y$2:$AD$16,MATCH(L$1,$X$2:$X$16,0),0))) -> 0 | M20: =IF($A20="","",SUMPRODUCT($B20:$G20,INDEX($Y$2:$AD$16,MATCH(M$1,$X$2:$X$16,0),0))) -> 0 | N20: =IF($A20="","",SUMPRODUCT($B20:$G20,INDEX($Y$2:$AD$16,MATCH(N$1,$X$2:$X$16,0),0))) -> 0 | O20: =IF($A20="","",SUMPRODUCT($B20:$G20,INDEX($Y$2:$AD$16,MATCH(O$1,$X$2:$X$16,0),0))) -> 0 | ... V20: =IF($A20="","",SUMPRODUCT($B20:$G20,INDEX($Y$2:$AD$16,MATCH(V$1,$X$2:$X$16,0),0))) -> 0
